Workbook

Sheet TB
A1: ULTRAFINE MINERAL & ADMIXTURES PVT LTD (HAY)
A2: 1516/907/2/1, RDC CONCRETE INDIA PRIVATE LIMITED,
A3: BEHRAMPUR ROAD, KHANDSA , GURGAON, Gurugram, Haryana
A4: UDYAM : UDYAM-MH-20-0007365 (Small/Mfgr)
A5: CIN: U24100MH2020PTC338575
A6: Contact : +91-
A7: Sundry Creditors
A8: Group Summary
A9: 1-Apr-26 to 31-Jul-26 | B9: =SUBTOTAL(9,B12:B255) -> 45031978 | C9: =SUBTOTAL(9,C12:C255) -> 2.7896965e+08
A10: PARTICULAR | B10: Closing Balance
B11: Debit | C11: Credit
A12: A. Abdul Hameed - Crs | C12: 225000
A13: Aadhya Shakti Enterprise-Crs | C13: 106912.12
A14: Abhay Dongare - Employee | B14: 7148
A15: Abhay Singh-Employee | B15: 4484
A16: ACE HIMALAYAN FERRO ALLOYS PRIVATE LIMITED - CRS | B16: 94000
A17: ADHUNIK TRASNPORT ORGANISATION LIMITED - Crs | C17: 104939.38
A18: ADVITA POLYCRAFT LLP - Crs | C18: 731548.93
A19: Agile Innotech - Crs | C19: 11328
A20: AI INDUSTRIAL SOLUTIONS-Crs | C20: 29854
A21: AIRMAX AUTOMATION - CRS | C21: 35913.4
A22: Akash Body Bildders-CRS | C22: 300000.02
A23: AMBUJA CEMENTS LIMITED -Crs | C23: 9642007.8
A24: Ankush Chavan- Employee | B24: 15000
A25: Arcelormittal Nippon Steel India Limited - Crs | B25: 531569.86
A26: ARKAY LOGISTICS-Crs | C26: 837826.02
A27: Arya CS - Crs | C27: 3000
A28: ASHCONNECT GLOBAL TRADING Pvt Ltd- Crs | C28: 8980658.6
A29: Ashish Kumar (Patna) - Employee | C29: 139597
A30: ASHOKA BUILDCON LIMITED-Crs | B30: 163127.04
A31: Ashvarya Kumar Verma-Employee | B31: 23510
A32: Asl Logistics Private Limited-Crs | C32: 9139346.2
A33: AVENGERS SECURITY SERVICES-CR | C33: 33434.68
A34: BAHUBALI CHEMICAL INDUSTRIES-CRS | C34: 6562298.2
A35: Balram Kumar Chakrawarti - Employee | C35: 413424
A36: Bandu Naik - Employee | B36: 187504
A37: Best Electro Mech-Crs | C37: 9762.76
A38: BGR Constructions - Crs | C38: 807940
A39: Bhamra Transport - Crs | C39: 311205.16
A40: Bhandari Automobiles Pvt Ltd - Crs | C40: 9150
...

Sheet Bill Wise
A1: Date | B1: Ref. No. | C1: Party's Name | D1: Cost Center/Location | E1: Ageing Bucket | F1: Pending (abs) | G1: Signed Amount
A2: 44357 | B2: CHN/2122/00447 | C2: Neptune Readymix Concrete Pvt. Ltd.(Cochin)-Vendor - Crs | D2: Bangalore | E2: Above 365 Days | F2: 85567 | G2: 85567
A3: 44361 | B3: CHN/2122/00452 | C3: Neptune Readymix Concrete Pvt. Ltd.(Cochin)-Vendor - Crs | D3: Bangalore | E3: Above 365 Days | F3: 62940 | G3: 62940
A4: 44383 | B4: CHN/2122/00448 | C4: Neptune Readymix Concrete Pvt. Ltd.(Cochin)-Vendor - Crs | D4: Bangalore | E4: Above 365 Days | F4: 78182 | G4: 78182
A5: 44400 | B5: CHN/2122/00453 | C5: Neptune Readymix Concrete Pvt. Ltd.(Cochin)-Vendor - Crs | D5: Bangalore | E5: Above 365 Days | F5: 73765 | G5: 73765
A6: 44456 | B6: CHN/2122/00543 | C6: Neptune Readymix Concrete Pvt. Ltd.(Cochin)-Vendor - Crs | D6: Bangalore | E6: Above 365 Days | F6: 74180 | G6: 74180
A7: 44473 | B7: CHN/2122/00547 | C7: Neptune Readymix Concrete Pvt. Ltd.(Cochin)-Vendor - Crs | D7: Bangalore | E7: Above 365 Days | F7: 92865 | G7: 92865
A8: 44488 | B8: CHN/2122/00548 | C8: Neptune Readymix Concrete Pvt. Ltd.(Cochin)-Vendor - Crs | D8: Bangalore | E8: Above 365 Days | F8: 71512 | G8: 71512
A9: 44493 | B9: CHN/2122/00560 | C9: Neptune Readymix Concrete Pvt. Ltd.(Cochin)-Vendor - Crs | D9: Bangalore | E9: Above 365 Days | F9: 15314 | G9: 15314
A10: 44500 | B10: CHN/2122/00562 | C10: Neptune Readymix Concrete Pvt. Ltd.(Cochin)-Vendor - Crs | D10: Bangalore | E10: Above 365 Days | F10: 81842 | G10: 81842
A11: 44535 | B11: CHN/2122/00579 | C11: Neptune Readymix Concrete Pvt. Ltd.(Cochin)-Vendor - Crs | D11: Bangalore | E11: Above 365 Days | F11: 19959 | G11: 19959
A12: 44545 | B12: CHN/21-22/00577 | C12: NEPTUNE READYMIX CONCRETE.PVT.LTD - MUPPATHADOM - Crs | D12: Bangalore | E12: Above 365 Days | F12: 72416 | G12: 72416
A13: 44546 | B13: CHN/21-22/00578 | C13: NEPTUNE READYMIX CONCRETE.PVT.LTD - MUPPATHADOM - Crs | D13: Bangalore | E13: Above 365 Days | F13: 56484 | G13: 56484
... A75: 45594 | B75: LSPL/24-25/400 | C75: Lub Solutions Pvt Ltd - Crs | D75: Goa | E75: Above 365 Days | F75: 786935 | G75: 786935
A76: 45692 | B76: 509 | C76: ASHOKA BUILDCON LIMITED-Crs | E76: Above 365 Days | F76: 13127.04 | G76: -13127.04
A77: 45722 | B77: 1750246755 | C77: SOCIAM EQUIPMENT SOLUTIONS PRIVATE LIMITED-CRS | D77: Gujarat | E77: Above 365 Days | F77: 819787.64 | G77: 819787.64
A78: 45747 | B78: WEET/RDC/024 | C78: Well Erectors Of Engineering Technology Private Limited - Crs | E78: Above 365 Days | F78: 819292.57 | G78: 819292.57
A79: 45777 | B79: JV/HO/2526/0009 | C79: RDC Concrete (India) Pvt Ltd (Head Office) - Crs | D79: Head Office | E79: Above 365 Days | F79: 1736215 | G79: 1736215
A80: 45798 | B80: 20KGRL/2025-26 | C80: KGR Logistics - Crs | D80: wada | E80: Above 365 Days | F80: 0.7 | G80: 0.7
A81: 45806 | B81: 038 | C81: SREERAMA INDUSTRIES PRIVATE LIMITED-Crs | D81: Vizag | E81: Above 365 Days | F81: 172046 | G81: 172046
A82: 45808 | B82: JV/HO/2526/0024 | C82: RDC Concrete (India) Pvt Ltd (Head Office) - Crs | D82: Head Office | E82: Above 365 Days | F82: 834281.26 | G82: 834281.26
A83: 45811 | B83: 027 | C83: Dattakrupa Minerals - Crs | D83: Goa | E83: Above 365 Days | F83: 0.2 | G83: 0.2
A84: 45812 | B84: PV/GUJ/2526/0123 | C84: Steel & Power-CR (CAP) - Crs | E84: Above 365 Days | F84: 300000 | G84: -300000
A85: 45813 | B85: 190 | C85: SULTAN ENTERPRISES-CRS | E85: Above 365 Days | F85: 110487.82 | G85: 110487.82
A86: 45814 | B86: 189 | C86: SULTAN ENTERPRISES-CRS | E86: Above 365 Days | F86: 100716 | G86: 100716
A87: 45818 | B87: 191 | C87: SULTAN ENTERPRISES-CRS | E87: Above 365 Days | F87: 106677.9 | G87: 106677.9
A88: 45825 | B88: 192 | C88: SULTAN ENTERPRISES-CRS | E88: Above 365 Days | F88: 108055.5 | G88: 108055.5
A89: 45826 | B89: Ash/12 | C89: ASHCONNECT GLOBAL TRADING Pvt Ltd- Crs | D89: flyash | E89: Above 365 Days | F89: 64759.02 | G89: 64759.02
A90: 45838 | B90: ASH/13 | C90: ASHCONNECT GLOBAL TRADING Pvt Ltd- Crs | E90: Above 365 Days | F90: 246403.27 | G90: 246403.27
A91: 45838 | B91: 2KL25ARMN10 | C91: RDC Concrete (India) Pvt Ltd (Kolkata)-Crs | D91: Panagarh (Aggregate) WB | E91: Above 365 Days | F91: 2972863.7 | G91: 2972863.7
A92: 45838 | B92: 2KL25ARMN12 | C92: RDC Concrete (India) Pvt Ltd (Kolkata)-Crs | D92: Gujarat | E92: Above 365 Days | F92: 1276850.8 | G92: 1276850.8
A93: 45839 | B93: JV/HO/2526/0073 | C93: RDC Concrete (India) Pvt Ltd (Head Office) - Crs | E93: Above 365 Days | F93: 740750 | G93: 740750
A94: 45839 | B94: JV/GUJ/2526/0038 | C94: SHIVSHAKTI ENTERPRISES - Crs | E94: Above 365 Days | F94: 649762.84 | G94: -649762.84
A95: 45858 | B95: Ash/15 | C95: ASHCONNECT GLOBAL TRADING Pvt Ltd- Crs | E95: Above 365 Days | F95: 99570 | G95: 99570
A96: 45863 | B96: Ash/16 | C96: ASHCONNECT GLOBAL TRADING Pvt Ltd- Crs | D96: flyash | E96: Above 365 Days | F96: 150479 | G96: 150479
A97: 45869 | B97: HM27/2526/069328 | C97: Hella Infra Market Limited-Crs | E97: 181-365 Days | F97: 1214662.7 | G97: 1214662.7
A98: 45869 | B98: JV/HO/2526/0070 | C98: RDC Concrete (India) Pvt Ltd (Head Office) - Crs | E98: 181-365 Days | F98: 821726.7 | G98: 821726.7
A99: 45869 | B99: 2KL25ARMN18 | C99: RDC Concrete (India) Pvt Ltd (Kolkata)-Crs | E99: 181-365 Days | F99: 540132.83 | G99: 540132.83
A100: 45869 | B100: 13HY25ARMN18 | C100: RDC Concrete (India) Pvt Ltd (Telangana)- Crs | E100: 181-365 Days | F100: 78487.5 | G100: 78487.5
A101: 45869 | B101: SRLGOA013/25-26 | C101: SRL Group and Company - Crs | D101: wada | E101: 181-365 Days | F101: 200928.42 | G101: 200928.42
...

Sheet Only Creditors
A1: Ultrafine Mineral & Admixtures Pvt. Ltd.
A2: Creditors Ageing Report | As at 31-July-2026
B3: SUBTOTAL | F3: =SUM(F5:F181) -> 32848614 | G3: =SUM(G5:G181) -> 1.3927462e+08 | H3: =SUM(H5:H181) -> 18364455 | I3: =SUM(I5:I181) -> 1.5763908e+08 | J3: =SUM(J5:J181) -> 65610551 | K3: =SUM(K5:K181) -> 34399226 | L3: =SUM(L5:L181) -> 17886604 | M3: =SUM(M5:M181) -> 6813919.8 | ... S3: =SUM(S5:S181) -> 660.95
A4: # | B4: Vendor Name | C4: Location | D4: Vendor Type | E4: Vendor Sub Type | F4: above 120 days | G4: As of 10-08-2026 | H4: Paid in August | I4: TB Balance (Cr) | J4: 0-30 Days | K4: 31-60 Days | L4: 61-90 Days | M4: 91-120 Days | N4: 121-150 Days | O4: 151-180 Days | P4: 181-365 Days | Q4: Above 365 Days | R4: BW Total | S4: Diff (TB-BW)
A5: 1 | B5: A. Abdul Hameed - Crs | C5: Goa | D5: Expenses | E5: Professional Fees | F5: =SUM(N5:Q5) -> 0 | G5: =I5-H5 -> 0 | H5: =SUMIF(Payments!$D$4:$D$117,'Only Creditors'!B5,Payments!$E$4:$E$130) -> 225000 | I5: 225000 | J5: 225000 | K5: 0 | L5: 0 | M5: 0 | N5: 0 | O5: 0 | P5: 0 | Q5: 0 | R5: 225000 | S5: 0
A6: 2 | B6: ADHUNIK TRASNPORT ORGANISATION LIMITED - Crs | C6: Galsi | D6: Transportation | E6: Transport | F6: =SUM(N6:Q6) -> 0 | G6: =I6-H6 -> 104939.38 | H6: =SUMIF(Payments!$D$4:$D$117,'Only Creditors'!B6,Payments!$E$4:$E$130) -> 0 | I6: 104939.38 | J6: 24500 | K6: 0 | L6: 80439.38 | M6: 0 | N6: 0 | O6: 0 | P6: 0 | Q6: 0 | R6: 104939.38 | S6: 0
A7: 3 | B7: ADVITA POLYCRAFT LLP - Crs | C7: Wada | D7: Expenses | E7: Store and spare | F7: =SUM(N7:Q7) -> 0 | G7: =I7-H7 -> 731548.93 | H7: =SUMIF(Payments!$D$4:$D$117,'Only Creditors'!B7,Payments!$E$4:$E$130) -> 0 | I7: 731548.93 | J7: 277304 | K7: 454244.93 | L7: 0 | M7: 0 | N7: 0 | O7: 0 | P7: 0 | Q7: 0 | R7: 731548.93 | S7: 0
A8: 4 | B8: AI INDUSTRIAL SOLUTIONS-Crs | C8: Wada | D8: Expenses | E8: Store and spare | F8: =SUM(N8:Q8) -> 0 | G8: =I8-H8 -> 29854 | H8: =SUMIF(Payments!$D$4:$D$117,'Only Creditors'!B8,Payments!$E$4:$E$130) -> 0 | I8: 29854 | J8: 29854 | K8: 0 | L8: 0 | M8: 0 | N8: 0 | O8: 0 | P8: 0 | Q8: 0 | R8: 29854 | S8: 0
A9: 5 | B9: AIRMAX AUTOMATION - CRS | C9: Wada | D9: Expenses | E9: Store and spare | F9: To be paid | G9: =I9-H9 -> 35913.4 | H9: =SUMIF(Payments!$D$4:$D$117,'Only Creditors'!B9,Payments!$E$4:$E$130) -> 0 | I9: 35913.4 | J9: 0 | K9: 0 | L9: 35913.4 | M9: 0 | N9: 0 | O9: 0 | P9: 0 | Q9: 0 | R9: 35913.4 | S9: 0
A10: 6 | B10: AMBUJA CEMENTS LIMITED -Crs | C10: flyash | D10: Trading | E10: Flyash | F10: =SUM(N10:Q10) -> 0 | G10: =I10-H10 -> 8637609.4 | H10: =SUMIF(Payments!$D$4:$D$117,'Only Creditors'!B10,Payments!$E$4:$E$130) -> 1004398.3 | I10: 9642007.8 | J10: 5766835.1 | K10: 3875172.7 | L10: 0 | M10: 0 | N10: 0 | O10: 0 | P10: 0 | Q10: 0 | R10: 9642007.8 | S10: 0
A11: 7 | B11: ARKAY LOGISTICS-Crs | C11: flyash | D11: Trading | E11: Flyash | F11: =SUM(N11:Q11) -> 0 | G11: =I11-H11 -> 837826.02 | H11: =SUMIF(Payments!$D$4:$D$117,'Only Creditors'!B11,Payments!$E$4:$E$130) -> 0 | I11: 837826.02 | J11: 479696.2 | K11: 358129.82 | L11: 0 | M11: 0 | N11: 0 | O11: 0 | P11: 0 | Q11: 0 | R11: 837826.02 | S11: 0
A12: 8 | B12: ASHCONNECT GLOBAL TRADING Pvt Ltd- Crs | C12: flyash | D12: Trading | E12: Flyash | F12: =SUM(N12:Q12) -> 6960958 | G12: =I12-H12 -> 8419447.3 | H12: =SUMIF(Payments!$D$4:$D$117,'Only Creditors'!B12,Payments!$E$4:$E$130) -> 561211.29 | I12: 8980658.6 | J12: 340769.77 | K12: 697265.26 | L12: 529460.71 | M12: 452204.79 | N12: 1885930.5 | O12: 1621868.9 | P12: 2891947.3 | Q12: 561211.29 | R12: 8980658.6 | S12: 0
A13: 9 | B13: AVENGERS SECURITY SERVICES-CR | C13: Nellore | D13: Expenses | E13: Security charges | F13: =SUM(N13:Q13) -> 0 | G13: =I13-H13 -> 33434.68 | H13: =SUMIF(Payments!$D$4:$D$117,'Only Creditors'!B13,Payments!$E$4:$E$130) -> 0 | I13: 33434.68 | J13: 33434.68 | K13: 0 | L13: 0 | M13: 0 | N13: 0 | O13: 0 | P13: 0 | Q13: 0 | R13: 33434.68 | S13: 0
A14: 10 | B14: Aadhya Shakti Enterprise-Crs | C14: Gujarat | D14: Transportation | E14: Transport | F14: =SUM(N14:Q14) -> 0 | G14: =I14-H14 -> 106912.12 | H14: =SUMIF(Payments!$D$4:$D$117,'Only Creditors'!B14,Payments!$E$4:$E$130) -> 0 | I14: 106912.12 | J14: 106912.12 | K14: 0 | L14: 0 | M14: 0 | N14: 0 | O14: 0 | P14: 0 | Q14: 0 | R14: 106912.12 | S14: 0
A15: 11 | B15: Agile Innotech - Crs | C15: Aggregate | D15: Expenses | E15: Office Exps | F15: To be paid | G15: =I15-H15 -> 0 | H15: =SUMIF(Payments!$D$4:$D$117,'Only Creditors'!B15,Payments!$E$4:$E$130) -> 11328 | I15: 11328 | J15: 11328 | K15: 0 | L15: 0 | M15: 0 | N15: 0 | O15: 0 | P15: 0 | Q15: 0 | R15: 11328 | S15: 0
A16: 12 | B16: Akash Body Bildders-CRS | C16: Aggregate | D16: Transportation | E16: Transport | F16: =SUM(N16:Q16) -> 300000.02 | G16: =I16-H16 -> 300000.02 | H16: =SUMIF(Payments!$D$4:$D$117,'Only Creditors'!B16,Payments!$E$4:$E$130) -> 0 | I16: 300000.02 | J16: 0 | K16: 0 | L16: 0 | M16: 0 | N16: 0 | O16: 0 | P16: 300000.02 | Q16: 0 | R16: 300000.02 | S16: 0
A17: 13 | B17: Arya CS - Crs | C17: Nagpur | D17: Expenses | E17: Guest House Rent | F17: To be paid | G17: =I17-H17 -> 3000 | H17: =SUMIF(Payments!$D$4:$D$117,'Only Creditors'!B17,Payments!$E$4:$E$130) -> 0 | I17: 3000 | J17: 3000 | K17: 0 | L17: 0 | M17: 0 | N17: 0 | O17: 0 | P17: 0 | Q17: 0 | R17: 3000 | S17: 0
A18: 14 | B18: Ashish Kumar (Patna) - Employee | C18: Patna | D18: Employee | E18: Employee | F18: =SUM(N18:Q18) -> 0 | G18: =I18-H18 -> 139597 | H18: =SUMIF(Payments!$D$4:$D$117,'Only Creditors'!B18,Payments!$E$4:$E$130) -> 0 | I18: 139597 | J18: 139597 | K18: 0 | L18: 0 | M18: 0 | N18: 0 | O18: 0 | P18: 0 | Q18: 0 | R18: 139597 | S18: 0
A19: 15 | B19: Asl Logistics Private Limited-Crs | C19: Gujarat | D19: Transportation | E19: Transport | F19: =SUM(N19:Q19) -> 0 | G19: =I19-H19 -> 8364610.1 | H19: =SUMIF(Payments!$D$4:$D$117,'Only Creditors'!B19,Payments!$E$4:$E$130) -> 774736.17 | I19: 9139346.2 | J19: 2782951.5 | K19: 2726848.2 | L19: 2054810.2 | M19: 1574736.2 | N19: 0 | O19: 0 | P19: 0 | Q19: 0 | R19: 9139346.2 | S19: 0
A20: 16 | B20: B Stone Product - Crs | C20: Aggregate | D20: Raw Material | E20: Aggregate | F20: =SUM(N20:Q20) -> 0 | G20: =I20-H20 -> 47027.5 | H20: =SUMIF(Payments!$D$4:$D$117,'Only Creditors'!B20,Payments!$E$4:$E$130) -> 0 | I20: 47027.5 | J20: 47068 | K20: 0 | L20: -40.5 | M20: 0 | N20: 0 | O20: 0 | P20: 0 | Q20: 0 | R20: 47027.5 | S20: 0
A21: 17 | B21: BAHUBALI CHEMICAL INDUSTRIES-CRS | C21: Bangalore | D21: Trading | E21: Microsilica | F21: =SUM(N21:Q21) -> 6562298.2 | G21: =I21-H21 -> 6562298.2 | H21: =SUMIF(Payments!$D$4:$D$117,'Only Creditors'!B21,Payments!$E$4:$E$130) -> 0 | I21: 6562298.2 | J21: 0 | K21: 0 | L21: 0 | M21: 0 | N21: 0 | O21: 832278 | P21: 5730020.2 | Q21: 0 | R21: 6562298.2 | S21: 0
A22: 18 | B22: BGR Constructions - Crs | C22: Nellore | D22: Transportation | E22: Transport | F22: =SUM(N22:Q22) -> 0 | G22: =I22-H22 -> 807940 | H22: =SUMIF(Payments!$D$4:$D$117,'Only Creditors'!B22,Payments!$E$4:$E$130) -> 0 | I22: 807940 | J22: 249690 | K22: 558250 | L22: 0 | M22: 0 | N22: 0 | O22: 0 | P22: 0 | Q22: 0 | R22: 807940 | S22: 0
A23: 19 | B23: BHARTIBEN SATISHBHAI PATEL-CR | C23: Gujarat | D23: Expenses | E23: Guest House Rent | F23: =SUM(N23:Q23) -> 0 | G23: =I23-H23 -> 0 | H23: =SUMIF(Payments!$D$4:$D$117,'Only Creditors'!B23,Payments!$E$4:$E$130) -> 8000 | I23: 8000 | J23: 8000 | K23: 0 | L23: 0 | M23: 0 | N23: 0 | O23: 0 | P23: 0 | Q23: 0 | R23: 8000 | S23: 0
A24: 20 | B24: BHUMAN ENTERPRISE-Crs | C24: Microsilica | D24: Raw Material | E24: Aggregate | F24: =SUM(N24:Q24) -> 0 | G24: =I24-H24 -> 1331796.1 | H24: =SUMIF(Payments!$D$4:$D$117,'Only Creditors'!B24,Payments!$E$4:$E$130) -> 0 | I24: 1331796.1 | J24: 441449.15 | K24: 890347 | L24: 0 | M24: 0 | N24: 0 | O24: 0 | P24: 0 | Q24: 0 | R24: 1331796.1 | S24: 0
A25: 21 | B25: BISWAJIT RUI DAS - Crs | C25: Microsilica | D25: Expenses | E25: Transport | F25: To be paid | G25: =I25-H25 -> 28072 | H25: =SUMIF(Payments!$D$4:$D$117,'Only Creditors'!B25,Payments!$E$4:$E$130) -> 36262.88 | I25: 64334.88 | J25: 28072 | K25: 36262.88 | L25: 0 | M25: 0 | N25: 0 | O25: 0 | P25: 0 | Q25: 0 | R25: 64334.88 | S25: 0
A26: 22 | B26: BN Trading and Transport Company-Cr | C26: Gujarat | D26: Transportation | E26: Transport | F26: =SUM(N26:Q26) -> 0 | G26: =I26-H26 -> 495364.28 | H26: =SUMIF(Payments!$D$4:$D$117,'Only Creditors'!B26,Payments!$E$4:$E$130) -> 0 | I26: 495364.28 | J26: 152876.4 | K26: 342487.88 | L26: 0 | M26: 0 | N26: 0 | O26: 0 | P26: 0 | Q26: 0 | R26: 495364.28 | S26: 0
A27: 23 | B27: Balram Kumar Chakrawarti - Employee | C27: Vizag | D27: Employee | E27: Employee | F27: =SUM(N27:Q27) -> 0 | G27: =I27-H27 -> 0 | H27: =SUMIF(Payments!$D$4:$D$117,'Only Creditors'!B27,Payments!$E$4:$E$130) -> 413424 | I27: 413424 | J27: 413424 | K27: 0 | L27: 0 | M27: 0 | N27: 0 | O27: 0 | P27: 0 | Q27: 0 | R27: 413424 | S27: 0
A28: 24 | B28: Best Electro Mech-Crs | C28: Wada | D28: Expenses | E28: Store and spare | F28: =SUM(N28:Q28) -> 0 | G28: =I28-H28 -> 9762.76 | H28: =SUMIF(Payments!$D$4:$D$117,'Only Creditors'!B28,Payments!$E$4:$E$130) -> 0 | I28: 9762.76 | J28: 9762.76 | K28: 0 | L28: 0 | M28: 0 | N28: 0 | O28: 0 | P28: 0 | Q28: 0 | R28: 9762.76 | S28: 0
A29: 25 | B29: Bhamra Transport - Crs | C29: flyash | D29: Expenses | E29: Transport | F29: =SUM(N29:Q29) -> 0 | G29: =I29-H29 -> 311205.16 | H29: =SUMIF(Payments!$D$4:$D$117,'Only Creditors'!B29,Payments!$E$4:$E$130) -> 0 | I29: 311205.16 | J29: 311205.16 | K29: 0 | L29: 0 | M29: 0 | N29: 0 | O29: 0 | P29: 0 | Q29: 0 | R29: 311205.16 | S29: 0
A30: 26 | B30: Bhandari Automobiles Pvt Ltd - Crs | C30: Aggregate | D30: Expenses | E30: Vehicle Exps | F30: To be paid | G30: =I30-H30 -> 0 | H30: =SUMIF(Payments!$D$4:$D$117,'Only Creditors'!B30,Payments!$E$4:$E$130) -> 9150 | I30: 9150 | J30: 0 | K30: 9150 | L30: 0 | M30: 0 | N30: 0 | O30: 0 | P30: 0 | Q30: 0 | R30: 9150 | S30: 0
A31: 27 | B31: Bharat Engineering - Crs | C31: Gujarat | D31: Expenses | E31: Store and spare | F31: =SUM(N31:Q31) -> 0 | G31: =I31-H31 -> 503912 | H31: =SUMIF(Payments!$D$4:$D$117,'Only Creditors'!B31,Payments!$E$4:$E$130) -> 0 | I31: 503912 | J31: 541762 | K31: -37850 | L31: 0 | M31: 0 | N31: 0 | O31: 0 | P31: 0 | Q31: 0 | R31: 503912 | S31: 0
A32: 28 | B32: Bharti Airtel Limited - Crs | C32: Gujarat | D32: Expenses | E32: Office Exps | F32: To be paid | G32: =I32-H32 -> 64940.1 | H32: =SUMIF(Payments!$D$4:$D$117,'Only Creditors'!B32,Payments!$E$4:$E$130) -> 0 | I32: 64940.1 | J32: 64940.1 | K32: 0 | L32: 0 | M32: 0 | N32: 0 | O32: 0 | P32: 0 | Q32: 0 | R32: 64940.1 | S32: 0
A33: 29 | B33: Bipin Jadhav Guest House - Crs | C33: Nagpur | D33: Expenses | E33: Guest House Rent | F33: To be paid | G33: =I33-H33 -> 4500 | H33: =SUMIF(Payments!$D$4:$D$117,'Only Creditors'!B33,Payments!$E$4:$E$130) -> 0 | I33: 4500 | J33: 4500 | K33: 0 | L33: 0 | M33: 0 | N33: 0 | O33: 0 | P33: 0 | Q33: 0 | R33: 4500 | S33: 0
A34: 30 | B34: CB SURATWALA AND SONS-CRS | C34: Gujarat | D34: Expenses | E34: Professional Fees | F34: =SUM(N34:Q34) -> 0 | G34: =I34-H34 -> 7167 | H34: =SUMIF(Payments!$D$4:$D$117,'Only Creditors'!B34,Payments!$E$4:$E$130) -> 0 | I34: 7167 | J34: 7167 | K34: 0 | L34: 0 | M34: 0 | N34: 0 | O34: 0 | P34: 0 | Q34: 0 | R34: 7167 | S34: 0
A35: 31 | B35: CJ DARCL Logistics Limited-Crs | C35: Nellore | D35: Transportation | E35: Transport | F35: =SUM(N35:Q35) -> 2052620 | G35: =I35-H35 -> 3978034.4 | H35: =SUMIF(Payments!$D$4:$D$117,'Only Creditors'!B35,Payments!$E$4:$E$130) -> 0 | I35: 3978034.4 | J35: 409480 | K35: 617885.6 | L35: 781468.8 | M35: 116580 | N35: 646700 | O35: 1405920 | P35: 0 | Q35: 0 | R35: 3978034.4 | S35: 0
A36: 32 | B36: Chettinad Cement Corporation Private Limited - Crs | C36: Vizag | D36: Raw Material | E36: GGBS | F36: =SUM(N36:Q36) -> 0 | G36: =I36-H36 -> 5058891.6 | H36: =SUMIF(Payments!$D$4:$D$117,'Only Creditors'!B36,Payments!$E$4:$E$130) -> 555132 | I36: 5614023.6 | J36: 3105090.6 | K36: 2508933 | L36: 0 | M36: 0 | N36: 0 | O36: 0 | P36: 0 | Q36: 0 | R36: 5614023.6 | S36: 0
A37: 33 | B37: Chukha Ferro Alloys Pvt Ltd- Crs | C37: Haryana | D37: Trading | E37: Bhutan Vendor | F37: To be paid | G37: =I37-H37 -> 32191.76 | H37: =SUMIF(Payments!$D$4:$D$117,'Only Creditors'!B37,Payments!$E$4:$E$130) -> 0 | I37: 32191.76 | J37: 0 | K37: 32191.76 | L37: 0 | M37: 0 | N37: 0 | O37: 0 | P37: 0 | Q37: 0 | R37: 32191.76 | S37: 0
A38: 34 | B38: Connect Residuary Pvt Ltd - Crs | C38: Head Office | D38: Loan EMI | E38: Loan EMI | F38: To be paid | G38: =I38-H38 -> 3.48 | H38: =SUMIF(Payments!$D$4:$D$117,'Only Creditors'!B38,Payments!$E$4:$E$130) -> 0 | I38: 3.48 | J38: 0 | K38: 1.24 | L38: 0 | M38: 0 | N38: 2.24 | O38: 0 | P38: 0 | Q38: 0 | R38: 3.48 | S38: 0
A39: 35 | B39: Csrl-Structwel Lab (Pune) Private Limited Crs | C39: Nagpur | D39: Expenses | E39: Testing charges | F39: To be paid | G39: =I39-H39 -> 0 | H39: =SUMIF(Payments!$D$4:$D$117,'Only Creditors'!B39,Payments!$E$4:$E$130) -> 3933 | I39: 3933 | J39: 0 | K39: 0 | L39: 3933 | M39: 0 | N39: 0 | O39: 0 | P39: 0 | Q39: 0 | R39: 3933 | S39: 0
A40: 36 | B40: CtrlP Solutions Private Limited - Crs | C40: Head Office | D40: Expenses | E40: Office Exps | F40: To be paid | G40: =I40-H40 -> 0 | H40: =SUMIF(Payments!$D$4:$D$117,'Only Creditors'!B40,Payments!$E$4:$E$130) -> 700 | I40: 700 | J40: 0 | K40: 700 | L40: -660.95 | M40: 0 | N40: 0 | O40: 0 | P40: 0 | Q40: 0 | R40: 39.05 | S40: 660.95
...

Sheet Advances
A1: Ultrafine Mineral & Admixtures Pvt. Ltd.
A2: Creditors - Advance Payments (Debit Balances) | As at 31-July-2026
B3: SUBTOTAL | H3: =SUBTOTAL(9,H5:H54) -> -45031978 | I3: =SUBTOTAL(9,I5:I54) -> -4141190 | J3: =SUBTOTAL(9,J5:J54) -> -8008796.6 | K3: =SUBTOTAL(9,K5:K54) -> -124791.9 | L3: =SUBTOTAL(9,L5:L54) -> -815688.58 | M3: =SUBTOTAL(9,M5:M54) -> -30000 | N3: =SUBTOTAL(9,N5:N54) -> -400000 | O3: =SUBTOTAL(9,O5:O54) -> -25207370 | ... R3: =SUBTOTAL(9,R5:R54) -> -298894
A4: # | B4: Vendor Name | C4: Location | D4: Vendor Type | E4: Vendor Sub Type | F4: Remarks | H4: TB Balance (Cr) | I4: 0-30 Days | J4: 31-60 Days | K4: 61-90 Days | L4: 91-120 Days | M4: 121-150 Days | N4: 151-180 Days | O4: 181-365 Days | P4: Above 365 Days | Q4: BW Total | R4: Diff (TB-BW)
A5: 1 | B5: ACE HIMALAYAN FERRO ALLOYS PRIVATE LIMITED - CRS | C5: Haryana | D5: Trading | E5: Bhutan Vendor | F5: Abhay | H5: -94000 | I5: 0 | J5: 0 | K5: -94000 | L5: 0 | M5: 0 | N5: 0 | O5: 0 | P5: 0 | Q5: -94000 | R5: 0
A6: 2 | B6: ASHOKA BUILDCON LIMITED-Crs | C6: Aggregate | D6: Vendor Advance | E6: Vendor Advance | H6: -163127.04 | I6: 0 | J6: 0 | K6: 0 | L6: 0 | M6: 0 | N6: 0 | O6: -150000 | P6: -13127.04 | Q6: -163127.04 | R6: 0
A7: 3 | B7: Abhay Dongare - Employee | C7: Head Office | D7: Employee | E7: Employee | H7: -7148 | I7: 0 | J7: 0 | K7: 0 | L7: -7148 | M7: 0 | N7: 0 | O7: 0 | P7: 0 | Q7: -7148 | R7: 0
A8: 4 | B8: Abhay Singh-Employee | C8: Head Office | D8: Employee | E8: Employee | H8: -4484 | I8: -4484 | J8: 0 | K8: 0 | L8: 0 | M8: 0 | N8: 0 | O8: 0 | P8: 0 | Q8: -4484 | R8: 0
A9: 5 | B9: Ankush Chavan- Employee | C9: Wada | D9: Employee | E9: Employee | H9: -15000 | I9: -15000 | J9: 0 | K9: 0 | L9: 0 | M9: 0 | N9: 0 | O9: 0 | P9: 0 | Q9: -15000 | R9: 0
A10: 6 | B10: Arcelormittal Nippon Steel India Limited - Crs | C10: Gujarat | D10: Vendor Advance | E10: Vendor Advance | H10: -531569.86 | I10: -531569.86 | J10: 0 | K10: 0 | L10: 0 | M10: 0 | N10: 0 | O10: 0 | P10: 0 | Q10: -531569.86 | R10: 0
A11: 7 | B11: Ashvarya Kumar Verma-Employee | C11: Head Office | D11: Employee | E11: Employee | H11: -23510 | I11: 0 | J11: 0 | K11: -10 | L11: -23500 | M11: 0 | N11: 0 | O11: 0 | P11: 0 | Q11: -23510 | R11: 0
A12: 8 | B12: BOMMI SUNEEL KUMAR-Employee | C12: Nellore | D12: Employee | E12: Employee | H12: -25000 | I12: 0 | J12: 0 | K12: 0 | L12: -25000 | M12: 0 | N12: 0 | O12: 0 | P12: 0 | Q12: -25000 | R12: 0
A13: 9 | B13: Bandu Naik - Employee | C13: Gujarat | D13: Employee | E13: Employee | F13: Rakesh Sir | H13: -187504 | I13: -10000 | J13: 0 | K13: 0 | L13: 0 | M13: 0 | N13: 0 | O13: -177504 | P13: 0 | Q13: -187504 | R13: 0
A14: 10 | B14: Bhushan Deshpande - Employee | C14: Head Office | D14: Employee | E14: Employee | F14: JV | H14: -17998 | I14: 0 | J14: -17998 | K14: 0 | L14: 0 | M14: 0 | N14: 0 | O14: 0 | P14: 0 | Q14: -17998 | R14: 0
A15: 11 | B15: C K Paul Gas Agency - Crs | C15: Galsi | D15: Expenses | E15: Repair & Maintenance | H15: -0.25 | I15: -0.25 | J15: 0 | K15: 0 | L15: 0 | M15: 0 | N15: 0 | O15: 0 | P15: 0 | Q15: -0.25 | R15: 0
A16: 12 | B16: Desai Cement Company Pvt Ltd-Crs | C16: Goa | D16: Expenses | E16: BG Incashed | H16: -13962953 | I16: 0 | J16: 0 | K16: 0 | L16: 0 | M16: 0 | N16: 0 | O16: -13962953 | P16: 0 | Q16: -13962953 | R16: 0
A17: 13 | B17: Digambar A. Naik - Crs | C17: Goa | D17: Expenses | E17: GST Claim | F17: Rakesh Sir | H17: -29669.94 | I17: 0 | J17: -29669.94 | K17: 0 | L17: 0 | M17: 0 | N17: 0 | O17: 0 | P17: 0 | Q17: -29669.94 | R17: 0
A18: 14 | B18: ETC POOL - Crs | C18: flyash | D18: Expenses | E18: Regular Advance | H18: -7000 | I18: 276000 | J18: -283000 | K18: 0 | L18: 0 | M18: 0 | N18: 0 | O18: 0 | P18: 0 | Q18: -7000 | R18: 0
A19: 15 | B19: Eurocem Additives Private Limited-Crs | C19: Head Office | D19: Capex | E19: Interest | H19: -2714140 | I19: -2000000 | J19: 0 | K19: 0 | L19: -714140 | M19: 0 | N19: 0 | O19: 0 | P19: 0 | Q19: -2714140 | R19: 0
A20: 16 | B20: Exalt Druk Enviroklens Pvt Ltd - Crs | C20: Haryana | D20: Trading | E20: Bhutan Vendor | F20: Abhay | H20: -2687615 | I20: -300000 | J20: -2387615 | K20: 0 | L20: 0 | M20: 0 | N20: 0 | O20: 0 | P20: 0 | Q20: -2687615 | R20: 0
A21: 17 | B21: Fourteckh Enviro India Pvt Ltd - Crs | C21: Gujarat | D21: Capex | E21: Capex Advance | H21: -2884000 | I21: -1656000 | J21: -1228000 | K21: 0 | L21: 0 | M21: 0 | N21: 0 | O21: 0 | P21: 0 | Q21: -2884000 | R21: 0
A22: 18 | B22: H R Industries - Crs | C22: Bangalore | D22: Trading | E22: GGBS | F22: Saif Sir | H22: -19032.8 | I22: 0 | J22: 0 | K22: 0 | L22: 0 | M22: 0 | N22: 0 | O22: -19032.8 | P22: 0 | Q22: -19032.8 | R22: 0
A23: 19 | B23: Harsh Raj - EMPLOYEE | C23: Head Office | D23: Employee | E23: Employee | H23: -4421 | I23: -4421 | J23: 0 | K23: 0 | L23: 0 | M23: 0 | N23: 0 | O23: 0 | P23: 0 | Q23: -4421 | R23: 0
A24: 20 | B24: Indian Oil Corporation Limited - Crs | C24: Wada | D24: Expenses | E24: Regular Advance | H24: -195874.65 | I24: 131705.39 | J24: -327580.04 | K24: 0 | L24: 0 | M24: 0 | N24: 0 | O24: 0 | P24: 0 | Q24: -195874.65 | R24: 0
A25: 21 | B25: JAI Energy Giant Engineering and consultancy - Crs | C25: Nagpur | D25: Capex | E25: Capex Advance | H25: -4692357 | I25: 0 | J25: 0 | K25: 0 | L25: 0 | M25: 0 | N25: 0 | O25: 0 | P25: -4692357 | Q25: -4692357 | R25: 0
A26: 22 | B26: JASSPER SHIPPING INDIA LIMITED- CRS | C26: Goa | D26: Transportation | E26: GST Claim | F26: legal mail | H26: -653396 | I26: 0 | J26: 0 | K26: 0 | L26: 0 | M26: 0 | N26: 0 | O26: -653396 | P26: 0 | Q26: -653396 | R26: 0
A27: 23 | B27: Jpgr Automobile Private Limited-Crs | C27: Wada | D27: Expenses | E27: Repair & Maintenance | H27: -0.68 | I27: -0.68 | J27: 0 | K27: 0 | L27: 0 | M27: 0 | N27: 0 | O27: 0 | P27: 0 | Q27: -0.68 | R27: 0
A28: 24 | B28: KFin Technologies Limited - Crs | C28: Howrah | D28: Expenses | E28: Professional Fees | H28: -5900 | I28: 0 | J28: 0 | K28: 0 | L28: -5900 | M28: 0 | N28: 0 | O28: 0 | P28: 0 | Q28: -5900 | R28: 0
A29: 25 | B29: Karim Shah - Employee | C29: Head Office | D29: Employee | E29: Employee | H29: -25507 | I29: -4493 | J29: 0 | K29: 0 | L29: 0 | M29: 0 | N29: 0 | O29: 0 | P29: 0 | Q29: -4493 | R29: -21014
A30: 26 | B30: Kinshar Metals - Crs | C30: Haryana | D30: Trading | E30: Bhutan Vendor | F30: Abhay | H30: -2874700 | I30: -222120 | J30: -2374700 | K30: 0 | L30: 0 | M30: 0 | N30: 0 | O30: 0 | P30: 0 | Q30: -2596820 | R30: -277880
A31: 27 | B31: LAXMI ENGINEERING INDUSTRIES - CRS | C31: Galsi | D31: Expenses | E31: Capex Advance | H31: -5781.9 | I31: 0 | J31: 0 | K31: -5781.9 | L31: 0 | M31: 0 | N31: 0 | O31: 0 | P31: 0 | Q31: -5781.9 | R31: 0
A32: 28 | B32: M/s Hms International-Crs | C32: Wada | D32: Expenses | E32: Sales Promotion Exps | F32: Cleared | H32: -179000 | I32: 0 | J32: -179000 | K32: 0 | L32: 0 | M32: 0 | N32: 0 | O32: 0 | P32: 0 | Q32: -179000 | R32: 0
A33: 29 | B33: M/s Manuwar Shaikh (Crusher)- Crs | C33: Microsilica | D33: Expenses | E33: Pending from Vendor | F33: ashutosh | H33: -600000 | I33: 0 | J33: 0 | K33: 0 | L33: 0 | M33: 0 | N33: 0 | O33: -600000 | P33: 0 | Q33: -600000 | R33: 0
A34: 30 | B34: MACPOWER ELECTRICALS-Crs (Cap) | C34: Galsi | D34: Capex | E34: Capex Advance | H34: -141300 | I34: 353700 | J34: -495000 | K34: 0 | L34: 0 | M34: 0 | N34: 0 | O34: 0 | P34: 0 | Q34: -141300 | R34: 0
A35: 31 | B35: MNG Automobiles Pvt Ltd - CRS | C35: Goa | D35: Expenses | E35: Vehicle Expenses | H35: -6891.58 | I35: 0 | J35: -6891.58 | K35: 0 | L35: 0 | M35: 0 | N35: 0 | O35: 0 | P35: 0 | Q35: -6891.58 | R35: 0
A36: 32 | B36: Narvekar Brothers - Crs | C36: Goa | D36: Expenses | E36: Stores and Spares | H36: -6048 | I36: 0 | J36: -6048 | K36: 0 | L36: 0 | M36: 0 | N36: 0 | O36: 0 | P36: 0 | Q36: -6048 | R36: 0
A37: 33 | B37: Rajeswar Polai - Employee | C37: Goa | D37: Employee | E37: Employee | H37: -25000 | I37: 0 | J37: 0 | K37: -25000 | L37: 0 | M37: 0 | N37: 0 | O37: 0 | P37: 0 | Q37: -25000 | R37: 0
A38: 34 | B38: Remi Sales and Engineering Ltd - Crs | C38: Goa | D38: Expenses | E38: Testing and Inspection | H38: -1852.02 | I38: 0 | J38: -1852.02 | K38: 0 | L38: 0 | M38: 0 | N38: 0 | O38: 0 | P38: 0 | Q38: -1852.02 | R38: 0
A39: 35 | B39: Rohit Prasad - Employee | C39: Gujarat | D39: Employee | E39: Employee | H39: -25000 | I39: 0 | J39: 0 | K39: 0 | L39: -25000 | M39: 0 | N39: 0 | O39: 0 | P39: 0 | Q39: -25000 | R39: 0
A40: 36 | B40: SGS Impex - Crs | C40: Gujarat | D40: Expenses | E40: Adjusted against Kinshar Metals | F40: Abhay 20 aug | H40: -400000 | I40: 0 | J40: 0 | K40: 0 | L40: 0 | M40: 0 | N40: -400000 | O40: 0 | P40: 0 | Q40: -400000 | R40: 0
...

Sheet Sheet1
B2: Vendor Name | C2: Location | D2: TB Balance (Cr) | E2: 0-30 Days | F2: 31-60 Days | G2: 61-90 Days | H2: 91-120 Days | I2: 121-150 Days | J2: 151-180 Days | K2: 181-365 Days | L2: Above 365 Days | M2: BW Total
B3: Kinshar Metals - Crs | C3: Haryana | D3: -2874700 | E3: -222120 | F3: -2374700 | G3: 0 | H3: 0 | I3: 0 | J3: 0 | K3: 0 | L3: 0 | M3: -2596820
B4: Exalt Druk Enviroklens Pvt Ltd - Crs | C4: Haryana | D4: -2687615 | E4: -300000 | F4: -2387615 | G4: 0 | H4: 0 | I4: 0 | J4: 0 | K4: 0 | L4: 0 | M4: -2687615
B5: SGS Impex - Crs | C5: Gujarat | D5: -400000 | E5: 0 | F5: 0 | G5: 0 | H5: 0 | I5: 0 | J5: -400000 | K5: 0 | L5: 0 | M5: -400000
B6: ACE HIMALAYAN FERRO ALLOYS PRIVATE LIMITED - CRS | C6: Haryana | D6: -94000 | E6: 0 | F6: 0 | G6: -94000 | H6: 0 | I6: 0 | J6: 0 | K6: 0 | L6: 0 | M6: -94000
D8: =SUM(D3:D7) -> -6056315 | E8: =SUM(E3:E7) -> -522120 | F8: =SUM(F3:F7) -> -4762315 | G8: =SUM(G3:G7) -> -94000 | H8: =SUM(H3:H7) -> 0 | I8: =SUM(I3:I7) -> 0 | J8: =SUM(J3:J7) -> -400000 | K8: =SUM(K3:K7) -> 0 | ... M8: =SUM(M3:M7) -> -5778435

Sheet Intercompany
A1: Ultrafine Mineral & Admixtures Pvt. Ltd.
A2: Creditors Ageing Report - Intercompany & Special | As at 31-July-2026
B3: SUBTOTAL | E3: =SUM(E5:E21) -> 1.2133057e+08 | F3: =SUM(F5:F21) -> 4133810.8 | G3: =SUM(G5:G21) -> 21034576 | H3: =SUM(H5:H21) -> 4849961.4 | I3: =SUM(I5:I21) -> 5021160.7 | J3: =SUM(J5:J21) -> 27744692 | K3: =SUM(K5:K21) -> 7489095.8 | L3: =SUM(L5:L21) -> 28657615 | ... O3: =SUM(O5:O21) -> 0
A4: # | B4: Vendor Name | C4: Vendor Type | E4: TB Balance (Cr) | F4: 0-30 Days | G4: 31-60 Days | H4: 61-90 Days | I4: 91-120 Days | J4: 121-150 Days | K4: 151-180 Days | L4: 181-365 Days | M4: Above 365 Days | N4: BW Total | O4: Diff (TB-BW)
A5: 1 | B5: RDC Concrete India Pvt. Ltd. Punjab - Crs | C5: Intercompany | E5: 30680 | F5: 0 | G5: 0 | H5: 0 | I5: 0 | J5: 0 | K5: 0 | L5: 30680 | M5: 0 | N5: 30680 | O5: 0
A6: 2 | B6: RDC Concrete (India) Pvt Ltd (Bangalore)-Crs | C6: Intercompany | E6: 215334 | F6: 0 | G6: 0 | H6: 0 | I6: 0 | J6: 0 | K6: 0 | L6: 215334 | M6: 0 | N6: 215334 | O6: 0
A7: 3 | B7: RDC Concrete (India) Pvt Ltd (Haryana)-Crs | C7: Intercompany | E7: 332760 | F7: 0 | G7: 0 | H7: 0 | I7: 0 | J7: 332760 | K7: 0 | L7: 0 | M7: 0 | N7: 332760 | O7: 0
A8: 4 | B8: RDC Concrete India Pvt Ltd (NCR)-Crs | C8: Intercompany | E8: 370425.6 | F8: 0 | G8: 0 | H8: 0 | I8: 0 | J8: 0 | K8: 0 | L8: 370425.6 | M8: 0 | N8: 370425.6 | O8: 0
A9: 5 | B9: RDC Concrete (India) Pvt Ltd (Pune)- Crs | C9: Intercompany | E9: 511161.75 | F9: 22815.75 | G9: 0 | H9: 0 | I9: 0 | J9: 0 | K9: 235800 | L9: 252546 | M9: 0 | N9: 511161.75 | O9: 0
A10: 6 | B10: RDC Concrete (India) Pvt Ltd (chattisgarh) - Crs | C10: Intercompany | E10: 590000 | F10: 0 | G10: 0 | H10: 0 | I10: 0 | J10: 0 | K10: 0 | L10: 590000 | M10: 0 | N10: 590000 | O10: 0
A11: 7 | B11: NEPTUNE READYMIX CONCRETE.PVT.LTD - MUPPATHADOM - Crs | C11: Intercompany | E11: 708759.9 | F11: 0 | G11: 0 | H11: 0 | I11: 0 | J11: 0 | K11: 0 | L11: 0 | M11: 708759.9 | N11: 708759.9 | O11: 0
A12: 8 | B12: Neptune Readymix Concrete Pvt. Ltd.(Cochin)-Vendor - Crs | C12: Intercompany | E12: 731051 | F12: 0 | G12: 0 | H12: 0 | I12: 0 | J12: 0 | K12: 0 | L12: 0 | M12: 731051 | N12: 731051 | O12: 0
A13: 9 | B13: RDC Concrete (India) Pvt Ltd (Chennai)-Crs | C13: Intercompany | E13: 1654914 | F13: 42444 | G13: 0 | H13: 0 | I13: 212400 | J13: 637200 | K13: 323910 | L13: 438960 | M13: 0 | N13: 1654914 | O13: 0
A14: 10 | B14: RDC Concrete (India) Pvt Ltd (Gujarat)-Crs | C14: Intercompany | E14: 1675373.1 | F14: 0 | G14: 52259.17 | H14: 1545263.4 | I14: 0 | J14: 0 | K14: 0 | L14: 77850.5 | M14: 0 | N14: 1675373.1 | O14: 0
A15: 11 | B15: RDC Concrete (India) Pvt Ltd (Telangana)- Crs | C15: Intercompany | E15: 6318122 | F15: 347743.5 | G15: 906231 | H15: 352856.76 | I15: 317874.38 | J15: 542348.64 | K15: 392437.5 | L15: 3458630.2 | M15: 0 | N15: 6318122 | O15: 0
A16: 12 | B16: SOCIAM EQUIPMENT SOLUTIONS PRIVATE LIMITED-CRS | C16: Intercompany | E16: 8446869.4 | F16: 412960 | G16: 412960 | H16: 412960 | I16: 412960 | J16: 412960 | K16: 412960 | L16: 5149321.8 | M16: 819787.64 | N16: 8446869.4 | O16: 0
... A21: 17 | B21: RDC Concrete (India) Pvt Ltd (Kolkata)-Crs | C21: Intercompany | E21: 38159903 | F21: 2933987.6 | G21: 3204745.7 | H21: 568112.6 | I21: 1677602.8 | J21: 19935746 | K21: 470229.6 | L21: 5119764.4 | M21: 4249714.4 | N21: 38159903 | O21: 0
B23: Grand Total | E23: =SUM(E5:E21) -> 1.2133057e+08 | F23: =SUM(F5:F21) -> 4133810.8 | G23: =SUM(G5:G21) -> 21034576 | H23: =SUM(H5:H21) -> 4849961.4 | I23: =SUM(I5:I21) -> 5021160.7 | J23: =SUM(J5:J21) -> 27744692 | K23: =SUM(K5:K21) -> 7489095.8 | L23: =SUM(L5:L21) -> 28657615 | ... O23: =SUM(O5:O21) -> 0

Sheet Review
A1: Review Items | Creditors Ageing as at 31-July-2026
A3: A. New vendors - classification required (25)
A4: Vendor Name | B4: Location (from cost centre) | C4: TB Balance | D4: Vendor Type | E4: Vendor Sub Type
A5: Aadhya Shakti Enterprise-Crs | B5: Gujarat | C5: 106912.12
A6: Arya CS - Crs | B6: Nagpur | C6: 3000
A7: Balram Kumar Chakrawarti - Employee | B7: Vizag | C7: 413424
A8: D.K. SERVICES - Crs | B8: Nagpur | C8: 45611.2
A9: Harish Ludhani - Employee | B9: Head Office | C9: 974095.2
A10: Jai Bhairunath | B10: Aggregate | C10: 10856
A11: KAMAL S PATIL - Crs | B11: Wada | C11: 34630.2
A12: KAPIL THAKARE - Crs | B12: Wada | C12: 5495
A13: Krishna Enterprise(Guj)-Crs | B13: Gujarat | C13: 2478
A14: Krishna Konar - Crs | B14: Galsi | C14: 18000
A15: Krishnendu Konar CRS | B15: Galsi | C15: 37000
A16: M B ENTERPRISE- Crs | B16: Galsi | C16: 81011.2
... A29: Tathoi Enterprise - Crs | B29: Galsi | C29: 700906.24
A31: B. New vendors - auto-classified, please confirm (23)
A32: Vendor Name | B32: Location | C32: TB Balance | D32: Vendor Type (suggested) | E32: Vendor Sub Type (suggested)
A33: AVENGERS SECURITY SERVICES-CR | B33: Nellore | C33: 33434.68 | D33: Expenses | E33: Security charges
A34: Agile Innotech - Crs | B34: Aggregate | C34: 11328 | D34: Expenses | E34: Office Exps
A35: Best Electro Mech-Crs | B35: Wada | C35: 9762.76 | D35: Expenses | E35: Store and spare
A36: Bharti Airtel Limited - Crs | B36: Gujarat | C36: 64940.1 | D36: Expenses | E36: Office Exps
A37: Bipin Jadhav Guest House - Crs | B37: Nagpur | C37: 4500 | D37: Expenses | E37: Guest House Rent
A38: CB SURATWALA AND SONS-CRS | B38: Gujarat | C38: 7167 | D38: Expenses | E38: Professional Fees
A39: Dev Security Services- Crs | B39: Aggregate | C39: 113558 | D39: Expenses | E39: Security charges
A40: First Choice Logistics-Crs | B40: Wada | C40: 153802.5 | D40: Transportation | E40: Transport
A41: Harrier Security Services Private Limited-Crs | B41: Wada | C41: 60336.57 | D41: Expenses | E41: Security charges
A42: Info Tech Computers - Crs | B42: Nagpur | C42: 924.16 | D42: Expenses | E42: Office Exps
A43: JANTA CEMENT INDUSTRIES-Crs | B43: Nagpur | C43: 279918.46 | D43: Trading | E43: Flyash
A44: JINENDRA AUTO PARTS-Crs | B44: Gujarat | C44: 10091 | D44: Expenses | E44: Store and spare
... A55: Yaa Baba Taj Restaurants - CRS | B55: Nagpur | C55: 4516 | D55: Expenses | E55: Staff Welfare
A57: C. TB vs Bill-Wise differences (3)
A58: Vendor Name | B58: Tab | C58: TB Balance | D58: BW Total | E58: Diff (TB-BW)
A59: CtrlP Solutions Private Limited - Crs | B59: Only Creditors | C59: 700 | D59: 39.05 | E59: 660.95
A60: Karim Shah - Employee | B60: Advances | C60: -25507 | D60: -4493 | E60: -21014
A61: Kinshar Metals - Crs | B61: Advances | C61: -2874700 | D61: -2596820 | E61: -277880
A63: D. Nil-balance vendors excluded (open bills net to zero in TB) (12)
A64: Vendor Name | B64: Bills | C64: Gross of bills | D64: Net after netting
A65: Anantha Vamshider Reddy - Employee | B65: 1 | C65: 20512 | D65: 20512
A66: MANNAT CONSTRUCTIONS - Crs | B66: 3 | C66: 216484 | D66: 0
...

Sheet Payments
C2: Total | E2: =SUBTOTAL(9,E4:E141) -> 34536948
B3: Date | C3: Description | D3: Name | E3: Amount | F3: UTR No | G3: Location | H3: CF Location
B4: 46235.174 | C4: AUTO INTEREST PAYMENT ON TERM LOAN AGAINST 5WSLN06240060003 | D4: Interest on Term Loan | E4: 352078 | F4: 5WSLN06240060003 | G4: Head Office | H4: Head Office
B5: 46235.296 | C5: Jadav Enterprise | D5: M/s Jadav Enterprise - Crs | E5: 730112 | F5: HDFCH01162147885 | G5: Aggregate | H5: Aggregate Panagarh Crusher
B6: 46235.296 | C6: P.S. Agency-CRS | D6: P.S. Agency-CRS | E6: 500000 | F6: HDFCH01162149041 | G6: Aggregate | H6: Aggregate pachami trading
B7: 46235.296 | C7: Kamakhya Enterprise | D7: Kamakhya Enterprises - Crs | E7: 492928.21 | F7: HDFCH01162149821 | G7: Aggregate | H7: Aggregate Panagarh Crusher
B8: 46235.572 | C8: Enet_ST CHG_ULTMIAN-CDT2621341895107 | D8: Bank Charges | E8: 590 | F8: CDT2621341895107 | G8: Head Office | H8: Main Operation
B9: 46235.635 | C9: ETC POOL | D9: ETC POOL - Crs | E9: 28000 | F9: HDFCH01163334322 | G9: Gujarat | H9: Main Operation
B10: 46235.635 | C10: ETC POOL | D10: ETC POOL - Crs | E10: 172000 | F10: HDFCH01163334322 | G10: Aggregate | H10: Aggregate Panagarh Crusher
B11: 46235.776 | C11: JFC Logistics | D11: JFC Logistics - Crs | E11: 300000 | F11: 608018651316 | G11: Goa | H11: Main Operation
B12: 46235.776 | C12: Sumit Goods Carrier | D12: Sumit Goods Carrier(Arabinda Kumar Das) - CRS | E12: 192200 | F12: 608018651325 | G12: Haryana | H12: Trading Business
B13: 46235.776 | C13: Devanand B Singh | D13: Devanand B. Singh - Employee | E13: 756000 | F13: HDFCH01164212484 | G13: Head Office | H13: Main Operation
B14: 46235.776 | C14: Shreeji Sales Corp | D14: Shreeji Sales Corporation-Crs | E14: 41480 | F14: HDFCH01164216054 | G14: Gujarat | H14: Main Operation
B15: 46235.777 | C15: THORON TURNKEY PVT | D15: THORON TURNKEY SOLUTIONS PRIVATE LIMITED-CRS | E15: 94814.01 | F15: HDFCH01164215435 | G15: Gujarat | H15: Main Operation
B16: 46235.777 | C16: STEP IN TECHNOLOGIE | D16: STEP IN TECHNOLOGIES-CRS | E16: 136560.6 | F16: HDFCH01164213377 | G16: TamilNadu | H16: Main Operation
B17: 46235.777 | C17: A Abdul Hameed | D17: A. Abdul Hameed - Crs | E17: 225000 | F17: HDFCH01164213978 | G17: Goa | H17: Main Operation
B18: 46235.777 | C18: G D Packaging | D18: G D Packaging - Crs | E18: 137428 | F18: HDFCH01164216833 | G18: Vizag | H18: Main Operation
B19: 46236.493 | C19: FT-IOCLXPP1002085506-IOCL | D19: Indian Oil Corporation Limited - Crs | E19: 58000 | F19: 607316199847 | G19: Gujarat | H19: Main Operation
B20: 46236.493 | C20: FT-IOCLXPP1002085506-IOCL | D20: Indian Oil Corporation Limited - Crs | E20: 42000 | F20: 607316199847 | G20: Flyash | H20: Flyash Business
B21: 46236.493 | C21: FT-IOCLXPP1002085506-IOCL | D21: Indian Oil Corporation Limited - Crs | E21: 100000 | F21: 607316199847 | G21: Aggregate | H21: Aggregate Panagarh Crusher
B22: 46236.493 | C22: FT-IOCLXPP1002085506-IOCL | D22: Indian Oil Corporation Limited - Crs | E22: 58000 | F22: 607316199845 | G22: Gujarat | H22: Main Operation
B23: 46236.493 | C23: FT-IOCLXPP1002085506-IOCL | D23: Indian Oil Corporation Limited - Crs | E23: 42000 | F23: 607316199845 | G23: Flyash | H23: Flyash Business
B24: 46236.493 | C24: FT-IOCLXPP1002085506-IOCL | D24: Indian Oil Corporation Limited - Crs | E24: 100000 | F24: 607316199845 | G24: Aggregate | H24: Aggregate Panagarh Crusher
B25: 46237.543 | C25: FT-CHETTINAD9214181-Chettinad Cement | D25: Chettinad Cement Corporation Private Limited - Crs | E25: 397403 | F25: 608038926716 | G25: Vizag | H25: Main Operation
B26: 46237.543 | C26: RMB KNOVATECH PVT LT | D26: RMB KNOVATECH PVT LTD. - Crs | E26: 199520 | F26: 608018651342 | G26: Nagpur | H26: Capex
B27: 46237.543 | C27: Nirmal and Co - Crs | D27: Nirmal and Co - Crs | E27: 479644.55 | F27: HDFCH01166126622 | G27: Gujarat | H27: Main Operation
B28: 46237.543 | C28: SREERAMA INDUSTRY | D28: SREERAMA INDUSTRIES PRIVATE LIMITED-Crs | E28: 2192060 | F28: HDFCH01166122720 | G28: Vizag | H28: Main Operation
B29: 46237.543 | C29: Siddhi Vinayak Corpo | D29: Siddhi Vinayak Corporation-Crs | E29: 456010 | F29: HDFCH01166122724 | G29: Gujarat | H29: Main Operation
B30: 46237.543 | C30: DOED JUNG KUEN PHEN | D30: DOED JUNG KUEN PHEN TRADING HOUSE-CRS | E30: 500000 | F30: HDFCH01166126641 | G30: Haryana | H30: Trading Business
B31: 46237.543 | C31: Shree Mahalaxmi Tra | D31: Shree Mahalaxmi Traders-Crs | E31: 373688 | F31: HDFCH01166128235 | G31: Gujarat | H31: Main Operation
B32: 46237.543 | C32: Puneet Logistics-Crs | D32: Puneet Logistics-Crs | E32: 100000 | F32: HDFCH01166128321 | G32: Gujarat | H32: Main Operation
B33: 46237.788 | C33: RTGS Dr-SBIN0005996-ArcelormittalNippo-NETBANK MUM-HDFCR52026080391506105 | D33: Arcelormittal Nippon Steel India Limited - Crs | E33: 400000 | F33: HDFCR52026080391506105 | G33: Gujarat | H33: Main Operation
B34: 46237.801 | C34: FT-IOCLXPP1002085506-IOCL | D34: Indian Oil Corporation Limited - Crs | E34: 200000 | F34: 607316199846 | G34: Gujarat | H34: Main Operation
B35: 46237.801 | C35: Csrl Structwel Lab | D35: Csrl-Structwel Lab (Pune) Private Limited Crs | E35: 3933 | F35: 608018651328 | G35: Nagpur | H35: Main Operation
B36: 46237.801 | C36: Bhandari Automobiles | D36: Bhandari Automobiles Pvt Ltd - Crs | E36: 9150 | F36: HDFCH01167731664 | G36: Aggregate | H36: Aggregate Panagarh Crusher
B37: 46237.801 | C37: Dmk Logistic | D37: Dmk Logistic - Crs | E37: 3286.91 | F37: HDFCH01167731665 | G37: Bangalore | H37: Trading Business
B38: 46237.801 | C38: NIGAM CAR SERVICES | D38: NIGAM CAR SERVICES | E38: 20958 | F38: HDFCH01167731666 | G38: Aggregate | H38: Aggregate Panagarh Crusher
B39: 46237.801 | C39: BISWAJIT RUI DAS | D39: BISWAJIT RUI DAS - Crs | E39: 36262.88 | F39: HDFCH01167737254 | G39: Galsi | H39: Main Operation
B40: 46237.801 | C40: DEVENDRA CHAUHAN | D40: DEVENDRA CHAUHAN REFRACTORY WORKS -CRS | E40: 43200 | F40: HDFCH01167734968 | G40: Gujarat | H40: Capex
B41: 46237.801 | C41: Dutta Auto Centre | D41: Dutta Auto Centre | E41: 36049.4 | F41: HDFCH01167731669 | G41: Galsi | H41: Main Operation
...
