Workbook

Sheet TB
A1: Ultrafine Mineral & Admixtures Pvt. Ltd.
A2: 76/1N, Wardha Road, Mouza Dongargaon, Nagpur,
A3: Maharashtra- 441108
A4: UDYAM : UDYAM-MH-20-0007365 (Small/Mfgr)
A5: CIN: U24100MH2020PTC338575
A6: Sundry Creditors
A7: Group Summary
A8: 1-Apr-26 to 30-Jun-26 | B8: =SUBTOTAL(9,B11:B266) -> 44503459 | C8: =SUBTOTAL(9,C11:C266) -> 3.1335228e+08
B9: Closing Balance
A10: Particulars | B10: Debit | C10: Credit
A12: Abhay Dongare - Employee | B12: 15161
A13: Abhay Singh-Employee | C13: 3519
A14: Abhishek Kumar Nayak - Employee | C14: 18812
A15: Accurate Engineering Works-Crs | C15: 30444
A16: ACE HIMALAYAN FERRO ALLOYS PRIVATE LIMITED - CRS | B16: 94000
A17: ADHUNIK TRASNPORT ORGANISATION LIMITED - Crs | C17: 80439.38
A18: ADVITA POLYCRAFT LLP - Crs | C18: 655797.08
A19: AIRMAX AUTOMATION - CRS | C19: 35913.4
A20: Akash Body Bildders-CRS | C20: 300000.02
A21: AKBAR TRAVELS OF INDIA PVT. LTD-Crs | C21: 104715
A22: AKRUTI ENTERPRISE-CRS | C22: 24564.26
A23: AMBUJA CEMENTS LIMITED -Crs | C23: 8563184.6
A24: Arcelormittal Nippon Steel India Limited - Crs | B24: 557957.34
A25: ARKAY LOGISTICS-Crs | C25: 848978.08
A26: Arya CS - Crs | C26: 3000
A27: ASHCONNECT GLOBAL TRADING Pvt Ltd- Crs | C27: 8639888.8
A28: ASHOKA BUILDCON LIMITED-Crs | B28: 163127.04
A29: Ashvarya Kumar Verma-Employee | B29: 23510
A30: Asia Minerals and Machinery Company - Crs | C30: 603502
A31: Asl Logistics Private Limited-Crs | C31: 6959753.5
A32: Atharva Enterprises - Crs | C32: 200175.08
A33: AVENGERS SECURITY SERVICES-CR | C33: 42305.6
A34: Avijit Chaubey - Employee | C34: 125285.4
A35: BAHUBALI CHEMICAL INDUSTRIES-CRS | C35: 7521130.2
A36: Balram Kumar Chakrawarti - Employee | C36: 372600
A37: Bandu Naik - Employee | B37: 187920
A38: BGR Constructions - Crs | C38: 968310
A39: Bhailal Jethva - Employee | C39: 78300
A40: Bhamra Transport - Crs | C40: 464872.27
A41: Bhandari Automobiles Pvt Ltd - Crs | C41: 9150
...

Sheet Bill Wise
A1: Group : | B1: Sundry Creditors | D1: 1-Apr-26 to 30-Jun-26
A2: Details of: | B2: Pending Bills
A4: Date | B4: Ref. No. | C4: Party's Name | D4: Cost Center/Location | E4: Opening Amount | F4: Pending Amount | G4: Overdue Days | H4: Ageing Bucket | I4: New Amt
A5: 44357 | B5: CHN/2122/00447 | C5: Neptune Readymix Concrete Pvt. Ltd.(Cochin)-Vendor - Crs | D5: Bangalore | E5: 85567 | F5: 85567 | G5: 1846 | H5: Above 365 Days | I5: 85567
A6: 44361 | B6: CHN/2122/00452 | C6: Neptune Readymix Concrete Pvt. Ltd.(Cochin)-Vendor - Crs | D6: Bangalore | E6: 62940 | F6: 62940 | G6: 1842 | H6: Above 365 Days | I6: 62940
A7: 44383 | B7: CHN/2122/00448 | C7: Neptune Readymix Concrete Pvt. Ltd.(Cochin)-Vendor - Crs | D7: Bangalore | E7: 78182 | F7: 78182 | G7: 1820 | H7: Above 365 Days | I7: 78182
A8: 44400 | B8: CHN/2122/00453 | C8: Neptune Readymix Concrete Pvt. Ltd.(Cochin)-Vendor - Crs | D8: Bangalore | E8: 73765 | F8: 73765 | G8: 1803 | H8: Above 365 Days | I8: 73765
A9: 44456 | B9: CHN/2122/00543 | C9: Neptune Readymix Concrete Pvt. Ltd.(Cochin)-Vendor - Crs | D9: Bangalore | E9: 74180 | F9: 74180 | G9: 1747 | H9: Above 365 Days | I9: 74180
A10: 44473 | B10: CHN/2122/00547 | C10: Neptune Readymix Concrete Pvt. Ltd.(Cochin)-Vendor - Crs | D10: Bangalore | E10: 92865 | F10: 92865 | G10: 1730 | H10: Above 365 Days | I10: 92865
A11: 44488 | B11: CHN/2122/00548 | C11: Neptune Readymix Concrete Pvt. Ltd.(Cochin)-Vendor - Crs | D11: Bangalore | E11: 71512 | F11: 71512 | G11: 1715 | H11: Above 365 Days | I11: 71512
A12: 44493 | B12: CHN/2122/00560 | C12: Neptune Readymix Concrete Pvt. Ltd.(Cochin)-Vendor - Crs | D12: Bangalore | E12: 15314 | F12: 15314 | G12: 1710 | H12: Above 365 Days | I12: 15314
A13: 44500 | B13: CHN/2122/00562 | C13: Neptune Readymix Concrete Pvt. Ltd.(Cochin)-Vendor - Crs | D13: Bangalore | E13: 81842 | F13: 81842 | G13: 1703 | H13: Above 365 Days | I13: 81842
A14: 44535 | B14: CHN/2122/00579 | C14: Neptune Readymix Concrete Pvt. Ltd.(Cochin)-Vendor - Crs | D14: Bangalore | E14: 19959 | F14: 19959 | G14: 1668 | H14: Above 365 Days | I14: 19959
A15: 44545 | B15: CHN/21-22/00577 | C15: NEPTUNE READYMIX CONCRETE.PVT.LTD - MUPPATHADOM - Crs | D15: Bangalore | E15: 72416 | F15: 72416 | G15: 1658 | H15: Above 365 Days | I15: 72416
A16: 44546 | B16: CHN/21-22/00578 | C16: NEPTUNE READYMIX CONCRETE.PVT.LTD - MUPPATHADOM - Crs | D16: Bangalore | E16: 56484 | F16: 56484 | G16: 1657 | H16: Above 365 Days | I16: 56484
... A78: 45594 | B78: LSPL/24-25/400 | C78: Lub Solutions Pvt Ltd - Crs | D78: Goa | E78: 786935 | F78: 786935 | G78: 609 | H78: Above 365 Days | I78: 786935
A79: 45692 | B79: 509 | C79: ASHOKA BUILDCON LIMITED-Crs | E79: 800000 | F79: 13127.04 | G79: 511 | H79: Above 365 Days | I79: -13127.04
A80: 45722 | B80: 1750246755 | C80: SOCIAM EQUIPMENT SOLUTIONS PRIVATE LIMITED-CRS | D80: Gujarat | E80: 875733.94 | F80: 1529560 | G80: 481 | H80: Above 365 Days | I80: 1529560
A81: 45747 | B81: WEET/RDC/024 | C81: Well Erectors Of Engineering Technology Private Limited - Crs | E81: 1318560.8 | F81: 819292.57 | G81: 456 | H81: Above 365 Days | I81: 819292.57
A82: 45777 | B82: JV/HO/2526/0009 | C82: RDC Concrete (India) Pvt Ltd (Head Office) - Crs | D82: Head Office | E82: 943113.04 | F82: 1736215 | G82: 426 | H82: Above 365 Days | I82: 1736215
A83: 45798 | B83: 20KGRL/2025-26 | C83: KGR Logistics - Crs | D83: Nellore | E83: 1503348 | F83: 300000.7 | G83: 405 | H83: Above 365 Days | I83: 300000.7
A84: 45806 | B84: 038 | C84: SREERAMA INDUSTRIES PRIVATE LIMITED-Crs | D84: Vizag | E84: 247299 | F84: 172046 | G84: 397 | H84: Above 365 Days | I84: 172046
A85: 45808 | B85: JV/HO/2526/0024 | C85: RDC Concrete (India) Pvt Ltd (Head Office) - Crs | D85: Head Office | E85: 834281.26 | F85: 834281.26 | G85: 395 | H85: Above 365 Days | I85: 834281.26
A86: 45808 | B86: 07 | C86: TMS ENTERPRISES - Crs | D86: Gujarat | E86: 292918.56 | F86: 346127.76 | G86: 395 | H86: Above 365 Days | I86: 346127.76
A87: 45811 | B87: 027 | C87: Dattakrupa Minerals - Crs | D87: Goa | E87: 5610552.2 | F87: 310552.2 | G87: 392 | H87: Above 365 Days | I87: 310552.2
A88: 45812 | B88: PV/GUJ/2526/0123 | C88: Steel & Power-CR (CAP) - Crs | E88: 300000 | F88: 300000 | G88: 391 | H88: Above 365 Days | I88: -300000
A89: 45813 | B89: 190 | C89: SULTAN ENTERPRISES-CRS | E89: 110487.82 | F89: 110487.82 | G89: 390 | H89: Above 365 Days | I89: 110487.82
A90: 45814 | B90: 189 | C90: SULTAN ENTERPRISES-CRS | E90: 100716 | F90: 100716 | G90: 389 | H90: Above 365 Days | I90: 100716
A91: 45818 | B91: 191 | C91: SULTAN ENTERPRISES-CRS | E91: 106677.9 | F91: 106677.9 | G91: 385 | H91: Above 365 Days | I91: 106677.9
A92: 45825 | B92: 192 | C92: SULTAN ENTERPRISES-CRS | E92: 108055.5 | F92: 108055.5 | G92: 378 | H92: Above 365 Days | I92: 108055.5
A93: 45826 | B93: Ash/12 | C93: ASHCONNECT GLOBAL TRADING Pvt Ltd- Crs | E93: 537661 | F93: 64759.02 | G93: 377 | H93: Above 365 Days | I93: 64759.02
A94: 45838 | B94: ASH/13 | C94: ASHCONNECT GLOBAL TRADING Pvt Ltd- Crs | E94: 246403.27 | F94: 246403.27 | G94: 365 | H94: 181-365 Days | I94: 246403.27
A95: 45838 | B95: 2KL25ARMN10 | C95: RDC Concrete (India) Pvt Ltd (Kolkata)-Crs | D95: Panagarh (Aggregate) WB | E95: 3092863.7 | F95: 3022863.7 | G95: 365 | H95: 181-365 Days | I95: 3022863.7
A96: 45838 | B96: 2KL25ARMN12 | C96: RDC Concrete (India) Pvt Ltd (Kolkata)-Crs | D96: Gujarat | E96: 1279904.3 | F96: 1276850.8 | G96: 365 | H96: 181-365 Days | I96: 1276850.8
A97: 45839 | B97: JV/HO/2526/0073 | C97: RDC Concrete (India) Pvt Ltd (Head Office) - Crs | E97: 740750 | F97: 740750 | G97: 364 | H97: 181-365 Days | I97: 740750
A98: 45839 | B98: JV/GUJ/2526/0038 | C98: SHIVSHAKTI ENTERPRISES - Crs | E98: 649762.84 | F98: 649762.84 | G98: 364 | H98: 181-365 Days | I98: -649762.84
A99: 45858 | B99: Ash/15 | C99: ASHCONNECT GLOBAL TRADING Pvt Ltd- Crs | E99: 99570 | F99: 99570 | G99: 345 | H99: 181-365 Days | I99: 99570
A100: 45863 | B100: Ash/16 | C100: ASHCONNECT GLOBAL TRADING Pvt Ltd- Crs | E100: 150479 | F100: 150479 | G100: 340 | H100: 181-365 Days | I100: 150479
A101: 45869 | B101: HM27/2526/069328 | C101: Hella Infra Market Limited-Crs | E101: 1214662.7 | F101: 1214662.7 | G101: 334 | H101: 181-365 Days | I101: 1214662.7
A102: 45869 | B102: JV/HO/2526/0070 | C102: RDC Concrete (India) Pvt Ltd (Head Office) - Crs | E102: 821726.7 | F102: 821726.7 | G102: 334 | H102: 181-365 Days | I102: 821726.7
...

Sheet Only Creditors
A1: Ultrafine Mineral & Admixtures Pvt. Ltd.
A2: Creditors Ageing Report | As at 30-June-2026
B3: SUBTOTAL | G3: =SUBTOTAL(9,G5:G189) -> 1.8275048e+08 | H3: =SUBTOTAL(9,H5:H189) -> 1.0932552e+08 | I3: =SUBTOTAL(9,I5:I189) -> 13959870 | J3: =SUBTOTAL(9,J5:J189) -> 12910755 | K3: =SUBTOTAL(9,K5:K189) -> 10238610 | L3: =SUBTOTAL(9,L5:L189) -> 18449869 | M3: =SUBTOTAL(9,M5:M189) -> 1354071.3 | N3: =SUBTOTAL(9,N5:N189) -> 10572313 | ... Q3: =SUBTOTAL(9,Q5:Q189) -> 660.95
A4: # | B4: Vendor Name | C4: Location | D4: Vendor Type | E4: Vendor Sub Type | G4: TB Balance (Cr) | H4: 0-30 Days | I4: 31-60 Days | J4: 61-90 Days | K4: 91-120 Days | L4: 121-150 Days | M4: 151-180 Days | N4: 181-365 Days | O4: Above 365 Days | P4: BW Total | Q4: Diff (TB-BW)
A6: 1 | B6: Ram Innovation & Solutions-Crs | C6: Gujarat | D6: Raw Material | E6: Slag | G6: =IFERROR(SUMIFS(TB!C:C,TB!A:A,B6)-SUMIFS(TB!B:B,TB!A:A,B6),0) -> 1000 | H6: =SUMIFS('Bill Wise'!I:I,'Bill Wise'!C:C,B6,'Bill Wise'!H:H,"0-30 Days") -> 1000 | I6: =SUMIFS('Bill Wise'!I:I,'Bill Wise'!C:C,B6,'Bill Wise'!H:H,"31-60 Days") -> 0 | J6: =SUMIFS('Bill Wise'!I:I,'Bill Wise'!C:C,B6,'Bill Wise'!H:H,"61-90 Days") -> 0 | K6: =SUMIFS('Bill Wise'!I:I,'Bill Wise'!C:C,B6,'Bill Wise'!H:H,"91-120 Days") -> 0 | L6: =SUMIFS('Bill Wise'!I:I,'Bill Wise'!C:C,B6,'Bill Wise'!H:H,"121-150 Days") -> 0 | M6: =SUMIFS('Bill Wise'!I:I,'Bill Wise'!C:C,B6,'Bill Wise'!H:H,"151-180 Days") -> 0 | N6: =SUMIFS('Bill Wise'!I:I,'Bill Wise'!C:C,B6,'Bill Wise'!H:H,"181-365 Days") -> 0 | O6: =SUMIFS('Bill Wise'!I:I,'Bill Wise'!C:C,B6,'Bill Wise'!H:H,"Above 365 Days") -> 0 | P6: =SUM(H6:O6) -> 1000 | Q6: =G6-P6 -> 0
A7: 2 | B7: Sumangala Naik - Crs | C7: Goa | D7: Expenses | E7: Rent | G7: =IFERROR(SUMIFS(TB!C:C,TB!A:A,B7)-SUMIFS(TB!B:B,TB!A:A,B7),0) -> 2000 | H7: =SUMIFS('Bill Wise'!I:I,'Bill Wise'!C:C,B7,'Bill Wise'!H:H,"0-30 Days") -> 2000 | I7: =SUMIFS('Bill Wise'!I:I,'Bill Wise'!C:C,B7,'Bill Wise'!H:H,"31-60 Days") -> 0 | J7: =SUMIFS('Bill Wise'!I:I,'Bill Wise'!C:C,B7,'Bill Wise'!H:H,"61-90 Days") -> 0 | K7: =SUMIFS('Bill Wise'!I:I,'Bill Wise'!C:C,B7,'Bill Wise'!H:H,"91-120 Days") -> 0 | L7: =SUMIFS('Bill Wise'!I:I,'Bill Wise'!C:C,B7,'Bill Wise'!H:H,"121-150 Days") -> 0 | M7: =SUMIFS('Bill Wise'!I:I,'Bill Wise'!C:C,B7,'Bill Wise'!H:H,"151-180 Days") -> 0 | N7: =SUMIFS('Bill Wise'!I:I,'Bill Wise'!C:C,B7,'Bill Wise'!H:H,"181-365 Days") -> 0 | O7: =SUMIFS('Bill Wise'!I:I,'Bill Wise'!C:C,B7,'Bill Wise'!H:H,"Above 365 Days") -> 0 | P7: =SUM(H7:O7) -> 2000 | Q7: =G7-P7 -> 0
A8: 3 | B8: Bharti Airtel Limited - Crs | C8: Goa | D8: Expenses | E8: Telephone Exps | G8: =IFERROR(SUMIFS(TB!C:C,TB!A:A,B8)-SUMIFS(TB!B:B,TB!A:A,B8),0) -> 2472.1 | H8: =SUMIFS('Bill Wise'!I:I,'Bill Wise'!C:C,B8,'Bill Wise'!H:H,"0-30 Days") -> 2472.1 | I8: =SUMIFS('Bill Wise'!I:I,'Bill Wise'!C:C,B8,'Bill Wise'!H:H,"31-60 Days") -> 0 | J8: =SUMIFS('Bill Wise'!I:I,'Bill Wise'!C:C,B8,'Bill Wise'!H:H,"61-90 Days") -> 0 | K8: =SUMIFS('Bill Wise'!I:I,'Bill Wise'!C:C,B8,'Bill Wise'!H:H,"91-120 Days") -> 0 | L8: =SUMIFS('Bill Wise'!I:I,'Bill Wise'!C:C,B8,'Bill Wise'!H:H,"121-150 Days") -> 0 | M8: =SUMIFS('Bill Wise'!I:I,'Bill Wise'!C:C,B8,'Bill Wise'!H:H,"151-180 Days") -> 0 | N8: =SUMIFS('Bill Wise'!I:I,'Bill Wise'!C:C,B8,'Bill Wise'!H:H,"181-365 Days") -> 0 | O8: =SUMIFS('Bill Wise'!I:I,'Bill Wise'!C:C,B8,'Bill Wise'!H:H,"Above 365 Days") -> 0 | P8: =SUM(H8:O8) -> 2472.1 | Q8: =G8-P8 -> 0
A9: 4 | B9: Arya CS - Crs | C9: Kerala | D9: Expenses | E9: Rent | G9: =IFERROR(SUMIFS(TB!C:C,TB!A:A,B9)-SUMIFS(TB!B:B,TB!A:A,B9),0) -> 3000 | H9: =SUMIFS('Bill Wise'!I:I,'Bill Wise'!C:C,B9,'Bill Wise'!H:H,"0-30 Days") -> 3000 | I9: =SUMIFS('Bill Wise'!I:I,'Bill Wise'!C:C,B9,'Bill Wise'!H:H,"31-60 Days") -> 0 | J9: =SUMIFS('Bill Wise'!I:I,'Bill Wise'!C:C,B9,'Bill Wise'!H:H,"61-90 Days") -> 0 | K9: =SUMIFS('Bill Wise'!I:I,'Bill Wise'!C:C,B9,'Bill Wise'!H:H,"91-120 Days") -> 0 | L9: =SUMIFS('Bill Wise'!I:I,'Bill Wise'!C:C,B9,'Bill Wise'!H:H,"121-150 Days") -> 0 | M9: =SUMIFS('Bill Wise'!I:I,'Bill Wise'!C:C,B9,'Bill Wise'!H:H,"151-180 Days") -> 0 | N9: =SUMIFS('Bill Wise'!I:I,'Bill Wise'!C:C,B9,'Bill Wise'!H:H,"181-365 Days") -> 0 | O9: =SUMIFS('Bill Wise'!I:I,'Bill Wise'!C:C,B9,'Bill Wise'!H:H,"Above 365 Days") -> 0 | P9: =SUM(H9:O9) -> 3000 | Q9: =G9-P9 -> 0
A10: 5 | B10: DEEP ENTERPRISES-CRS | C10: Nagpur | D10: Expenses | E10: Office Exps | G10: =IFERROR(SUMIFS(TB!C:C,TB!A:A,B10)-SUMIFS(TB!B:B,TB!A:A,B10),0) -> 3000 | H10: =SUMIFS('Bill Wise'!I:I,'Bill Wise'!C:C,B10,'Bill Wise'!H:H,"0-30 Days") -> 3000 | I10: =SUMIFS('Bill Wise'!I:I,'Bill Wise'!C:C,B10,'Bill Wise'!H:H,"31-60 Days") -> 0 | J10: =SUMIFS('Bill Wise'!I:I,'Bill Wise'!C:C,B10,'Bill Wise'!H:H,"61-90 Days") -> 0 | K10: =SUMIFS('Bill Wise'!I:I,'Bill Wise'!C:C,B10,'Bill Wise'!H:H,"91-120 Days") -> 0 | L10: =SUMIFS('Bill Wise'!I:I,'Bill Wise'!C:C,B10,'Bill Wise'!H:H,"121-150 Days") -> 0 | M10: =SUMIFS('Bill Wise'!I:I,'Bill Wise'!C:C,B10,'Bill Wise'!H:H,"151-180 Days") -> 0 | N10: =SUMIFS('Bill Wise'!I:I,'Bill Wise'!C:C,B10,'Bill Wise'!H:H,"181-365 Days") -> 0 | O10: =SUMIFS('Bill Wise'!I:I,'Bill Wise'!C:C,B10,'Bill Wise'!H:H,"Above 365 Days") -> 0 | P10: =SUM(H10:O10) -> 3000 | Q10: =G10-P10 -> 0
A11: 6 | B11: Abhay Singh-Employee | C11: Head Office | D11: Employee | E11: Claim Exps | G11: =IFERROR(SUMIFS(TB!C:C,TB!A:A,B11)-SUMIFS(TB!B:B,TB!A:A,B11),0) -> 3519 | H11: =SUMIFS('Bill Wise'!I:I,'Bill Wise'!C:C,B11,'Bill Wise'!H:H,"0-30 Days") -> 3519 | I11: =SUMIFS('Bill Wise'!I:I,'Bill Wise'!C:C,B11,'Bill Wise'!H:H,"31-60 Days") -> 0 | J11: =SUMIFS('Bill Wise'!I:I,'Bill Wise'!C:C,B11,'Bill Wise'!H:H,"61-90 Days") -> 0 | K11: =SUMIFS('Bill Wise'!I:I,'Bill Wise'!C:C,B11,'Bill Wise'!H:H,"91-120 Days") -> 0 | L11: =SUMIFS('Bill Wise'!I:I,'Bill Wise'!C:C,B11,'Bill Wise'!H:H,"121-150 Days") -> 0 | M11: =SUMIFS('Bill Wise'!I:I,'Bill Wise'!C:C,B11,'Bill Wise'!H:H,"151-180 Days") -> 0 | N11: =SUMIFS('Bill Wise'!I:I,'Bill Wise'!C:C,B11,'Bill Wise'!H:H,"181-365 Days") -> 0 | O11: =SUMIFS('Bill Wise'!I:I,'Bill Wise'!C:C,B11,'Bill Wise'!H:H,"Above 365 Days") -> 0 | P11: =SUM(H11:O11) -> 3519 | Q11: =G11-P11 -> 0
A12: 7 | B12: Yaa Baba Taj Restaurants - CRS | C12: Nagpur | D12: Expenses | E12: Office Exps | G12: =IFERROR(SUMIFS(TB!C:C,TB!A:A,B12)-SUMIFS(TB!B:B,TB!A:A,B12),0) -> 3606 | H12: =SUMIFS('Bill Wise'!I:I,'Bill Wise'!C:C,B12,'Bill Wise'!H:H,"0-30 Days") -> 3606 | I12: =SUMIFS('Bill Wise'!I:I,'Bill Wise'!C:C,B12,'Bill Wise'!H:H,"31-60 Days") -> 0 | J12: =SUMIFS('Bill Wise'!I:I,'Bill Wise'!C:C,B12,'Bill Wise'!H:H,"61-90 Days") -> 0 | K12: =SUMIFS('Bill Wise'!I:I,'Bill Wise'!C:C,B12,'Bill Wise'!H:H,"91-120 Days") -> 0 | L12: =SUMIFS('Bill Wise'!I:I,'Bill Wise'!C:C,B12,'Bill Wise'!H:H,"121-150 Days") -> 0 | M12: =SUMIFS('Bill Wise'!I:I,'Bill Wise'!C:C,B12,'Bill Wise'!H:H,"151-180 Days") -> 0 | N12: =SUMIFS('Bill Wise'!I:I,'Bill Wise'!C:C,B12,'Bill Wise'!H:H,"181-365 Days") -> 0 | O12: =SUMIFS('Bill Wise'!I:I,'Bill Wise'!C:C,B12,'Bill Wise'!H:H,"Above 365 Days") -> 0 | P12: =SUM(H12:O12) -> 3606 | Q12: =G12-P12 -> 0
A13: 8 | B13: JINENDRA AUTO PARTS-Crs | C13: Gujarat | D13: Expenses | E13: Store and spare | G13: =IFERROR(SUMIFS(TB!C:C,TB!A:A,B13)-SUMIFS(TB!B:B,TB!A:A,B13),0) -> 3800 | H13: =SUMIFS('Bill Wise'!I:I,'Bill Wise'!C:C,B13,'Bill Wise'!H:H,"0-30 Days") -> 3800 | I13: =SUMIFS('Bill Wise'!I:I,'Bill Wise'!C:C,B13,'Bill Wise'!H:H,"31-60 Days") -> 0 | J13: =SUMIFS('Bill Wise'!I:I,'Bill Wise'!C:C,B13,'Bill Wise'!H:H,"61-90 Days") -> 0 | K13: =SUMIFS('Bill Wise'!I:I,'Bill Wise'!C:C,B13,'Bill Wise'!H:H,"91-120 Days") -> 0 | L13: =SUMIFS('Bill Wise'!I:I,'Bill Wise'!C:C,B13,'Bill Wise'!H:H,"121-150 Days") -> 0 | M13: =SUMIFS('Bill Wise'!I:I,'Bill Wise'!C:C,B13,'Bill Wise'!H:H,"151-180 Days") -> 0 | N13: =SUMIFS('Bill Wise'!I:I,'Bill Wise'!C:C,B13,'Bill Wise'!H:H,"181-365 Days") -> 0 | O13: =SUMIFS('Bill Wise'!I:I,'Bill Wise'!C:C,B13,'Bill Wise'!H:H,"Above 365 Days") -> 0 | P13: =SUM(H13:O13) -> 3800 | Q13: =G13-P13 -> 0
A14: 9 | B14: Csrl-Structwel Lab (Pune) Private Limited Crs | C14: Nagpur | D14: Expenses | E14: 0 | G14: =IFERROR(SUMIFS(TB!C:C,TB!A:A,B14)-SUMIFS(TB!B:B,TB!A:A,B14),0) -> 3933 | H14: =SUMIFS('Bill Wise'!I:I,'Bill Wise'!C:C,B14,'Bill Wise'!H:H,"0-30 Days") -> 3933 | I14: =SUMIFS('Bill Wise'!I:I,'Bill Wise'!C:C,B14,'Bill Wise'!H:H,"31-60 Days") -> 0 | J14: =SUMIFS('Bill Wise'!I:I,'Bill Wise'!C:C,B14,'Bill Wise'!H:H,"61-90 Days") -> 0 | K14: =SUMIFS('Bill Wise'!I:I,'Bill Wise'!C:C,B14,'Bill Wise'!H:H,"91-120 Days") -> 0 | L14: =SUMIFS('Bill Wise'!I:I,'Bill Wise'!C:C,B14,'Bill Wise'!H:H,"121-150 Days") -> 0 | M14: =SUMIFS('Bill Wise'!I:I,'Bill Wise'!C:C,B14,'Bill Wise'!H:H,"151-180 Days") -> 0 | N14: =SUMIFS('Bill Wise'!I:I,'Bill Wise'!C:C,B14,'Bill Wise'!H:H,"181-365 Days") -> 0 | O14: =SUMIFS('Bill Wise'!I:I,'Bill Wise'!C:C,B14,'Bill Wise'!H:H,"Above 365 Days") -> 0 | P14: =SUM(H14:O14) -> 3933 | Q14: =G14-P14 -> 0
A15: 10 | B15: S. K. Traders-Crs | C15: Gujarat | D15: Expenses | E15: 0 | G15: =IFERROR(SUMIFS(TB!C:C,TB!A:A,B15)-SUMIFS(TB!B:B,TB!A:A,B15),0) -> 4130 | H15: =SUMIFS('Bill Wise'!I:I,'Bill Wise'!C:C,B15,'Bill Wise'!H:H,"0-30 Days") -> 4130 | I15: =SUMIFS('Bill Wise'!I:I,'Bill Wise'!C:C,B15,'Bill Wise'!H:H,"31-60 Days") -> 0 | J15: =SUMIFS('Bill Wise'!I:I,'Bill Wise'!C:C,B15,'Bill Wise'!H:H,"61-90 Days") -> 0 | K15: =SUMIFS('Bill Wise'!I:I,'Bill Wise'!C:C,B15,'Bill Wise'!H:H,"91-120 Days") -> 0 | L15: =SUMIFS('Bill Wise'!I:I,'Bill Wise'!C:C,B15,'Bill Wise'!H:H,"121-150 Days") -> 0 | M15: =SUMIFS('Bill Wise'!I:I,'Bill Wise'!C:C,B15,'Bill Wise'!H:H,"151-180 Days") -> 0 | N15: =SUMIFS('Bill Wise'!I:I,'Bill Wise'!C:C,B15,'Bill Wise'!H:H,"181-365 Days") -> 0 | O15: =SUMIFS('Bill Wise'!I:I,'Bill Wise'!C:C,B15,'Bill Wise'!H:H,"Above 365 Days") -> 0 | P15: =SUM(H15:O15) -> 4130 | Q15: =G15-P15 -> 0
A16: 11 | B16: Bipin Jadhav Guest House - Crs | C16: Wada | D16: Expenses | E16: Rent | G16: =IFERROR(SUMIFS(TB!C:C,TB!A:A,B16)-SUMIFS(TB!B:B,TB!A:A,B16),0) -> 4500 | H16: =SUMIFS('Bill Wise'!I:I,'Bill Wise'!C:C,B16,'Bill Wise'!H:H,"0-30 Days") -> 4500 | I16: =SUMIFS('Bill Wise'!I:I,'Bill Wise'!C:C,B16,'Bill Wise'!H:H,"31-60 Days") -> 0 | J16: =SUMIFS('Bill Wise'!I:I,'Bill Wise'!C:C,B16,'Bill Wise'!H:H,"61-90 Days") -> 0 | K16: =SUMIFS('Bill Wise'!I:I,'Bill Wise'!C:C,B16,'Bill Wise'!H:H,"91-120 Days") -> 0 | L16: =SUMIFS('Bill Wise'!I:I,'Bill Wise'!C:C,B16,'Bill Wise'!H:H,"121-150 Days") -> 0 | M16: =SUMIFS('Bill Wise'!I:I,'Bill Wise'!C:C,B16,'Bill Wise'!H:H,"151-180 Days") -> 0 | N16: =SUMIFS('Bill Wise'!I:I,'Bill Wise'!C:C,B16,'Bill Wise'!H:H,"181-365 Days") -> 0 | O16: =SUMIFS('Bill Wise'!I:I,'Bill Wise'!C:C,B16,'Bill Wise'!H:H,"Above 365 Days") -> 0 | P16: =SUM(H16:O16) -> 4500 | Q16: =G16-P16 -> 0
A17: 12 | B17: Ramakant L Dalal - Crs | C17: Nagpur | D17: Expenses | E17: Repair & Maintenance | G17: =IFERROR(SUMIFS(TB!C:C,TB!A:A,B17)-SUMIFS(TB!B:B,TB!A:A,B17),0) -> 4851 | H17: =SUMIFS('Bill Wise'!I:I,'Bill Wise'!C:C,B17,'Bill Wise'!H:H,"0-30 Days") -> 4851 | I17: =SUMIFS('Bill Wise'!I:I,'Bill Wise'!C:C,B17,'Bill Wise'!H:H,"31-60 Days") -> 0 | J17: =SUMIFS('Bill Wise'!I:I,'Bill Wise'!C:C,B17,'Bill Wise'!H:H,"61-90 Days") -> 0 | K17: =SUMIFS('Bill Wise'!I:I,'Bill Wise'!C:C,B17,'Bill Wise'!H:H,"91-120 Days") -> 0 | L17: =SUMIFS('Bill Wise'!I:I,'Bill Wise'!C:C,B17,'Bill Wise'!H:H,"121-150 Days") -> 0 | M17: =SUMIFS('Bill Wise'!I:I,'Bill Wise'!C:C,B17,'Bill Wise'!H:H,"151-180 Days") -> 0 | N17: =SUMIFS('Bill Wise'!I:I,'Bill Wise'!C:C,B17,'Bill Wise'!H:H,"181-365 Days") -> 0 | O17: =SUMIFS('Bill Wise'!I:I,'Bill Wise'!C:C,B17,'Bill Wise'!H:H,"Above 365 Days") -> 0 | P17: =SUM(H17:O17) -> 4851 | Q17: =G17-P17 -> 0
A18: 13 | B18: MADAN MOHAN SINGH-CRS | C18: Gujarat | D18: Expenses | E18: Staff Welfare | G18: =IFERROR(SUMIFS(TB!C:C,TB!A:A,B18)-SUMIFS(TB!B:B,TB!A:A,B18),0) -> 4970 | H18: =SUMIFS('Bill Wise'!I:I,'Bill Wise'!C:C,B18,'Bill Wise'!H:H,"0-30 Days") -> 4970 | I18: =SUMIFS('Bill Wise'!I:I,'Bill Wise'!C:C,B18,'Bill Wise'!H:H,"31-60 Days") -> 0 | J18: =SUMIFS('Bill Wise'!I:I,'Bill Wise'!C:C,B18,'Bill Wise'!H:H,"61-90 Days") -> 0 | K18: =SUMIFS('Bill Wise'!I:I,'Bill Wise'!C:C,B18,'Bill Wise'!H:H,"91-120 Days") -> 0 | L18: =SUMIFS('Bill Wise'!I:I,'Bill Wise'!C:C,B18,'Bill Wise'!H:H,"121-150 Days") -> 0 | M18: =SUMIFS('Bill Wise'!I:I,'Bill Wise'!C:C,B18,'Bill Wise'!H:H,"151-180 Days") -> 0 | N18: =SUMIFS('Bill Wise'!I:I,'Bill Wise'!C:C,B18,'Bill Wise'!H:H,"181-365 Days") -> 0 | O18: =SUMIFS('Bill Wise'!I:I,'Bill Wise'!C:C,B18,'Bill Wise'!H:H,"Above 365 Days") -> 0 | P18: =SUM(H18:O18) -> 4970 | Q18: =G18-P18 -> 0
A19: 14 | B19: KAPIL THAKARE - Crs | C19: wada | D19: Expenses | E19: Office Exps | G19: =IFERROR(SUMIFS(TB!C:C,TB!A:A,B19)-SUMIFS(TB!B:B,TB!A:A,B19),0) -> 5705 | H19: =SUMIFS('Bill Wise'!I:I,'Bill Wise'!C:C,B19,'Bill Wise'!H:H,"0-30 Days") -> 5705 | I19: =SUMIFS('Bill Wise'!I:I,'Bill Wise'!C:C,B19,'Bill Wise'!H:H,"31-60 Days") -> 0 | J19: =SUMIFS('Bill Wise'!I:I,'Bill Wise'!C:C,B19,'Bill Wise'!H:H,"61-90 Days") -> 0 | K19: =SUMIFS('Bill Wise'!I:I,'Bill Wise'!C:C,B19,'Bill Wise'!H:H,"91-120 Days") -> 0 | L19: =SUMIFS('Bill Wise'!I:I,'Bill Wise'!C:C,B19,'Bill Wise'!H:H,"121-150 Days") -> 0 | M19: =SUMIFS('Bill Wise'!I:I,'Bill Wise'!C:C,B19,'Bill Wise'!H:H,"151-180 Days") -> 0 | N19: =SUMIFS('Bill Wise'!I:I,'Bill Wise'!C:C,B19,'Bill Wise'!H:H,"181-365 Days") -> 0 | O19: =SUMIFS('Bill Wise'!I:I,'Bill Wise'!C:C,B19,'Bill Wise'!H:H,"Above 365 Days") -> 0 | P19: =SUM(H19:O19) -> 5705 | Q19: =G19-P19 -> 0
A20: 15 | B20: Mohd. Saif - Employee | C20: Head Office | D20: Employee | E20: Claim Exps | G20: =IFERROR(SUMIFS(TB!C:C,TB!A:A,B20)-SUMIFS(TB!B:B,TB!A:A,B20),0) -> 5757 | H20: =SUMIFS('Bill Wise'!I:I,'Bill Wise'!C:C,B20,'Bill Wise'!H:H,"0-30 Days") -> 5757 | I20: =SUMIFS('Bill Wise'!I:I,'Bill Wise'!C:C,B20,'Bill Wise'!H:H,"31-60 Days") -> 0 | J20: =SUMIFS('Bill Wise'!I:I,'Bill Wise'!C:C,B20,'Bill Wise'!H:H,"61-90 Days") -> 0 | K20: =SUMIFS('Bill Wise'!I:I,'Bill Wise'!C:C,B20,'Bill Wise'!H:H,"91-120 Days") -> 0 | L20: =SUMIFS('Bill Wise'!I:I,'Bill Wise'!C:C,B20,'Bill Wise'!H:H,"121-150 Days") -> 0 | M20: =SUMIFS('Bill Wise'!I:I,'Bill Wise'!C:C,B20,'Bill Wise'!H:H,"151-180 Days") -> 0 | N20: =SUMIFS('Bill Wise'!I:I,'Bill Wise'!C:C,B20,'Bill Wise'!H:H,"181-365 Days") -> 0 | O20: =SUMIFS('Bill Wise'!I:I,'Bill Wise'!C:C,B20,'Bill Wise'!H:H,"Above 365 Days") -> 0 | P20: =SUM(H20:O20) -> 5757 | Q20: =G20-P20 -> 0
A21: 16 | B21: Krishna Enterprise(Guj)-Crs | C21: Gujarat | D21: Expenses | E21: Repair & Maintenance | G21: =IFERROR(SUMIFS(TB!C:C,TB!A:A,B21)-SUMIFS(TB!B:B,TB!A:A,B21),0) -> 5782 | H21: =SUMIFS('Bill Wise'!I:I,'Bill Wise'!C:C,B21,'Bill Wise'!H:H,"0-30 Days") -> 5782 | I21: =SUMIFS('Bill Wise'!I:I,'Bill Wise'!C:C,B21,'Bill Wise'!H:H,"31-60 Days") -> 0 | J21: =SUMIFS('Bill Wise'!I:I,'Bill Wise'!C:C,B21,'Bill Wise'!H:H,"61-90 Days") -> 0 | K21: =SUMIFS('Bill Wise'!I:I,'Bill Wise'!C:C,B21,'Bill Wise'!H:H,"91-120 Days") -> 0 | L21: =SUMIFS('Bill Wise'!I:I,'Bill Wise'!C:C,B21,'Bill Wise'!H:H,"121-150 Days") -> 0 | M21: =SUMIFS('Bill Wise'!I:I,'Bill Wise'!C:C,B21,'Bill Wise'!H:H,"151-180 Days") -> 0 | N21: =SUMIFS('Bill Wise'!I:I,'Bill Wise'!C:C,B21,'Bill Wise'!H:H,"181-365 Days") -> 0 | O21: =SUMIFS('Bill Wise'!I:I,'Bill Wise'!C:C,B21,'Bill Wise'!H:H,"Above 365 Days") -> 0 | P21: =SUM(H21:O21) -> 5782 | Q21: =G21-P21 -> 0
A22: 17 | B22: Kapadia Global Actuaries-Crs | C22: Head Office | D22: Expenses | E22: Professional Fees | G22: =IFERROR(SUMIFS(TB!C:C,TB!A:A,B22)-SUMIFS(TB!B:B,TB!A:A,B22),0) -> 5900 | H22: =SUMIFS('Bill Wise'!I:I,'Bill Wise'!C:C,B22,'Bill Wise'!H:H,"0-30 Days") -> 5900 | I22: =SUMIFS('Bill Wise'!I:I,'Bill Wise'!C:C,B22,'Bill Wise'!H:H,"31-60 Days") -> 0 | J22: =SUMIFS('Bill Wise'!I:I,'Bill Wise'!C:C,B22,'Bill Wise'!H:H,"61-90 Days") -> 0 | K22: =SUMIFS('Bill Wise'!I:I,'Bill Wise'!C:C,B22,'Bill Wise'!H:H,"91-120 Days") -> 0 | L22: =SUMIFS('Bill Wise'!I:I,'Bill Wise'!C:C,B22,'Bill Wise'!H:H,"121-150 Days") -> 0 | M22: =SUMIFS('Bill Wise'!I:I,'Bill Wise'!C:C,B22,'Bill Wise'!H:H,"151-180 Days") -> 0 | N22: =SUMIFS('Bill Wise'!I:I,'Bill Wise'!C:C,B22,'Bill Wise'!H:H,"181-365 Days") -> 0 | O22: =SUMIFS('Bill Wise'!I:I,'Bill Wise'!C:C,B22,'Bill Wise'!H:H,"Above 365 Days") -> 0 | P22: =SUM(H22:O22) -> 5900 | Q22: =G22-P22 -> 0
A23: 18 | B23: Jhuman Bagdi- Crs | C23: Galsi | D23: Expenses | E23: Staff Welfare | G23: =IFERROR(SUMIFS(TB!C:C,TB!A:A,B23)-SUMIFS(TB!B:B,TB!A:A,B23),0) -> 6000 | H23: =SUMIFS('Bill Wise'!I:I,'Bill Wise'!C:C,B23,'Bill Wise'!H:H,"0-30 Days") -> 6000 | I23: =SUMIFS('Bill Wise'!I:I,'Bill Wise'!C:C,B23,'Bill Wise'!H:H,"31-60 Days") -> 0 | J23: =SUMIFS('Bill Wise'!I:I,'Bill Wise'!C:C,B23,'Bill Wise'!H:H,"61-90 Days") -> 0 | K23: =SUMIFS('Bill Wise'!I:I,'Bill Wise'!C:C,B23,'Bill Wise'!H:H,"91-120 Days") -> 0 | L23: =SUMIFS('Bill Wise'!I:I,'Bill Wise'!C:C,B23,'Bill Wise'!H:H,"121-150 Days") -> 0 | M23: =SUMIFS('Bill Wise'!I:I,'Bill Wise'!C:C,B23,'Bill Wise'!H:H,"151-180 Days") -> 0 | N23: =SUMIFS('Bill Wise'!I:I,'Bill Wise'!C:C,B23,'Bill Wise'!H:H,"181-365 Days") -> 0 | O23: =SUMIFS('Bill Wise'!I:I,'Bill Wise'!C:C,B23,'Bill Wise'!H:H,"Above 365 Days") -> 0 | P23: =SUM(H23:O23) -> 6000 | Q23: =G23-P23 -> 0
A24: 19 | B24: BHARTIBEN SATISHBHAI PATEL-CR | C24: Gujarat | D24: Expenses | E24: Guest House Rent | G24: =IFERROR(SUMIFS(TB!C:C,TB!A:A,B24)-SUMIFS(TB!B:B,TB!A:A,B24),0) -> 8000 | H24: =SUMIFS('Bill Wise'!I:I,'Bill Wise'!C:C,B24,'Bill Wise'!H:H,"0-30 Days") -> 8000 | I24: =SUMIFS('Bill Wise'!I:I,'Bill Wise'!C:C,B24,'Bill Wise'!H:H,"31-60 Days") -> 0 | J24: =SUMIFS('Bill Wise'!I:I,'Bill Wise'!C:C,B24,'Bill Wise'!H:H,"61-90 Days") -> 0 | K24: =SUMIFS('Bill Wise'!I:I,'Bill Wise'!C:C,B24,'Bill Wise'!H:H,"91-120 Days") -> 0 | L24: =SUMIFS('Bill Wise'!I:I,'Bill Wise'!C:C,B24,'Bill Wise'!H:H,"121-150 Days") -> 0 | M24: =SUMIFS('Bill Wise'!I:I,'Bill Wise'!C:C,B24,'Bill Wise'!H:H,"151-180 Days") -> 0 | N24: =SUMIFS('Bill Wise'!I:I,'Bill Wise'!C:C,B24,'Bill Wise'!H:H,"181-365 Days") -> 0 | O24: =SUMIFS('Bill Wise'!I:I,'Bill Wise'!C:C,B24,'Bill Wise'!H:H,"Above 365 Days") -> 0 | P24: =SUM(H24:O24) -> 8000 | Q24: =G24-P24 -> 0
A25: 20 | B25: Pramod Marotirao Kumbhare- Crs | C25: Nagpur | D25: Expenses | E25: Contract Labour | G25: =IFERROR(SUMIFS(TB!C:C,TB!A:A,B25)-SUMIFS(TB!B:B,TB!A:A,B25),0) -> 8232 | H25: =SUMIFS('Bill Wise'!I:I,'Bill Wise'!C:C,B25,'Bill Wise'!H:H,"0-30 Days") -> 8232 | I25: =SUMIFS('Bill Wise'!I:I,'Bill Wise'!C:C,B25,'Bill Wise'!H:H,"31-60 Days") -> 0 | J25: =SUMIFS('Bill Wise'!I:I,'Bill Wise'!C:C,B25,'Bill Wise'!H:H,"61-90 Days") -> 0 | K25: =SUMIFS('Bill Wise'!I:I,'Bill Wise'!C:C,B25,'Bill Wise'!H:H,"91-120 Days") -> 0 | L25: =SUMIFS('Bill Wise'!I:I,'Bill Wise'!C:C,B25,'Bill Wise'!H:H,"121-150 Days") -> 0 | M25: =SUMIFS('Bill Wise'!I:I,'Bill Wise'!C:C,B25,'Bill Wise'!H:H,"151-180 Days") -> 0 | N25: =SUMIFS('Bill Wise'!I:I,'Bill Wise'!C:C,B25,'Bill Wise'!H:H,"181-365 Days") -> 0 | O25: =SUMIFS('Bill Wise'!I:I,'Bill Wise'!C:C,B25,'Bill Wise'!H:H,"Above 365 Days") -> 0 | P25: =SUM(H25:O25) -> 8232 | Q25: =G25-P25 -> 0
A26: 21 | B26: Om Sai Krupa Chai - Crs | C26: wada | D26: Expenses | E26: Office Exps | G26: =IFERROR(SUMIFS(TB!C:C,TB!A:A,B26)-SUMIFS(TB!B:B,TB!A:A,B26),0) -> 9114 | H26: =SUMIFS('Bill Wise'!I:I,'Bill Wise'!C:C,B26,'Bill Wise'!H:H,"0-30 Days") -> 9114 | I26: =SUMIFS('Bill Wise'!I:I,'Bill Wise'!C:C,B26,'Bill Wise'!H:H,"31-60 Days") -> 0 | J26: =SUMIFS('Bill Wise'!I:I,'Bill Wise'!C:C,B26,'Bill Wise'!H:H,"61-90 Days") -> 0 | K26: =SUMIFS('Bill Wise'!I:I,'Bill Wise'!C:C,B26,'Bill Wise'!H:H,"91-120 Days") -> 0 | L26: =SUMIFS('Bill Wise'!I:I,'Bill Wise'!C:C,B26,'Bill Wise'!H:H,"121-150 Days") -> 0 | M26: =SUMIFS('Bill Wise'!I:I,'Bill Wise'!C:C,B26,'Bill Wise'!H:H,"151-180 Days") -> 0 | N26: =SUMIFS('Bill Wise'!I:I,'Bill Wise'!C:C,B26,'Bill Wise'!H:H,"181-365 Days") -> 0 | O26: =SUMIFS('Bill Wise'!I:I,'Bill Wise'!C:C,B26,'Bill Wise'!H:H,"Above 365 Days") -> 0 | P26: =SUM(H26:O26) -> 9114 | Q26: =G26-P26 -> 0
A27: 22 | B27: Bhandari Automobiles Pvt Ltd - Crs | C27: Aggregate | D27: Expenses | E27: Vehicle Exps | G27: =IFERROR(SUMIFS(TB!C:C,TB!A:A,B27)-SUMIFS(TB!B:B,TB!A:A,B27),0) -> 9150 | H27: =SUMIFS('Bill Wise'!I:I,'Bill Wise'!C:C,B27,'Bill Wise'!H:H,"0-30 Days") -> 9150 | I27: =SUMIFS('Bill Wise'!I:I,'Bill Wise'!C:C,B27,'Bill Wise'!H:H,"31-60 Days") -> 0 | J27: =SUMIFS('Bill Wise'!I:I,'Bill Wise'!C:C,B27,'Bill Wise'!H:H,"61-90 Days") -> 0 | K27: =SUMIFS('Bill Wise'!I:I,'Bill Wise'!C:C,B27,'Bill Wise'!H:H,"91-120 Days") -> 0 | L27: =SUMIFS('Bill Wise'!I:I,'Bill Wise'!C:C,B27,'Bill Wise'!H:H,"121-150 Days") -> 0 | M27: =SUMIFS('Bill Wise'!I:I,'Bill Wise'!C:C,B27,'Bill Wise'!H:H,"151-180 Days") -> 0 | N27: =SUMIFS('Bill Wise'!I:I,'Bill Wise'!C:C,B27,'Bill Wise'!H:H,"181-365 Days") -> 0 | O27: =SUMIFS('Bill Wise'!I:I,'Bill Wise'!C:C,B27,'Bill Wise'!H:H,"Above 365 Days") -> 0 | P27: =SUM(H27:O27) -> 9150 | Q27: =G27-P27 -> 0
... A43: 38 | B43: FIRDOSH ERUCH ICHHAPORIA-Crs | C43: Gujarat | D43: Expenses | E43: Guest House Rent | G43: =IFERROR(SUMIFS(TB!C:C,TB!A:A,B43)-SUMIFS(TB!B:B,TB!A:A,B43),0) -> 20000 | H43: =SUMIFS('Bill Wise'!I:I,'Bill Wise'!C:C,B43,'Bill Wise'!H:H,"0-30 Days") -> 20000 | I43: =SUMIFS('Bill Wise'!I:I,'Bill Wise'!C:C,B43,'Bill Wise'!H:H,"31-60 Days") -> 0 | J43: =SUMIFS('Bill Wise'!I:I,'Bill Wise'!C:C,B43,'Bill Wise'!H:H,"61-90 Days") -> 0 | K43: =SUMIFS('Bill Wise'!I:I,'Bill Wise'!C:C,B43,'Bill Wise'!H:H,"91-120 Days") -> 0 | L43: =SUMIFS('Bill Wise'!I:I,'Bill Wise'!C:C,B43,'Bill Wise'!H:H,"121-150 Days") -> 0 | M43: =SUMIFS('Bill Wise'!I:I,'Bill Wise'!C:C,B43,'Bill Wise'!H:H,"151-180 Days") -> 0 | N43: =SUMIFS('Bill Wise'!I:I,'Bill Wise'!C:C,B43,'Bill Wise'!H:H,"181-365 Days") -> 0 | O43: =SUMIFS('Bill Wise'!I:I,'Bill Wise'!C:C,B43,'Bill Wise'!H:H,"Above 365 Days") -> 0 | P43: =SUM(H43:O43) -> 20000 | Q43: =G43-P43 -> 0
A44: 39 | B44: N P Services - Crs | C44: Nagpur | D44: Expenses | E44: 0 | G44: =IFERROR(SUMIFS(TB!C:C,TB!A:A,B44)-SUMIFS(TB!B:B,TB!A:A,B44),0) -> 20535 | H44: =SUMIFS('Bill Wise'!I:I,'Bill Wise'!C:C,B44,'Bill Wise'!H:H,"0-30 Days") -> 0 | I44: =SUMIFS('Bill Wise'!I:I,'Bill Wise'!C:C,B44,'Bill Wise'!H:H,"31-60 Days") -> 20535 | J44: =SUMIFS('Bill Wise'!I:I,'Bill Wise'!C:C,B44,'Bill Wise'!H:H,"61-90 Days") -> 0 | K44: =SUMIFS('Bill Wise'!I:I,'Bill Wise'!C:C,B44,'Bill Wise'!H:H,"91-120 Days") -> 0 | L44: =SUMIFS('Bill Wise'!I:I,'Bill Wise'!C:C,B44,'Bill Wise'!H:H,"121-150 Days") -> 0 | M44: =SUMIFS('Bill Wise'!I:I,'Bill Wise'!C:C,B44,'Bill Wise'!H:H,"151-180 Days") -> 0 | N44: =SUMIFS('Bill Wise'!I:I,'Bill Wise'!C:C,B44,'Bill Wise'!H:H,"181-365 Days") -> 0 | O44: =SUMIFS('Bill Wise'!I:I,'Bill Wise'!C:C,B44,'Bill Wise'!H:H,"Above 365 Days") -> 0 | P44: =SUM(H44:O44) -> 20535 | Q44: =G44-P44 -> 0
A45: 40 | B45: Naresh Gupta - Employee | C45: Gujarat | D45: Employee | E45: Employee | G45: =IFERROR(SUMIFS(TB!C:C,TB!A:A,B45)-SUMIFS(TB!B:B,TB!A:A,B45),0) -> 21729 | H45: =SUMIFS('Bill Wise'!I:I,'Bill Wise'!C:C,B45,'Bill Wise'!H:H,"0-30 Days") -> 21729 | I45: =SUMIFS('Bill Wise'!I:I,'Bill Wise'!C:C,B45,'Bill Wise'!H:H,"31-60 Days") -> 0 | J45: =SUMIFS('Bill Wise'!I:I,'Bill Wise'!C:C,B45,'Bill Wise'!H:H,"61-90 Days") -> 0 | K45: =SUMIFS('Bill Wise'!I:I,'Bill Wise'!C:C,B45,'Bill Wise'!H:H,"91-120 Days") -> 0 | L45: =SUMIFS('Bill Wise'!I:I,'Bill Wise'!C:C,B45,'Bill Wise'!H:H,"121-150 Days") -> 0 | M45: =SUMIFS('Bill Wise'!I:I,'Bill Wise'!C:C,B45,'Bill Wise'!H:H,"151-180 Days") -> 0 | N45: =SUMIFS('Bill Wise'!I:I,'Bill Wise'!C:C,B45,'Bill Wise'!H:H,"181-365 Days") -> 0 | O45: =SUMIFS('Bill Wise'!I:I,'Bill Wise'!C:C,B45,'Bill Wise'!H:H,"Above 365 Days") -> 0 | P45: =SUM(H45:O45) -> 21729 | Q45: =G45-P45 -> 0
A46: 41 | B46: Nanak Auto Parts-Crs | C46: Gujarat | D46: Expenses | E46: Repair & Maintenance | G46: =IFERROR(SUMIFS(TB!C:C,TB!A:A,B46)-SUMIFS(TB!B:B,TB!A:A,B46),0) -> 22148 | H46: =SUMIFS('Bill Wise'!I:I,'Bill Wise'!C:C,B46,'Bill Wise'!H:H,"0-30 Days") -> 22148 | I46: =SUMIFS('Bill Wise'!I:I,'Bill Wise'!C:C,B46,'Bill Wise'!H:H,"31-60 Days") -> 0 | J46: =SUMIFS('Bill Wise'!I:I,'Bill Wise'!C:C,B46,'Bill Wise'!H:H,"61-90 Days") -> 0 | K46: =SUMIFS('Bill Wise'!I:I,'Bill Wise'!C:C,B46,'Bill Wise'!H:H,"91-120 Days") -> 0 | L46: =SUMIFS('Bill Wise'!I:I,'Bill Wise'!C:C,B46,'Bill Wise'!H:H,"121-150 Days") -> 0 | M46: =SUMIFS('Bill Wise'!I:I,'Bill Wise'!C:C,B46,'Bill Wise'!H:H,"151-180 Days") -> 0 | N46: =SUMIFS('Bill Wise'!I:I,'Bill Wise'!C:C,B46,'Bill Wise'!H:H,"181-365 Days") -> 0 | O46: =SUMIFS('Bill Wise'!I:I,'Bill Wise'!C:C,B46,'Bill Wise'!H:H,"Above 365 Days") -> 0 | P46: =SUM(H46:O46) -> 22148 | Q46: =G46-P46 -> 0
A47: 42 | B47: Rohit Prasad - Employee | C47: Gujarat | D47: Employee | E47: Claim Exps | G47: =IFERROR(SUMIFS(TB!C:C,TB!A:A,B47)-SUMIFS(TB!B:B,TB!A:A,B47),0) -> 22423 | H47: =SUMIFS('Bill Wise'!I:I,'Bill Wise'!C:C,B47,'Bill Wise'!H:H,"0-30 Days") -> 47423 | I47: =SUMIFS('Bill Wise'!I:I,'Bill Wise'!C:C,B47,'Bill Wise'!H:H,"31-60 Days") -> 0 | J47: =SUMIFS('Bill Wise'!I:I,'Bill Wise'!C:C,B47,'Bill Wise'!H:H,"61-90 Days") -> -25000 | K47: =SUMIFS('Bill Wise'!I:I,'Bill Wise'!C:C,B47,'Bill Wise'!H:H,"91-120 Days") -> 0 | L47: =SUMIFS('Bill Wise'!I:I,'Bill Wise'!C:C,B47,'Bill Wise'!H:H,"121-150 Days") -> 0 | M47: =SUMIFS('Bill Wise'!I:I,'Bill Wise'!C:C,B47,'Bill Wise'!H:H,"151-180 Days") -> 0 | N47: =SUMIFS('Bill Wise'!I:I,'Bill Wise'!C:C,B47,'Bill Wise'!H:H,"181-365 Days") -> 0 | O47: =SUMIFS('Bill Wise'!I:I,'Bill Wise'!C:C,B47,'Bill Wise'!H:H,"Above 365 Days") -> 0 | P47: =SUM(H47:O47) -> 22423 | Q47: =G47-P47 -> 0
A48: 43 | B48: SHIV OM PREFAB INFRA AND LOGISTICS-Crs | C48: Nagpur | D48: Expenses | E48: Store and spare | G48: =IFERROR(SUMIFS(TB!C:C,TB!A:A,B48)-SUMIFS(TB!B:B,TB!A:A,B48),0) -> 23174.83 | H48: =SUMIFS('Bill Wise'!I:I,'Bill Wise'!C:C,B48,'Bill Wise'!H:H,"0-30 Days") -> 23174.57 | I48: =SUMIFS('Bill Wise'!I:I,'Bill Wise'!C:C,B48,'Bill Wise'!H:H,"31-60 Days") -> 0 | J48: =SUMIFS('Bill Wise'!I:I,'Bill Wise'!C:C,B48,'Bill Wise'!H:H,"61-90 Days") -> 0.26 | K48: =SUMIFS('Bill Wise'!I:I,'Bill Wise'!C:C,B48,'Bill Wise'!H:H,"91-120 Days") -> 0 | L48: =SUMIFS('Bill Wise'!I:I,'Bill Wise'!C:C,B48,'Bill Wise'!H:H,"121-150 Days") -> 0 | M48: =SUMIFS('Bill Wise'!I:I,'Bill Wise'!C:C,B48,'Bill Wise'!H:H,"151-180 Days") -> 0 | N48: =SUMIFS('Bill Wise'!I:I,'Bill Wise'!C:C,B48,'Bill Wise'!H:H,"181-365 Days") -> 0 | O48: =SUMIFS('Bill Wise'!I:I,'Bill Wise'!C:C,B48,'Bill Wise'!H:H,"Above 365 Days") -> 0 | P48: =SUM(H48:O48) -> 23174.83 | Q48: =G48-P48 -> 0
A49: 44 | B49: AKRUTI ENTERPRISE-CRS | C49: Head Office | D49: Expenses | E49: Office Exps | G49: =IFERROR(SUMIFS(TB!C:C,TB!A:A,B49)-SUMIFS(TB!B:B,TB!A:A,B49),0) -> 24564.26 | H49: =SUMIFS('Bill Wise'!I:I,'Bill Wise'!C:C,B49,'Bill Wise'!H:H,"0-30 Days") -> 24564.06 | I49: =SUMIFS('Bill Wise'!I:I,'Bill Wise'!C:C,B49,'Bill Wise'!H:H,"31-60 Days") -> 0 | J49: =SUMIFS('Bill Wise'!I:I,'Bill Wise'!C:C,B49,'Bill Wise'!H:H,"61-90 Days") -> 0 | K49: =SUMIFS('Bill Wise'!I:I,'Bill Wise'!C:C,B49,'Bill Wise'!H:H,"91-120 Days") -> 0 | L49: =SUMIFS('Bill Wise'!I:I,'Bill Wise'!C:C,B49,'Bill Wise'!H:H,"121-150 Days") -> 0.2 | M49: =SUMIFS('Bill Wise'!I:I,'Bill Wise'!C:C,B49,'Bill Wise'!H:H,"151-180 Days") -> 0 | N49: =SUMIFS('Bill Wise'!I:I,'Bill Wise'!C:C,B49,'Bill Wise'!H:H,"181-365 Days") -> 0 | O49: =SUMIFS('Bill Wise'!I:I,'Bill Wise'!C:C,B49,'Bill Wise'!H:H,"Above 365 Days") -> 0 | P49: =SUM(H49:O49) -> 24564.26 | Q49: =G49-P49 -> 0
A50: 45 | B50: Prabhat Crane Service-CRS | C50: Gujarat | D50: Expenses | E50: Repair & Maintenance | G50: =IFERROR(SUMIFS(TB!C:C,TB!A:A,B50)-SUMIFS(TB!B:B,TB!A:A,B50),0) -> 24592 | H50: =SUMIFS('Bill Wise'!I:I,'Bill Wise'!C:C,B50,'Bill Wise'!H:H,"0-30 Days") -> 24592 | I50: =SUMIFS('Bill Wise'!I:I,'Bill Wise'!C:C,B50,'Bill Wise'!H:H,"31-60 Days") -> 0 | J50: =SUMIFS('Bill Wise'!I:I,'Bill Wise'!C:C,B50,'Bill Wise'!H:H,"61-90 Days") -> 0 | K50: =SUMIFS('Bill Wise'!I:I,'Bill Wise'!C:C,B50,'Bill Wise'!H:H,"91-120 Days") -> 0 | L50: =SUMIFS('Bill Wise'!I:I,'Bill Wise'!C:C,B50,'Bill Wise'!H:H,"121-150 Days") -> 0 | M50: =SUMIFS('Bill Wise'!I:I,'Bill Wise'!C:C,B50,'Bill Wise'!H:H,"151-180 Days") -> 0 | N50: =SUMIFS('Bill Wise'!I:I,'Bill Wise'!C:C,B50,'Bill Wise'!H:H,"181-365 Days") -> 0 | O50: =SUMIFS('Bill Wise'!I:I,'Bill Wise'!C:C,B50,'Bill Wise'!H:H,"Above 365 Days") -> 0 | P50: =SUM(H50:O50) -> 24592 | Q50: =G50-P50 -> 0
A51: 46 | B51: Rice Lake Weighing System India - Crs | C51: Galsi | D51: Expenses | E51: 0 | G51: =IFERROR(SUMIFS(TB!C:C,TB!A:A,B51)-SUMIFS(TB!B:B,TB!A:A,B51),0) -> 24759 | H51: =SUMIFS('Bill Wise'!I:I,'Bill Wise'!C:C,B51,'Bill Wise'!H:H,"0-30 Days") -> 24759 | I51: =SUMIFS('Bill Wise'!I:I,'Bill Wise'!C:C,B51,'Bill Wise'!H:H,"31-60 Days") -> 0 | J51: =SUMIFS('Bill Wise'!I:I,'Bill Wise'!C:C,B51,'Bill Wise'!H:H,"61-90 Days") -> 0 | K51: =SUMIFS('Bill Wise'!I:I,'Bill Wise'!C:C,B51,'Bill Wise'!H:H,"91-120 Days") -> 0 | L51: =SUMIFS('Bill Wise'!I:I,'Bill Wise'!C:C,B51,'Bill Wise'!H:H,"121-150 Days") -> 0 | M51: =SUMIFS('Bill Wise'!I:I,'Bill Wise'!C:C,B51,'Bill Wise'!H:H,"151-180 Days") -> 0 | N51: =SUMIFS('Bill Wise'!I:I,'Bill Wise'!C:C,B51,'Bill Wise'!H:H,"181-365 Days") -> 0 | O51: =SUMIFS('Bill Wise'!I:I,'Bill Wise'!C:C,B51,'Bill Wise'!H:H,"Above 365 Days") -> 0 | P51: =SUM(H51:O51) -> 24759 | Q51: =G51-P51 -> 0
A52: 47 | B52: NAVEEN P REDDY - Crs | C52: Nellore | D52: Expenses | E52: Rent | G52: =IFERROR(SUMIFS(TB!C:C,TB!A:A,B52)-SUMIFS(TB!B:B,TB!A:A,B52),0) -> 27225 | H52: =SUMIFS('Bill Wise'!I:I,'Bill Wise'!C:C,B52,'Bill Wise'!H:H,"0-30 Days") -> 27225 | I52: =SUMIFS('Bill Wise'!I:I,'Bill Wise'!C:C,B52,'Bill Wise'!H:H,"31-60 Days") -> 0 | J52: =SUMIFS('Bill Wise'!I:I,'Bill Wise'!C:C,B52,'Bill Wise'!H:H,"61-90 Days") -> 0 | K52: =SUMIFS('Bill Wise'!I:I,'Bill Wise'!C:C,B52,'Bill Wise'!H:H,"91-120 Days") -> 0 | L52: =SUMIFS('Bill Wise'!I:I,'Bill Wise'!C:C,B52,'Bill Wise'!H:H,"121-150 Days") -> 0 | M52: =SUMIFS('Bill Wise'!I:I,'Bill Wise'!C:C,B52,'Bill Wise'!H:H,"151-180 Days") -> 0 | N52: =SUMIFS('Bill Wise'!I:I,'Bill Wise'!C:C,B52,'Bill Wise'!H:H,"181-365 Days") -> 0 | O52: =SUMIFS('Bill Wise'!I:I,'Bill Wise'!C:C,B52,'Bill Wise'!H:H,"Above 365 Days") -> 0 | P52: =SUM(H52:O52) -> 27225 | Q52: =G52-P52 -> 0
A53: 48 | B53: Accurate Engineering Works-Crs | C53: Gujarat | D53: Expenses | E53: Store and spare | G53: =IFERROR(SUMIFS(TB!C:C,TB!A:A,B53)-SUMIFS(TB!B:B,TB!A:A,B53),0) -> 30444 | H53: =SUMIFS('Bill Wise'!I:I,'Bill Wise'!C:C,B53,'Bill Wise'!H:H,"0-30 Days") -> 30444 | I53: =SUMIFS('Bill Wise'!I:I,'Bill Wise'!C:C,B53,'Bill Wise'!H:H,"31-60 Days") -> 0 | J53: =SUMIFS('Bill Wise'!I:I,'Bill Wise'!C:C,B53,'Bill Wise'!H:H,"61-90 Days") -> 0 | K53: =SUMIFS('Bill Wise'!I:I,'Bill Wise'!C:C,B53,'Bill Wise'!H:H,"91-120 Days") -> 0 | L53: =SUMIFS('Bill Wise'!I:I,'Bill Wise'!C:C,B53,'Bill Wise'!H:H,"121-150 Days") -> 0 | M53: =SUMIFS('Bill Wise'!I:I,'Bill Wise'!C:C,B53,'Bill Wise'!H:H,"151-180 Days") -> 0 | N53: =SUMIFS('Bill Wise'!I:I,'Bill Wise'!C:C,B53,'Bill Wise'!H:H,"181-365 Days") -> 0 | O53: =SUMIFS('Bill Wise'!I:I,'Bill Wise'!C:C,B53,'Bill Wise'!H:H,"Above 365 Days") -> 0 | P53: =SUM(H53:O53) -> 30444 | Q53: =G53-P53 -> 0
A54: 49 | B54: Chukha Ferro Alloys Pvt Ltd- Crs | C54: Haryana | D54: Trading | E54: Bhutan Vendor | G54: =IFERROR(SUMIFS(TB!C:C,TB!A:A,B54)-SUMIFS(TB!B:B,TB!A:A,B54),0) -> 32191.76 | H54: =SUMIFS('Bill Wise'!I:I,'Bill Wise'!C:C,B54,'Bill Wise'!H:H,"0-30 Days") -> 32191.76 | I54: =SUMIFS('Bill Wise'!I:I,'Bill Wise'!C:C,B54,'Bill Wise'!H:H,"31-60 Days") -> 0 | J54: =SUMIFS('Bill Wise'!I:I,'Bill Wise'!C:C,B54,'Bill Wise'!H:H,"61-90 Days") -> 0 | K54: =SUMIFS('Bill Wise'!I:I,'Bill Wise'!C:C,B54,'Bill Wise'!H:H,"91-120 Days") -> 0 | L54: =SUMIFS('Bill Wise'!I:I,'Bill Wise'!C:C,B54,'Bill Wise'!H:H,"121-150 Days") -> 0 | M54: =SUMIFS('Bill Wise'!I:I,'Bill Wise'!C:C,B54,'Bill Wise'!H:H,"151-180 Days") -> 0 | N54: =SUMIFS('Bill Wise'!I:I,'Bill Wise'!C:C,B54,'Bill Wise'!H:H,"181-365 Days") -> 0 | O54: =SUMIFS('Bill Wise'!I:I,'Bill Wise'!C:C,B54,'Bill Wise'!H:H,"Above 365 Days") -> 0 | P54: =SUM(H54:O54) -> 32191.76 | Q54: =G54-P54 -> 0
A55: 50 | B55: SAI SAMARTH SECURITY SERVICES & LABOUR SUPPLIER - Crs | C55: Nagpur | D55: Expenses | E55: Security charges | G55: =IFERROR(SUMIFS(TB!C:C,TB!A:A,B55)-SUMIFS(TB!B:B,TB!A:A,B55),0) -> 33320 | H55: =SUMIFS('Bill Wise'!I:I,'Bill Wise'!C:C,B55,'Bill Wise'!H:H,"0-30 Days") -> 33320 | I55: =SUMIFS('Bill Wise'!I:I,'Bill Wise'!C:C,B55,'Bill Wise'!H:H,"31-60 Days") -> 0 | J55: =SUMIFS('Bill Wise'!I:I,'Bill Wise'!C:C,B55,'Bill Wise'!H:H,"61-90 Days") -> 0 | K55: =SUMIFS('Bill Wise'!I:I,'Bill Wise'!C:C,B55,'Bill Wise'!H:H,"91-120 Days") -> 0 | L55: =SUMIFS('Bill Wise'!I:I,'Bill Wise'!C:C,B55,'Bill Wise'!H:H,"121-150 Days") -> 0 | M55: =SUMIFS('Bill Wise'!I:I,'Bill Wise'!C:C,B55,'Bill Wise'!H:H,"151-180 Days") -> 0 | N55: =SUMIFS('Bill Wise'!I:I,'Bill Wise'!C:C,B55,'Bill Wise'!H:H,"181-365 Days") -> 0 | O55: =SUMIFS('Bill Wise'!I:I,'Bill Wise'!C:C,B55,'Bill Wise'!H:H,"Above 365 Days") -> 0 | P55: =SUM(H55:O55) -> 33320 | Q55: =G55-P55 -> 0
A56: 51 | B56: Pramod Shinde - EMPLOYEE | C56: Head Office | D56: Employee | E56: Claim Exps | G56: =IFERROR(SUMIFS(TB!C:C,TB!A:A,B56)-SUMIFS(TB!B:B,TB!A:A,B56),0) -> 33829 | H56: =SUMIFS('Bill Wise'!I:I,'Bill Wise'!C:C,B56,'Bill Wise'!H:H,"0-30 Days") -> 33829 | I56: =SUMIFS('Bill Wise'!I:I,'Bill Wise'!C:C,B56,'Bill Wise'!H:H,"31-60 Days") -> 0 | J56: =SUMIFS('Bill Wise'!I:I,'Bill Wise'!C:C,B56,'Bill Wise'!H:H,"61-90 Days") -> 0 | K56: =SUMIFS('Bill Wise'!I:I,'Bill Wise'!C:C,B56,'Bill Wise'!H:H,"91-120 Days") -> 0 | L56: =SUMIFS('Bill Wise'!I:I,'Bill Wise'!C:C,B56,'Bill Wise'!H:H,"121-150 Days") -> 0 | M56: =SUMIFS('Bill Wise'!I:I,'Bill Wise'!C:C,B56,'Bill Wise'!H:H,"151-180 Days") -> 0 | N56: =SUMIFS('Bill Wise'!I:I,'Bill Wise'!C:C,B56,'Bill Wise'!H:H,"181-365 Days") -> 0 | O56: =SUMIFS('Bill Wise'!I:I,'Bill Wise'!C:C,B56,'Bill Wise'!H:H,"Above 365 Days") -> 0 | P56: =SUM(H56:O56) -> 33829 | Q56: =G56-P56 -> 0
...

Sheet Advances
A1: Ultrafine Mineral & Admixtures Pvt. Ltd.
A2: Creditors – Advance Payments (Debit Balances) | As at 30-June-2026
B3: SUBTOTAL | G3: =SUBTOTAL(9,G5:G60) -> -44503459 | H3: =SUBTOTAL(9,H5:H60) -> -10773370 | I3: =SUBTOTAL(9,I5:I60) -> -257950.4 | J3: =SUBTOTAL(9,J5:J60) -> -1792541.6 | K3: =SUBTOTAL(9,K5:K60) -> -45000 | L3: =SUBTOTAL(9,L5:L60) -> -432782.7 | M3: =SUBTOTAL(9,M5:M60) -> -187920 | N3: =SUBTOTAL(9,N5:N60) -> -25658410 | ... Q3: =SUBTOTAL(9,Q5:Q60) -> 0
A4: # | B4: Vendor Name | C4: Location | D4: Vendor Type | E4: Vendor Sub Type | G4: TB Balance (Cr) | H4: 0-30 Days | I4: 31-60 Days | J4: 61-90 Days | K4: 91-120 Days | L4: 121-150 Days | M4: 151-180 Days | N4: 181-365 Days | O4: Above 365 Days | P4: BW Total | Q4: Diff (TB-BW)
H5: =SUMIFS('Bill Wise'!I:I,'Bill Wise'!C:C,B5,'Bill Wise'!H:H,"0-30 Days") -> 0 | I5: =SUMIFS('Bill Wise'!I:I,'Bill Wise'!C:C,B5,'Bill Wise'!H:H,"31-60 Days") -> 0 | J5: =SUMIFS('Bill Wise'!I:I,'Bill Wise'!C:C,B5,'Bill Wise'!H:H,"61-90 Days") -> 0 | K5: =SUMIFS('Bill Wise'!I:I,'Bill Wise'!C:C,B5,'Bill Wise'!H:H,"91-120 Days") -> 0 | L5: =SUMIFS('Bill Wise'!I:I,'Bill Wise'!C:C,B5,'Bill Wise'!H:H,"121-150 Days") -> 0 | M5: =SUMIFS('Bill Wise'!I:I,'Bill Wise'!C:C,B5,'Bill Wise'!H:H,"151-180 Days") -> 0 | N5: =SUMIFS('Bill Wise'!I:I,'Bill Wise'!C:C,B5,'Bill Wise'!H:H,"181-365 Days") -> 0 | O5: =SUMIFS('Bill Wise'!I:I,'Bill Wise'!C:C,B5,'Bill Wise'!H:H,"Above 365 Days") -> 0
A6: 1 | B6: Desai Cement Company Pvt Ltd-Crs | C6: Goa | D6: Expenses | E6: BG Incashed | G6: =IFERROR(SUMIFS(TB!C:C,TB!A:A,B6)-SUMIFS(TB!B:B,TB!A:A,B6),0) -> -13962953 | H6: =SUMIFS('Bill Wise'!I:I,'Bill Wise'!C:C,B6,'Bill Wise'!H:H,"0-30 Days") -> 0 | I6: =SUMIFS('Bill Wise'!I:I,'Bill Wise'!C:C,B6,'Bill Wise'!H:H,"31-60 Days") -> 0 | J6: =SUMIFS('Bill Wise'!I:I,'Bill Wise'!C:C,B6,'Bill Wise'!H:H,"61-90 Days") -> 0 | K6: =SUMIFS('Bill Wise'!I:I,'Bill Wise'!C:C,B6,'Bill Wise'!H:H,"91-120 Days") -> 0 | L6: =SUMIFS('Bill Wise'!I:I,'Bill Wise'!C:C,B6,'Bill Wise'!H:H,"121-150 Days") -> 0 | M6: =SUMIFS('Bill Wise'!I:I,'Bill Wise'!C:C,B6,'Bill Wise'!H:H,"151-180 Days") -> 0 | N6: =SUMIFS('Bill Wise'!I:I,'Bill Wise'!C:C,B6,'Bill Wise'!H:H,"181-365 Days") -> -13962953 | O6: =SUMIFS('Bill Wise'!I:I,'Bill Wise'!C:C,B6,'Bill Wise'!H:H,"Above 365 Days") -> 0 | P6: =SUM(H6:O6) -> -13962953 | Q6: =G6-P6 -> 0
A7: 2 | B7: Vedanta Limited (Goa) - Crs | C7: Goa | D7: Raw Material | E7: BG Issue | G7: =IFERROR(SUMIFS(TB!C:C,TB!A:A,B7)-SUMIFS(TB!B:B,TB!A:A,B7),0) -> -9481609.8 | H7: =SUMIFS('Bill Wise'!I:I,'Bill Wise'!C:C,B7,'Bill Wise'!H:H,"0-30 Days") -> 0 | I7: =SUMIFS('Bill Wise'!I:I,'Bill Wise'!C:C,B7,'Bill Wise'!H:H,"31-60 Days") -> 0 | J7: =SUMIFS('Bill Wise'!I:I,'Bill Wise'!C:C,B7,'Bill Wise'!H:H,"61-90 Days") -> 0 | K7: =SUMIFS('Bill Wise'!I:I,'Bill Wise'!C:C,B7,'Bill Wise'!H:H,"91-120 Days") -> 0 | L7: =SUMIFS('Bill Wise'!I:I,'Bill Wise'!C:C,B7,'Bill Wise'!H:H,"121-150 Days") -> 0 | M7: =SUMIFS('Bill Wise'!I:I,'Bill Wise'!C:C,B7,'Bill Wise'!H:H,"151-180 Days") -> 0 | N7: =SUMIFS('Bill Wise'!I:I,'Bill Wise'!C:C,B7,'Bill Wise'!H:H,"181-365 Days") -> -9481609.8 | O7: =SUMIFS('Bill Wise'!I:I,'Bill Wise'!C:C,B7,'Bill Wise'!H:H,"Above 365 Days") -> 0 | P7: =SUM(H7:O7) -> -9481609.8 | Q7: =G7-P7 -> 0
A8: 3 | B8: JAI Energy Giant Engineering and consultancy - Crs | C8: Nagpur | D8: Capex | E8: Capex Advance | G8: =IFERROR(SUMIFS(TB!C:C,TB!A:A,B8)-SUMIFS(TB!B:B,TB!A:A,B8),0) -> -4692357 | H8: =SUMIFS('Bill Wise'!I:I,'Bill Wise'!C:C,B8,'Bill Wise'!H:H,"0-30 Days") -> 0 | I8: =SUMIFS('Bill Wise'!I:I,'Bill Wise'!C:C,B8,'Bill Wise'!H:H,"31-60 Days") -> 0 | J8: =SUMIFS('Bill Wise'!I:I,'Bill Wise'!C:C,B8,'Bill Wise'!H:H,"61-90 Days") -> 0 | K8: =SUMIFS('Bill Wise'!I:I,'Bill Wise'!C:C,B8,'Bill Wise'!H:H,"91-120 Days") -> 0 | L8: =SUMIFS('Bill Wise'!I:I,'Bill Wise'!C:C,B8,'Bill Wise'!H:H,"121-150 Days") -> 0 | M8: =SUMIFS('Bill Wise'!I:I,'Bill Wise'!C:C,B8,'Bill Wise'!H:H,"151-180 Days") -> 0 | N8: =SUMIFS('Bill Wise'!I:I,'Bill Wise'!C:C,B8,'Bill Wise'!H:H,"181-365 Days") -> 0 | O8: =SUMIFS('Bill Wise'!I:I,'Bill Wise'!C:C,B8,'Bill Wise'!H:H,"Above 365 Days") -> -4692357 | P8: =SUM(H8:O8) -> -4692357 | Q8: =G8-P8 -> 0
A9: 4 | B9: Exalt Druk Enviroklens Pvt Ltd - Crs | C9: Haryana | D9: Trading | E9: Bhutan Vendor | G9: =IFERROR(SUMIFS(TB!C:C,TB!A:A,B9)-SUMIFS(TB!B:B,TB!A:A,B9),0) -> -2387615 | H9: =SUMIFS('Bill Wise'!I:I,'Bill Wise'!C:C,B9,'Bill Wise'!H:H,"0-30 Days") -> -2387615 | I9: =SUMIFS('Bill Wise'!I:I,'Bill Wise'!C:C,B9,'Bill Wise'!H:H,"31-60 Days") -> 0 | J9: =SUMIFS('Bill Wise'!I:I,'Bill Wise'!C:C,B9,'Bill Wise'!H:H,"61-90 Days") -> 0 | K9: =SUMIFS('Bill Wise'!I:I,'Bill Wise'!C:C,B9,'Bill Wise'!H:H,"91-120 Days") -> 0 | L9: =SUMIFS('Bill Wise'!I:I,'Bill Wise'!C:C,B9,'Bill Wise'!H:H,"121-150 Days") -> 0 | M9: =SUMIFS('Bill Wise'!I:I,'Bill Wise'!C:C,B9,'Bill Wise'!H:H,"151-180 Days") -> 0 | N9: =SUMIFS('Bill Wise'!I:I,'Bill Wise'!C:C,B9,'Bill Wise'!H:H,"181-365 Days") -> 0 | O9: =SUMIFS('Bill Wise'!I:I,'Bill Wise'!C:C,B9,'Bill Wise'!H:H,"Above 365 Days") -> 0 | P9: =SUM(H9:O9) -> -2387615 | Q9: =G9-P9 -> 0
A10: 5 | B10: Kinshar Metals - Crs | C10: Haryana | D10: Trading | E10: Bhutan Vendor | G10: =IFERROR(SUMIFS(TB!C:C,TB!A:A,B10)-SUMIFS(TB!B:B,TB!A:A,B10),0) -> -2374700 | H10: =SUMIFS('Bill Wise'!I:I,'Bill Wise'!C:C,B10,'Bill Wise'!H:H,"0-30 Days") -> -2374700 | I10: =SUMIFS('Bill Wise'!I:I,'Bill Wise'!C:C,B10,'Bill Wise'!H:H,"31-60 Days") -> 0 | J10: =SUMIFS('Bill Wise'!I:I,'Bill Wise'!C:C,B10,'Bill Wise'!H:H,"61-90 Days") -> 0 | K10: =SUMIFS('Bill Wise'!I:I,'Bill Wise'!C:C,B10,'Bill Wise'!H:H,"91-120 Days") -> 0 | L10: =SUMIFS('Bill Wise'!I:I,'Bill Wise'!C:C,B10,'Bill Wise'!H:H,"121-150 Days") -> 0 | M10: =SUMIFS('Bill Wise'!I:I,'Bill Wise'!C:C,B10,'Bill Wise'!H:H,"151-180 Days") -> 0 | N10: =SUMIFS('Bill Wise'!I:I,'Bill Wise'!C:C,B10,'Bill Wise'!H:H,"181-365 Days") -> 0 | O10: =SUMIFS('Bill Wise'!I:I,'Bill Wise'!C:C,B10,'Bill Wise'!H:H,"Above 365 Days") -> 0 | P10: =SUM(H10:O10) -> -2374700 | Q10: =G10-P10 -> 0
A11: 6 | B11: DOED JUNG KUEN PHEN TRADING HOUSE-CRS | C11: Haryana | D11: Trading | E11: Bhutan Vendor | G11: =IFERROR(SUMIFS(TB!C:C,TB!A:A,B11)-SUMIFS(TB!B:B,TB!A:A,B11),0) -> -1949646.5 | H11: =SUMIFS('Bill Wise'!I:I,'Bill Wise'!C:C,B11,'Bill Wise'!H:H,"0-30 Days") -> -1949646.5 | I11: =SUMIFS('Bill Wise'!I:I,'Bill Wise'!C:C,B11,'Bill Wise'!H:H,"31-60 Days") -> 0 | J11: =SUMIFS('Bill Wise'!I:I,'Bill Wise'!C:C,B11,'Bill Wise'!H:H,"61-90 Days") -> 0 | K11: =SUMIFS('Bill Wise'!I:I,'Bill Wise'!C:C,B11,'Bill Wise'!H:H,"91-120 Days") -> 0 | L11: =SUMIFS('Bill Wise'!I:I,'Bill Wise'!C:C,B11,'Bill Wise'!H:H,"121-150 Days") -> 0 | M11: =SUMIFS('Bill Wise'!I:I,'Bill Wise'!C:C,B11,'Bill Wise'!H:H,"151-180 Days") -> 0 | N11: =SUMIFS('Bill Wise'!I:I,'Bill Wise'!C:C,B11,'Bill Wise'!H:H,"181-365 Days") -> 0 | O11: =SUMIFS('Bill Wise'!I:I,'Bill Wise'!C:C,B11,'Bill Wise'!H:H,"Above 365 Days") -> 0 | P11: =SUM(H11:O11) -> -1949646.5 | Q11: =G11-P11 -> 0
A12: 7 | B12: Fourteckh Enviro India Pvt Ltd - Crs | C12: Gujarat | D12: Capex | E12: Capex Advance | G12: =IFERROR(SUMIFS(TB!C:C,TB!A:A,B12)-SUMIFS(TB!B:B,TB!A:A,B12),0) -> -1228000 | H12: =SUMIFS('Bill Wise'!I:I,'Bill Wise'!C:C,B12,'Bill Wise'!H:H,"0-30 Days") -> -1228000 | I12: =SUMIFS('Bill Wise'!I:I,'Bill Wise'!C:C,B12,'Bill Wise'!H:H,"31-60 Days") -> 0 | J12: =SUMIFS('Bill Wise'!I:I,'Bill Wise'!C:C,B12,'Bill Wise'!H:H,"61-90 Days") -> 0 | K12: =SUMIFS('Bill Wise'!I:I,'Bill Wise'!C:C,B12,'Bill Wise'!H:H,"91-120 Days") -> 0 | L12: =SUMIFS('Bill Wise'!I:I,'Bill Wise'!C:C,B12,'Bill Wise'!H:H,"121-150 Days") -> 0 | M12: =SUMIFS('Bill Wise'!I:I,'Bill Wise'!C:C,B12,'Bill Wise'!H:H,"151-180 Days") -> 0 | N12: =SUMIFS('Bill Wise'!I:I,'Bill Wise'!C:C,B12,'Bill Wise'!H:H,"181-365 Days") -> 0 | O12: =SUMIFS('Bill Wise'!I:I,'Bill Wise'!C:C,B12,'Bill Wise'!H:H,"Above 365 Days") -> 0 | P12: =SUM(H12:O12) -> -1228000 | Q12: =G12-P12 -> 0
A13: 8 | B13: M/s Macro Engineers-Crs | C13: Gujarat | D13: Expenses | E13: Stores and Spares | G13: =IFERROR(SUMIFS(TB!C:C,TB!A:A,B13)-SUMIFS(TB!B:B,TB!A:A,B13),0) -> -955800 | H13: =SUMIFS('Bill Wise'!I:I,'Bill Wise'!C:C,B13,'Bill Wise'!H:H,"0-30 Days") -> 0 | I13: =SUMIFS('Bill Wise'!I:I,'Bill Wise'!C:C,B13,'Bill Wise'!H:H,"31-60 Days") -> 0 | J13: =SUMIFS('Bill Wise'!I:I,'Bill Wise'!C:C,B13,'Bill Wise'!H:H,"61-90 Days") -> -955800 | K13: =SUMIFS('Bill Wise'!I:I,'Bill Wise'!C:C,B13,'Bill Wise'!H:H,"91-120 Days") -> 0 | L13: =SUMIFS('Bill Wise'!I:I,'Bill Wise'!C:C,B13,'Bill Wise'!H:H,"121-150 Days") -> 0 | M13: =SUMIFS('Bill Wise'!I:I,'Bill Wise'!C:C,B13,'Bill Wise'!H:H,"151-180 Days") -> 0 | N13: =SUMIFS('Bill Wise'!I:I,'Bill Wise'!C:C,B13,'Bill Wise'!H:H,"181-365 Days") -> 0 | O13: =SUMIFS('Bill Wise'!I:I,'Bill Wise'!C:C,B13,'Bill Wise'!H:H,"Above 365 Days") -> 0 | P13: =SUM(H13:O13) -> -955800 | Q13: =G13-P13 -> 0
A14: 9 | B14: Eurocem Additives Private Limited-Crs | C14: Head Office | D14: Capex | E14: Interest | G14: =IFERROR(SUMIFS(TB!C:C,TB!A:A,B14)-SUMIFS(TB!B:B,TB!A:A,B14),0) -> -714140 | H14: =SUMIFS('Bill Wise'!I:I,'Bill Wise'!C:C,B14,'Bill Wise'!H:H,"0-30 Days") -> 0 | I14: =SUMIFS('Bill Wise'!I:I,'Bill Wise'!C:C,B14,'Bill Wise'!H:H,"31-60 Days") -> 0 | J14: =SUMIFS('Bill Wise'!I:I,'Bill Wise'!C:C,B14,'Bill Wise'!H:H,"61-90 Days") -> -714140 | K14: =SUMIFS('Bill Wise'!I:I,'Bill Wise'!C:C,B14,'Bill Wise'!H:H,"91-120 Days") -> 0 | L14: =SUMIFS('Bill Wise'!I:I,'Bill Wise'!C:C,B14,'Bill Wise'!H:H,"121-150 Days") -> 0 | M14: =SUMIFS('Bill Wise'!I:I,'Bill Wise'!C:C,B14,'Bill Wise'!H:H,"151-180 Days") -> 0 | N14: =SUMIFS('Bill Wise'!I:I,'Bill Wise'!C:C,B14,'Bill Wise'!H:H,"181-365 Days") -> 0 | O14: =SUMIFS('Bill Wise'!I:I,'Bill Wise'!C:C,B14,'Bill Wise'!H:H,"Above 365 Days") -> 0 | P14: =SUM(H14:O14) -> -714140 | Q14: =G14-P14 -> 0
A15: 10 | B15: JASSPER SHIPPING INDIA LIMITED- CRS | C15: Goa | D15: Transportation | E15: GST Claim | G15: =IFERROR(SUMIFS(TB!C:C,TB!A:A,B15)-SUMIFS(TB!B:B,TB!A:A,B15),0) -> -653396 | H15: =SUMIFS('Bill Wise'!I:I,'Bill Wise'!C:C,B15,'Bill Wise'!H:H,"0-30 Days") -> 0 | I15: =SUMIFS('Bill Wise'!I:I,'Bill Wise'!C:C,B15,'Bill Wise'!H:H,"31-60 Days") -> 0 | J15: =SUMIFS('Bill Wise'!I:I,'Bill Wise'!C:C,B15,'Bill Wise'!H:H,"61-90 Days") -> 0 | K15: =SUMIFS('Bill Wise'!I:I,'Bill Wise'!C:C,B15,'Bill Wise'!H:H,"91-120 Days") -> 0 | L15: =SUMIFS('Bill Wise'!I:I,'Bill Wise'!C:C,B15,'Bill Wise'!H:H,"121-150 Days") -> 0 | M15: =SUMIFS('Bill Wise'!I:I,'Bill Wise'!C:C,B15,'Bill Wise'!H:H,"151-180 Days") -> 0 | N15: =SUMIFS('Bill Wise'!I:I,'Bill Wise'!C:C,B15,'Bill Wise'!H:H,"181-365 Days") -> -653396 | O15: =SUMIFS('Bill Wise'!I:I,'Bill Wise'!C:C,B15,'Bill Wise'!H:H,"Above 365 Days") -> 0 | P15: =SUM(H15:O15) -> -653396 | Q15: =G15-P15 -> 0
A16: 11 | B16: Steel & Power-CR (CAP) - Crs | C16: Gujarat | D16: Capex | E16: Capex Advance | G16: =IFERROR(SUMIFS(TB!C:C,TB!A:A,B16)-SUMIFS(TB!B:B,TB!A:A,B16),0) -> -650000 | H16: =SUMIFS('Bill Wise'!I:I,'Bill Wise'!C:C,B16,'Bill Wise'!H:H,"0-30 Days") -> 0 | I16: =SUMIFS('Bill Wise'!I:I,'Bill Wise'!C:C,B16,'Bill Wise'!H:H,"31-60 Days") -> 0 | J16: =SUMIFS('Bill Wise'!I:I,'Bill Wise'!C:C,B16,'Bill Wise'!H:H,"61-90 Days") -> 0 | K16: =SUMIFS('Bill Wise'!I:I,'Bill Wise'!C:C,B16,'Bill Wise'!H:H,"91-120 Days") -> 0 | L16: =SUMIFS('Bill Wise'!I:I,'Bill Wise'!C:C,B16,'Bill Wise'!H:H,"121-150 Days") -> 0 | M16: =SUMIFS('Bill Wise'!I:I,'Bill Wise'!C:C,B16,'Bill Wise'!H:H,"151-180 Days") -> 0 | N16: =SUMIFS('Bill Wise'!I:I,'Bill Wise'!C:C,B16,'Bill Wise'!H:H,"181-365 Days") -> 0 | O16: =SUMIFS('Bill Wise'!I:I,'Bill Wise'!C:C,B16,'Bill Wise'!H:H,"Above 365 Days") -> -650000 | P16: =SUM(H16:O16) -> -650000 | Q16: =G16-P16 -> 0
A17: 12 | B17: SHIVSHAKTI ENTERPRISES - Crs | C17: flyash | D17: Raw Material | E17: Advance With Vendor Invoice or Refund Required | G17: =IFERROR(SUMIFS(TB!C:C,TB!A:A,B17)-SUMIFS(TB!B:B,TB!A:A,B17),0) -> -649762.84 | H17: =SUMIFS('Bill Wise'!I:I,'Bill Wise'!C:C,B17,'Bill Wise'!H:H,"0-30 Days") -> 0 | I17: =SUMIFS('Bill Wise'!I:I,'Bill Wise'!C:C,B17,'Bill Wise'!H:H,"31-60 Days") -> 0 | J17: =SUMIFS('Bill Wise'!I:I,'Bill Wise'!C:C,B17,'Bill Wise'!H:H,"61-90 Days") -> 0 | K17: =SUMIFS('Bill Wise'!I:I,'Bill Wise'!C:C,B17,'Bill Wise'!H:H,"91-120 Days") -> 0 | L17: =SUMIFS('Bill Wise'!I:I,'Bill Wise'!C:C,B17,'Bill Wise'!H:H,"121-150 Days") -> 0 | M17: =SUMIFS('Bill Wise'!I:I,'Bill Wise'!C:C,B17,'Bill Wise'!H:H,"151-180 Days") -> 0 | N17: =SUMIFS('Bill Wise'!I:I,'Bill Wise'!C:C,B17,'Bill Wise'!H:H,"181-365 Days") -> -649762.84 | O17: =SUMIFS('Bill Wise'!I:I,'Bill Wise'!C:C,B17,'Bill Wise'!H:H,"Above 365 Days") -> 0 | P17: =SUM(H17:O17) -> -649762.84 | Q17: =G17-P17 -> 0
... A59: 55 | B59: Vinayak Oil Industries - Crs | C59: Nagpur | D59: Expenses | E59: Repair & Maintenance | G59: =IFERROR(SUMIFS(TB!C:C,TB!A:A,B59)-SUMIFS(TB!B:B,TB!A:A,B59),0) -> -0.58 | H59: =SUMIFS('Bill Wise'!I:I,'Bill Wise'!C:C,B59,'Bill Wise'!H:H,"0-30 Days") -> 0 | I59: =SUMIFS('Bill Wise'!I:I,'Bill Wise'!C:C,B59,'Bill Wise'!H:H,"31-60 Days") -> 0 | J59: =SUMIFS('Bill Wise'!I:I,'Bill Wise'!C:C,B59,'Bill Wise'!H:H,"61-90 Days") -> -0.58 | K59: =SUMIFS('Bill Wise'!I:I,'Bill Wise'!C:C,B59,'Bill Wise'!H:H,"91-120 Days") -> 0 | L59: =SUMIFS('Bill Wise'!I:I,'Bill Wise'!C:C,B59,'Bill Wise'!H:H,"121-150 Days") -> 0 | M59: =SUMIFS('Bill Wise'!I:I,'Bill Wise'!C:C,B59,'Bill Wise'!H:H,"151-180 Days") -> 0 | N59: =SUMIFS('Bill Wise'!I:I,'Bill Wise'!C:C,B59,'Bill Wise'!H:H,"181-365 Days") -> 0 | O59: =SUMIFS('Bill Wise'!I:I,'Bill Wise'!C:C,B59,'Bill Wise'!H:H,"Above 365 Days") -> 0 | P59: =SUM(H59:O59) -> -0.58 | Q59: =G59-P59 -> 0
B61: Grand Total | G61: =SUM(G4:G60) -> -44503459 | H61: =SUM(H4:H60) -> -10773370 | I61: =SUM(I4:I60) -> -257950.4 | J61: =SUM(J4:J60) -> -1792541.6 | K61: =SUM(K4:K60) -> -45000 | L61: =SUM(L4:L60) -> -432782.7 | M61: =SUM(M4:M60) -> -187920 | N61: =SUM(N4:N60) -> -25658410 | ... Q61: =SUM(Q4:Q60) -> 0

Sheet Intercompany
A1: Ultrafine Mineral & Admixtures Pvt. Ltd.
A2: Creditors Ageing Report - Intercompany & Special | As at 30-Jun-2026
B3: SUBTOTAL | E3: =SUBTOTAL(9,E5:E24) -> 1.306018e+08 | F3: =SUBTOTAL(9,F5:F24) -> 24335937 | G3: =SUBTOTAL(9,G5:G24) -> 2729956.6 | H3: =SUBTOTAL(9,H5:H24) -> 3836467.5 | I3: =SUBTOTAL(9,I5:I24) -> 29521126 | J3: =SUBTOTAL(9,J5:J24) -> 11584568 | K3: =SUBTOTAL(9,K5:K24) -> 862289.56 | L3: =SUBTOTAL(9,L5:L24) -> 39612486 | ... O3: =SUBTOTAL(9,O5:O24) -> 0
A4: # | B4: Vendor Name | C4: Vendor Type | E4: TB Balance (Cr) | F4: 0-30 Days | G4: 31-60 Days | H4: 61-90 Days | I4: 91-120 Days | J4: 121-150 Days | K4: 151-180 Days | L4: 181-365 Days | M4: Above 365 Days | N4: BW Total | O4: Diff (TB-BW)
A6: 1 | B6: RDC Concrete India Pvt. Ltd. Punjab - Crs | C6: Intercompany | E6: =IFERROR(SUMIFS(TB!C:C,TB!A:A,B6)-SUMIFS(TB!B:B,TB!A:A,B6),0) -> 30680 | F6: =SUMIFS('Bill Wise'!I:I,'Bill Wise'!C:C,B6,'Bill Wise'!H:H,"0-30 Days") -> 0 | G6: =SUMIFS('Bill Wise'!I:I,'Bill Wise'!C:C,B6,'Bill Wise'!H:H,"31-60 Days") -> 0 | H6: =SUMIFS('Bill Wise'!I:I,'Bill Wise'!C:C,B6,'Bill Wise'!H:H,"61-90 Days") -> 0 | I6: =SUMIFS('Bill Wise'!I:I,'Bill Wise'!C:C,B6,'Bill Wise'!H:H,"91-120 Days") -> 0 | J6: =SUMIFS('Bill Wise'!I:I,'Bill Wise'!C:C,B6,'Bill Wise'!H:H,"121-150 Days") -> 0 | K6: =SUMIFS('Bill Wise'!I:I,'Bill Wise'!C:C,B6,'Bill Wise'!H:H,"151-180 Days") -> 0 | L6: =SUMIFS('Bill Wise'!I:I,'Bill Wise'!C:C,B6,'Bill Wise'!H:H,"181-365 Days") -> 30680 | M6: =SUMIFS('Bill Wise'!I:I,'Bill Wise'!C:C,B6,'Bill Wise'!H:H,"Above 365 Days") -> 0 | N6: =SUM(F6:M6) -> 30680 | O6: =E6-N6 -> 0
A7: 2 | B7: RDC Concrete (India) Pvt Ltd (Bangalore)-Crs | C7: Intercompany | E7: =IFERROR(SUMIFS(TB!C:C,TB!A:A,B7)-SUMIFS(TB!B:B,TB!A:A,B7),0) -> 215334 | F7: =SUMIFS('Bill Wise'!I:I,'Bill Wise'!C:C,B7,'Bill Wise'!H:H,"0-30 Days") -> 0 | G7: =SUMIFS('Bill Wise'!I:I,'Bill Wise'!C:C,B7,'Bill Wise'!H:H,"31-60 Days") -> 0 | H7: =SUMIFS('Bill Wise'!I:I,'Bill Wise'!C:C,B7,'Bill Wise'!H:H,"61-90 Days") -> 0 | I7: =SUMIFS('Bill Wise'!I:I,'Bill Wise'!C:C,B7,'Bill Wise'!H:H,"91-120 Days") -> 0 | J7: =SUMIFS('Bill Wise'!I:I,'Bill Wise'!C:C,B7,'Bill Wise'!H:H,"121-150 Days") -> 0 | K7: =SUMIFS('Bill Wise'!I:I,'Bill Wise'!C:C,B7,'Bill Wise'!H:H,"151-180 Days") -> 0 | L7: =SUMIFS('Bill Wise'!I:I,'Bill Wise'!C:C,B7,'Bill Wise'!H:H,"181-365 Days") -> 215334 | M7: =SUMIFS('Bill Wise'!I:I,'Bill Wise'!C:C,B7,'Bill Wise'!H:H,"Above 365 Days") -> 0 | N7: =SUM(F7:M7) -> 215334 | O7: =E7-N7 -> 0
A8: 3 | B8: RDC Concrete (India) Pvt Ltd (Haryana)-Crs | C8: Intercompany | E8: =IFERROR(SUMIFS(TB!C:C,TB!A:A,B8)-SUMIFS(TB!B:B,TB!A:A,B8),0) -> 332760 | F8: =SUMIFS('Bill Wise'!I:I,'Bill Wise'!C:C,B8,'Bill Wise'!H:H,"0-30 Days") -> 0 | G8: =SUMIFS('Bill Wise'!I:I,'Bill Wise'!C:C,B8,'Bill Wise'!H:H,"31-60 Days") -> 0 | H8: =SUMIFS('Bill Wise'!I:I,'Bill Wise'!C:C,B8,'Bill Wise'!H:H,"61-90 Days") -> 0 | I8: =SUMIFS('Bill Wise'!I:I,'Bill Wise'!C:C,B8,'Bill Wise'!H:H,"91-120 Days") -> 332760 | J8: =SUMIFS('Bill Wise'!I:I,'Bill Wise'!C:C,B8,'Bill Wise'!H:H,"121-150 Days") -> 0 | K8: =SUMIFS('Bill Wise'!I:I,'Bill Wise'!C:C,B8,'Bill Wise'!H:H,"151-180 Days") -> 0 | L8: =SUMIFS('Bill Wise'!I:I,'Bill Wise'!C:C,B8,'Bill Wise'!H:H,"181-365 Days") -> 0 | M8: =SUMIFS('Bill Wise'!I:I,'Bill Wise'!C:C,B8,'Bill Wise'!H:H,"Above 365 Days") -> 0 | N8: =SUM(F8:M8) -> 332760 | O8: =E8-N8 -> 0
