Workbook

Sheet Summary
B1: Cash Flow as of 11th December , 2025
B2: Sr.No. | C2: Location | D2: Authorized Person | F2: Collection Dec- 2025 | G2: Payable (80 % Of Collection) | H2: Reserve ( 20% of Collection) | I2: Actual Paid | J2: Statutory & Others Expns | K2: Balance
B3: 1 | C3: Aggregate | D3: Saptarishi Majumdar | F3: =SUMIF(Receipts!$G$4:$G$101,Summary!C3,Receipts!$E$4:$E$101)/100000 -> 0 | G3: =F3*80% -> 0 | H3: =F3*20% -> 0 | I3: =SUMIF(Payments!#REF!,Summary!C3,Payments!#REF!)/100000 -> #REF! | K3: =G3-I3 -> #REF!
B4: 2 | C4: Main Operation | D4: Devanand Singh | F4: =SUMIF(Receipts!$G$4:$G$101,Summary!C4,Receipts!$E$4:$E$101)/100000 -> 400.57365 | G4: =F4*80% -> 320.45892 | H4: =F4*20% -> 80.114731 | I4: =SUMIF(Payments!#REF!,Summary!C4,Payments!#REF!)/100000 -> #REF! | K4: =G4-I4 -> #REF!
B5: 3 | C5: Flyash | D5: Harish Ludhani | F5: =SUMIF(Receipts!$G$4:$G$101,Summary!C5,Receipts!$E$4:$E$101)/100000 -> 0 | G5: =F5*80% -> 0 | H5: =F5*20% -> 0 | I5: =SUMIF(Payments!#REF!,Summary!C5,Payments!#REF!)/100000 -> #REF! | K5: =G5-I5 -> #REF!
C7: Statutory Exps & Others
C8: Interest & EMI | J8: =SUMIF(Payments!#REF!,Summary!C8,Payments!#REF!)/100000 -> #REF!
C9: IOCL | J9: =SUMIF(Payments!#REF!,Summary!C9,Payments!#REF!)/100000 -> #REF!
C10: Employee | J10: =SUMIF(Payments!#REF!,Summary!C10,Payments!#REF!)/100000 -> #REF!
C11: TDS | J11: =SUMIF(Payments!#REF!,Summary!C11,Payments!#REF!)/100000 -> #REF!
C13: Total | F13: =SUM(F3:F12) -> 400.57365 | G13: =SUM(G3:G12) -> 320.45892 | H13: =SUM(H3:H12) -> 80.114731 | I13: =SUM(I3:I12) -> #REF! | J13: =SUM(J3:J12) -> #REF! | K13: =SUM(K3:K12) -> #REF!
B16: Cash Flow as of 12th October, 2026 Amt in Lacs
B17: Sr.No. | C17: Location | D17: Authorized Person | E17: Op. Balance | F17: Collection July- 2026 | G17: Payable (80 % Of Collection) | H17: Reserve ( 20% of Collection) | I17: Actual Paid | J17: Statutory & Others Expns | K17: Cl. Balance
B18: 1 | C18: Aggregate Pachami Trading | D18: Saptarishi Majumdar / Sandeep Singh | E18: 58.634263 | F18: =SUMIF(Receipts!$G$4:$G$101,Summary!C18,Receipts!$E$4:$E$101)/100000 -> 26.426208 | G18: =(F18*95%) -> 25.104897 | H18: =F18*20% -> 5.2852415 | I18: =SUMIF(Payments!$H$3:$H$189,Summary!C18,Payments!$E$3:$E$189)/100000 -> 1.319068 | K18: =E18+G18-I18 -> 82.420092
B19: 2 | C19: Aggregate Panagarh Crusher | E19: -109.00272 | F19: =SUMIF(Receipts!$G$4:$G$101,Summary!C19,Receipts!$E$4:$E$101)/100000 -> 12.914766 | G19: =(F19*95%) -> 12.269028 | H19: =F19*20% -> 2.5829532 | I19: =SUMIF(Payments!$H$3:$H$189,Summary!C19,Payments!$E$3:$E$189)/100000 -> 38.488404 | K19: =E19+G19-I19 -> -135.22209
D20: Total Panagarh | E20: -50.368452 | F20: =F19+F18 -> 39.340974 | G20: =G19+G18 -> 37.373925 | I20: =I19+I18 -> 39.807472 | K20: =K19+K18 -> -52.801999
B21: 3 | C21: Main Operation | D21: Devanand Singh | E21: -419.7182 | F21: =SUMIF(Receipts!$G$4:$G$101,Summary!C21,Receipts!$E$4:$E$101)/100000 -> 400.57365 | G21: =(F21*80%) -> 320.45892 | H21: =F21*20% -> 80.114731 | I21: =SUMIF(Payments!$H$3:$H$189,Summary!C21,Payments!$E$3:$E$189)/100000 -> 260.45312 | K21: =E21+G21-I21 -> -359.71239
B22: 4 | C22: Flyash Business | D22: Harish Ludhani | E22: -147.76159 | F22: =SUMIF(Receipts!$G$4:$G$101,Summary!C22,Receipts!$E$4:$E$101)/100000 -> 46.170424 | G22: =(F22*80%) -> 36.936339 | H22: =F22*20% -> 9.2340849 | I22: =SUMIF(Payments!$H$3:$H$189,Summary!C22,Payments!$E$3:$E$189)/100000 -> 56.831229 | K22: =E22+G22-I22 -> -167.65648
B23: 5 | C23: Trading Business | D23: Saif Khan | E23: -102.38115 | F23: =SUMIF(Receipts!$G$4:$G$101,Summary!C23,Receipts!$E$4:$E$101)/100000 -> 44.895206 | G23: =(F23*80%) -> 35.916165 | I23: =SUMIF(Payments!$H$3:$H$189,Summary!C23,Payments!$E$3:$E$189)/100000 -> 62.564721 | K23: =E23+G23-I23 -> -129.02971
B24: 6 | C24: Capex | E24: -124.34189 | F24: =SUMIF(Receipts!$G$4:$G$101,Summary!C24,Receipts!$E$4:$E$101)/100000 -> 0 | G24: =(F24*100%) -> 0 | I24: =SUMIF(Payments!$H$3:$H$189,Summary!C24,Payments!$E$3:$E$189)/100000 -> 75.118093 | K24: =E24+G24-I24 -> -199.45998
B25: 7 | C25: Head Office | E25: -378.5805 | F25: =SUMIF(Receipts!$G$4:$G$101,Summary!C25,Receipts!$E$4:$E$101)/100000 -> 214.23822 | G25: =(F25*100%) -> 214.23822 | I25: =SUMIF(Payments!$H$3:$H$189,Summary!C25,Payments!$E$3:$E$189)/100000 -> 260.76304 | K25: =E25+G25-I25 -> -425.10532
C27: Total | E27: =SUM(E20:E26) -> -1223.1518 | F27: =SUM(F20:F26) -> 745.21848 | G27: =SUM(G20:G26) -> 644.92357 | H27: =SUM(H20:H26) -> 89.348816 | I27: =SUM(I20:I26) -> 755.53767 | J27: =SUM(J20:J26) -> 0 | K27: =SUM(K20:K26) -> -1333.7659
D46: Particulars | E46: Amt in Lacs
D47: Salaries
D48: Onroll Salaries | E48: 45
D49: Consultancy | E49: 30
D50: Teamlease Salaries | E50: 30
D51: Con. Labour& Security | E51: =20+3+1.5 -> 24.5
D53: Auto Debits
D54: Interest & EMI | E54: =30 -> 30
D55: PDC Given | E55: 4
D56: IOCL | E56: 25
D58: Statutory Dues
D59: TDS Payable | E59: 33
D61: Others IMP
D62: Sree Rama | E62: 25
D63: Spares & Repairs | E63: 10
D64: Flyash | E64: 25
D65: Aggregate | E65: 35
D67: Transporters | E67: 35
...

Sheet payment
A2: Date | B2: Particulars | F2: Vch Type | G2: Vch No. | H2: Debit | I2: Credit
A3: 46093 | B3: Dr | C3: BAHUBALI CHEMICAL INDUSTRIES-CRS | F3: Payment (Gujarat) | G3: PV/GUJ/2526/0909 | I3: 1482706 | J3: BAHUBALI CHEMICAL INDUSTRIES-CRS | K3: Gujarat
A4: 46093 | B4: Dr | C4: SREERAMA INDUSTRIES PRIVATE LIMITED-Crs | F4: Payment (Vizag) | G4: PV/APV/2526/0218 | I4: 484841 | J4: SREERAMA INDUSTRIES PRIVATE LIMITED-Crs | K4: Vizag
A5: 46093 | B5: Dr | C5: P A Steel and Co - Crs | F5: Payment (Nagpur) | G5: PV/MHN/2526/0466 | I5: 584090 | J5: P A Steel and Co - Crs | K5: Nagpur
A6: 46093 | B6: Dr | C6: AMBUJA CEMENTS LIMITED -Crs | F6: Payment (Flyash Trading) | G6: PV/MHF/2526/0212 | I6: 1255400.4 | J6: AMBUJA CEMENTS LIMITED -Crs | K6: Flyash Trading
A7: 46093 | B7: Dr | C7: Chettinad Cement Corporation Private Limited - Crs | F7: Payment (Vizag) | G7: PV/APV/2526/0219 | I7: 788149 | J7: Chettinad Cement Corporation Private Limited - Crs | K7: Vizag
A8: 46093 | B8: Dr | C8: PATRA AND SUPPLIER-CRS | F8: Payment (Howrah) | G8: PV/WBH/2526/0160 | I8: 2876.8 | J8: PATRA AND SUPPLIER-CRS | K8: Howrah
A9: 46093 | B9: Dr | C9: DEEP ENTERPRISES-CRS | F9: Payment (Nagpur) | G9: PV/MHN/2526/0467 | I9: 3000 | J9: DEEP ENTERPRISES-CRS | K9: Nagpur
A10: 46093 | B10: Dr | C10: Durocrete Engineering Ser Vices PVT LTD-Crs | F10: Payment (Nagpur) | G10: PV/MHN/2526/0468 | I10: 3480 | J10: Durocrete Engineering Ser Vices PVT LTD-Crs | K10: Nagpur
A11: 46093 | B11: Dr | C11: KAPIL THAKARE - Crs | F11: Payment (Wada) | G11: PV/MHW/2526/0319 | I11: 3840 | J11: KAPIL THAKARE - Crs | K11: Wada
A12: 46093 | B12: Dr | C12: Yaa Baba Taj Restaurants - CRS | F12: Payment (Nagpur) | G12: PV/MHN/2526/0469 | I12: 4112 | J12: Yaa Baba Taj Restaurants - CRS | K12: Nagpur
A13: 46093 | B13: Dr | C13: Sunita Enterprises- Crs | F13: Payment (Panagarh-Microsilica)WB | G13: PV/WBM/2526/0332 | I13: 5310 | J13: Sunita Enterprises- Crs | K13: Microsilica
A14: 46093 | B14: Dr | C14: Jai Bhairunath | F14: Payment (Panagarh-Aggregate)WB | G14: PV/WBA/2526/0390 | I14: 5664 | J14: Jai Bhairunath | K14: Aggregate
... A142: 46101 | B142: Dr | C142: Revethi Dealers Pvt. Ltd. | F142: Payment (Panagarh-Aggregate)WB | G142: PV/WBA/2526/0399 | I142: 62059 | J142: Revethi Dealers Pvt. Ltd. | K142: Aggregate

Sheet Sheet1
A2: Date | B2: Particulars | F2: Vch Type | G2: Vch No. | H2: Debit | I2: Credit
A3: 46093 | B3: Dr | C3: Opening Balance | I3: 1.2551321e+08
A4: 46093 | B4: Dr | C4: BAHUBALI CHEMICAL INDUSTRIES-CRS | F4: Payment (Gujarat) | G4: PV/GUJ/2526/0909 | I4: 1482706
A5: 46093 | B5: Dr | C5: SREERAMA INDUSTRIES PRIVATE LIMITED-Crs | F5: Payment (Vishakhapattanam-Vizag) | G5: PV/APV/2526/0218 | I5: 484841
A6: 46093 | B6: Dr | C6: P A Steel and Co - Crs | F6: Payment (Nagpur) | G6: PV/MHN/2526/0466 | I6: 584090
A7: 46093 | B7: Dr | C7: AMBUJA CEMENTS LIMITED -Crs | F7: Payment (Flyash Trading) | G7: PV/MHF/2526/0212 | I7: 1255400.4
A8: 46093 | B8: Dr | C8: Chettinad Cement Corporation Private Limited - Crs | F8: Payment (Vishakhapattanam-Vizag) | G8: PV/APV/2526/0219 | I8: 788149
A9: 46093 | B9: Dr | C9: PATRA AND SUPPLIER-CRS | F9: Payment (Howrah) | G9: PV/WBH/2526/0160 | I9: 2876.8
A10: 46093 | B10: Dr | C10: DEEP ENTERPRISES-CRS | F10: Payment (Nagpur) | G10: PV/MHN/2526/0467 | I10: 3000
A11: 46093 | B11: Dr | C11: Durocrete Engineering Ser Vices PVT LTD-Crs | F11: Payment (Nagpur) | G11: PV/MHN/2526/0468 | I11: 3480
A12: 46093 | B12: Dr | C12: KAPIL THAKARE - Crs | F12: Payment (Wada) | G12: PV/MHW/2526/0319 | I12: 3840
A13: 46093 | B13: Dr | C13: Yaa Baba Taj Restaurants - CRS | F13: Payment (Nagpur) | G13: PV/MHN/2526/0469 | I13: 4112
A14: 46093 | B14: Dr | C14: Sunita Enterprises- Crs | F14: Payment (Panagarh-Microsilica)WB | G14: PV/WBM/2526/0332 | I14: 5310
A15: 46093 | B15: Dr | C15: Jai Bhairunath | F15: Payment (Panagarh-Aggregate)WB | G15: PV/WBA/2526/0390 | I15: 5664
... A39: 46093 | B39: Dr | C39: State Bank of India | F39: Contra (Head Office) | G39: 22 | I39: 2500000
A40: 46093 | B40: Cr | C40: Karim Shah - Employee | F40: Receipt (Head Office) | G40: RC/HO/2526/0209 | H40: 1
A41: 46093 | B41: Cr | C41: Karim Shah - Employee | F41: Receipt (Head Office) | G41: RC/HO/2526/0210 | H41: 21638
A42: 46093 | B42: Dr | C42: Thirumala Enterprises - Crs | F42: Payment (Nellore)AP | G42: PV/APN/2526/170 | I42: 350000
A43: 46093 | B43: Cr | C43: Nops Infrastructure Private Limited- Drs | F43: Receipt (Panagarh-Aggregate)WB | G43: RC/WBA/2526/0139 | H43: 200000
A44: 46093 | B44: Dr | C44: SREERAMA INDUSTRIES PRIVATE LIMITED-Crs | F44: Payment (Vishakhapattanam-Vizag) | G44: PV/APV/2526/0210 | I44: 1074240
A45: 46093 | B45: Dr | C45: M.B.S. Construction | F45: Payment (Panagarh-Aggregate)WB | G45: PV/WBA/2526/0379 | I45: 500000
A46: 46093 | B46: Dr | C46: P.S. Agency-CRS | F46: Payment (Panagarh-Aggregate)WB | G46: PV/WBA/2526/0387 | I46: 410373
A47: 46093 | B47: Cr | C47: H.G. Infra Engineering Ltd. - Drs | F47: Receipt (Howrah) | G47: RC/WBH/2526/0017 | H47: 330750
A48: 46093 | B48: Cr | C48: Ultratech Cement Limited - Drs | F48: Receipt (Gujarat) | G48: RC/GUJ/2526/0215 | H48: 480657
A49: 46093 | B49: Cr | C49: (as per details) | F49: Receipt (Head Office) | G49: RC/HO/2526/0213 | H49: 1000000
C50: RDC Concrete (India ) Pvt Ltd-Telangana-Drs | I50: 915635
C51: RDC Concrete ( India ) Pvt Ltd- Bangalore - Drs | I51: 84365
A52: 46093 | B52: Cr | C52: RDC Concrete ( India ) Pvt Ltd- Bangalore - Drs | F52: Receipt (Head Office) | G52: RC/HO/2526/0214 | H52: 1500000
A53: 46093 | B53: Cr | C53: Pyramid Infratech Pvt Ltd - Drs | F53: Receipt (Panagarh-Microsilica)WB | G53: RC/WBM/2526/0156 | H53: 1697760
A54: 46094 | B54: Dr | C54: ARKAY LOGISTICS-Crs | F54: Payment (Flyash Trading) | G54: PV/MHF/2526/0216 | I54: 238302.12
A55: 46094 | B55: Dr | C55: Bhushan Deshpande - Employee | F55: Payment (Head Office) | G55: PV/HO/2526/0761 | I55: 23871.08
A56: 46094 | B56: Dr | C56: Balram Kumar Chakrawarti - Employee | F56: Payment (Head Office) | G56: PV/HO/2526/0762 | I56: 20668
A57: 46094 | B57: Dr | C57: Sandeep Singh - Employee | F57: Payment (Panagarh-Aggregate)WB | G57: PV/WBA/2526/0392 | I57: 36978
A58: 46094 | B58: Dr | C58: (as per details) | F58: Payment (Haryana) | G58: PV/HR/2526/0161 | I58: 85500
C59: Atharva Enterprises - Crs | H59: 90000
C60: 194J TDS on Professional Fees | I60: 4500
A61: 46094 | B61: Dr | C61: Bharat Engineering - Crs | F61: Payment (Gujarat) | G61: PV/GUJ/2526/0918 | I61: 363157
A62: 46094 | B62: Dr | C62: (as per details) | F62: Payment (Haryana) | G62: PV/HR/2526/0162 | I62: 85500
C63: Atharva Enterprises - Crs | H63: 90000
C64: 194J TDS on Professional Fees | I64: 4500
...

Sheet Payments
C2: Total | E2: =SUBTOTAL(9,E3:E190) -> 75553767
B3: Date | C3: Description | D3: Name | E3: Amount | F3: UTR No | G3: Location | H3: CF Location
B4: 01/10/2026 01:37:24 | C4: NEFT - FDRL0002301 - Rushika Enterprise - 23010200000646 - Rushika Enterprise | D4: Rushika Enterprise - Crs | E4: 476828.32 | F4: HDFCH01294576579 | G4: Flyash | H4: Flyash Business
B5: 01/10/2026 05:38:57 | C5: AUTO INTEREST PAYMENT ON TERM LOAN AGAINST 5WSLN06240060003 | D5: Interest on Term Loan | E5: 317164 | F5: 5WSLN06240060003 | G5: Head Office | H5: Head Office
B6: 01/10/2026 13:04:11 | C6: NEFT - SBIN0001447 - Samdubling Metal - 31772947757 - Samdubling Metal | D6: Samdrubling Metals Pvt Ltd - Crs | E6: 500000 | F6: HDFCH01296253163 | G6: Haryana | H6: Trading Business
B7: 01/10/2026 13:04:12 | C7: NEFT - UTIB0001486 - Kamakhya Enterprises - 924020056026505 - Kamakhya Enterprises | D7: Kamakhya Enterprises - Crs | E7: 346320 | F7: HDFCH01296249219 | G7: Aggregate | H7: Aggregate Panagarh Crusher
B8: 01/10/2026 13:04:13 | C8: NEFT - ICIC0000106 - ETC POOL - ETCCUG14982026 - ETC POOL | D8: ETC POOL - Crs | E8: 31000 | F8: HDFCH01296249226 | G8: Gujarat | H8: Main Operation
B9: 01/10/2026 13:04:13 | C9: NEFT - ICIC0000106 - ETC POOL - ETCCUG14982026 - ETC POOL | D9: ETC POOL - Crs | E9: 69000 | F9: HDFCH01296249226 | G9: Aggregate | H9: Aggregate Pachami Trading
B10: 01/10/2026 13:04:13 | C10: NEFT - UTIB0001583 - SRM Logistics - 920020067135669 - SRM Logistics | D10: Srm Logistics - Crs | E10: 118580 | F10: HDFCH01296249230 | G10: Haryana | H10: Trading Business
B11: 01/10/2026 13:04:37 | C11: NEFT - SBIN0000026 - Shanidev Enterprise - 37348863334 - Shanidev Enterprise | D11: Shanidev Enterprises - Crs | E11: 58000 | F11: HDFCH01296254003 | G11: Haryana | H11: Trading Business
B12: 01/10/2026 13:05:34 | C12: FT-IOCLXPP1002085506-IOCL | D12: Indian Oil Corporation Limited - Crs | E12: 46500 | F12: 1959593435 | G12: Gujarat | H12: Main Operation
B13: 01/10/2026 13:05:34 | C13: FT-IOCLXPP1002085506-IOCL | D13: Indian Oil Corporation Limited - Crs | E13: 33000 | F13: 1959593435 | G13: Flyash | H13: Flyash Business
B14: 01/10/2026 13:05:34 | C14: FT-IOCLXPP1002085506-IOCL | D14: Indian Oil Corporation Limited - Crs | E14: 70500 | F14: 1959593435 | G14: Aggregate | H14: Aggregate Panagarh Crusher
B15: 01/10/2026 13:05:34 | C15: FT-IOCLXPP1002085506-IOCL | D15: Indian Oil Corporation Limited - Crs | E15: 46500 | F15: 1959593434 | G15: Gujarat | H15: Main Operation
... B27: 01/10/2026 16:23:13 | C27: NEFT - UTIB0003599 - Neofines Solution - 923020061649242 - Neofines Solution | D27: Neofines Solution-CRS | E27: 315927.3 | F27: HDFCH01297111968 | G27: Raipur | H27: Trading Business
B28: 01/10/2026 18:18:30 | C28: CUS0088662 PenalChrg SS OverdueQ1 26-27 | D28: Bank Charges | E28: 40714 | G28: Head Office | H28: Main Operation
B29: 01/10/2026 21:03:01 | C29: FT-IOCLXPP1002085506-IOCL | D29: Indian Oil Corporation Limited - Crs | E29: 89955.558 | F29: 1971935597 | G29: Gujarat | H29: Main Operation
B30: 01/10/2026 21:03:01 | C30: FT-IOCLXPP1002085506-IOCL | D30: Indian Oil Corporation Limited - Crs | E30: 65929.405 | F30: 1971935597 | G30: Flyash | H30: Flyash Business
B31: 01/10/2026 21:03:01 | C31: FT-IOCLXPP1002085506-IOCL | D31: Indian Oil Corporation Limited - Crs | E31: 44115.037 | F31: 1971935597 | G31: Aggregate | H31: Aggregate Panagarh Crusher
B32: 01/10/2026 21:04:32 | C32: FT - R G Brothers Enginee - 50200046609360 - R G Brothers Enginee | D32: R. G. Brothers Engineering Works - Crs | E32: 1305009.3 | F32: 1974911586 | G32: Capex | H32: Capex
B33: 01/10/2026 21:04:33 | C33: FT - Macpower Electricals - 99990000196925 - Macpower Electricals | D33: MACPOWER ELECTRICALS-Crs (Cap) | E33: 400000 | F33: 1974911590 | G33: Capex | H33: Capex
B34: 02/10/2026 13:15:32 | C34: EPI-CBICICEGATE_DHCEYD91XVMGXL | D34: Icegate IGST | E34: 150000 | F34: 011976105517 | G34: Haryana | H34: Trading Business
B35: 03/10/2026 01:38:17 | C35: NEFT - IDIB000T508 - SSP Enterprises - 8068729550 - SSP Enterprises | D35: SSP Enterprises - Crs | E35: 300000 | F35: HDFCH01299942543 | G35: Capex | H35: Capex
B36: 03/10/2026 09:47:32 | C36: NEFT - SBIN0000489 - Fourteckh Enviro - 42030343519 - Fourteckh Enviro | D36: Fourteckh Enviro India Pvt Ltd - Crs | E36: 1000000 | F36: HDFCH01300207888 | G36: Head Office | H36: Capex
B37: 03/10/2026 09:47:34 | C37: FT - Vashi Solution Ltd - 50200050070484 - Vashi Solution Ltd | D37: Vashi Integrated Solution Limited - Crs | E37: 1500000 | F37: 1974911585 | G37: Head Office | H37: Capex
B38: 03/10/2026 14:31:34 | C38: NEFT - UBIN0933376 - Sunrise Pump - 333725080000011 - Sunrise Pump | D38: Sunrise Pd Pumps & Systems - Crs | E38: 410000 | F38: HDFCH01300916096 | G38: Capex | H38: Capex
B39: 03/10/2026 14:31:34 | C39: NEFT - PUNB0001810 - Cenlub System - 00184010000630 - Cenlub System | D39: Cenlub Systems - Crs | E39: 90000 | F39: HDFCH01300916101 | G39: Capex | H39: Capex
B40: 03/10/2026 14:31:35 | C40: NEFT - ICIC0000039 - Midas Autosoft - 003905033436 - Midas Autosoft | D40: Midas Autosoft Engineers Pvt Ltd - Crs | E40: 103500 | F40: HDFCH01300916109 | G40: Capex | H40: Capex
... B186: 12/10/2026 18:25:42 | C186: FT - P K Traders - 50200084340758 - P K Traders | D186: P.K. Traders- Crs | E186: 296003 | F186: 2006953081 | G186: Aggregate Panagarh Crusher | H186: Aggregate Panagarh Crusher
B189: - | C189: - | D189: - | E189: - | F189: - | G189: - | H189: -
C193: Date | D193: Name | E193: Amount | F193: UTR No
C194: 08/10/2026 18:08:14 | D194: WBSEDCL (Galsi) - Crs | E194: 217307 | F194: HDFCH01317676574
C195: 21/09/2026 18:39:08 | D195: JANTA CEMENT INDUSTRIES-Crs | E195: 441154.36 | F195: HDFCH01275398113
C196: 46253.724 | D196: Shri Raghavendra Enterprises - Crs | E196: 157116.96 | F196: HDFCH01204820167
C197: 46253.724 | D197: Shri Raghavendra Enterprises - Crs | E197: 166524.76 | F197: HDFCH01204817254
C198: 46254.734 | D198: Shri Raghavendra Enterprises - Crs | E198: 241443.74 | F198: HDFCH01206862998
C199: 46254.734 | D199: Shri Raghavendra Enterprises - Crs | E199: 239429.42 | F199: HDFCH01206863004
E200: =SUBTOTAL(9,E194:E199) -> 1462976.2

Sheet Receipts
C2: Total | E2: =SUBTOTAL(9,E4:E99) -> 74521848
B3: Date | C3: Description | D3: Name | E3: Amount | F3: Tally Location | G3: CF Location | H3: Z
B4: 01/10/2026 13:23:30 | C4: NEFT Cr-ICIC0SF0002-SRK BUILDWELL PRIVATE LIMITED PROJE-ULTRAFINE MINERAL ADMIXTURES-IN12627457688980 | D4: SRK Buildwell Private Limited-Drs | E4: 267750 | F4: Gujarat | G4: Main Operation
B5: 01/10/2026 16:18:47 | C5: CHQ DEP - TRANSFER OW 1 - MUMBAI CLEARIN: RDC CONCRETE (INDIA) :HDFC BANK LTD | D5: Rdc Concrete (India) Pvt Ltd | E5: 341622.94 | F5: Aggregate Pachami Trading | G5: Aggregate Pachami Trading
B6: 01/10/2026 16:18:47 | C6: CHQ DEP - TRANSFER OW 1 - MUMBAI CLEARIN: RDC CONCRETE (INDIA) :HDFC BANK LTD | D6: Rdc Concrete (India) Pvt Ltd | E6: 69654.22 | F6: Aggregate Panagarh Crusher | G6: Aggregate Panagarh Crusher
B7: 01/10/2026 16:18:47 | C7: CHQ DEP - TRANSFER OW 1 - MUMBAI CLEARIN: RDC CONCRETE (INDIA) :HDFC BANK LTD | D7: Rdc Concrete (India) Pvt Ltd | E7: 258526.99 | F7: Flyash Business | G7: Flyash Business
B8: 01/10/2026 16:18:47 | C8: CHQ DEP - TRANSFER OW 1 - MUMBAI CLEARIN: RDC CONCRETE (INDIA) :HDFC BANK LTD | D8: Rdc Concrete (India) Pvt Ltd | E8: 1020248.2 | F8: Main Operation | G8: Main Operation
B9: 01/10/2026 16:18:47 | C9: CHQ DEP - TRANSFER OW 1 - MUMBAI CLEARIN: RDC CONCRETE (INDIA) :HDFC BANK LTD | D9: Rdc Concrete (India) Pvt Ltd | E9: 309947.62 | F9: Trading Business | G9: Trading Business
B10: 01/10/2026 17:44:10 | C10: 50200053382175-TPT-Bill No 3026270248-R AND S ENTERPRISES | D10: R & S Enterprises - Drs | E10: 1365277.5 | F10: Flyash | G10: Flyash Business
B11: 01/10/2026 20:02:07 | C11: NEFT Cr-SBIN0016446-NCC LIMITED-ULTRAFINE MINERAL AND ADMIXTURES-SBIN126274766908 | D11: NCC LIMITED -DRS | E11: 948880 | F11: Galsi | G11: Main Operation
B12: 01/10/2026 22:06:17 | C12: NEFT Cr-MAHB0001175-GMS INFRATECH-Ultrafine Minerals Admixtures Pvt-MAHBH00166290339 | D12: GMS INFRATECH -Drs | E12: 178500 | F12: Telangana | G12: Main Operation
B13: 03/10/2026 15:05:46 | C13: FT - Cr - 57500001803372 - LANSUM & MK REALTY LLP | D13: LANSUM & MK REALTY LLP-Drs | E13: 4612999 | F13: Vizag | G13: Main Operation
B14: 03/10/2026 16:06:14 | C14: NEFT Cr-BKID0004252-ARITRA CONSTRUCTION-ULTRAFINE-BKIDY26276972378 | E14: 125552 | F14: Aggregate Pachami Trading | G14: Aggregate Pachami Trading
B15: 03/10/2026 16:21:08 | C15: CHQ DEP - TRANSFER OW 1 - MUMBAI CLEARIN: RDC CONCRETE (INDIA) :HDFC BANK LTD | D15: Rdc Concrete (India) Pvt Ltd | E15: 360736.41 | F15: Aggregate Pachami Trading | G15: Aggregate Pachami Trading
B16: 03/10/2026 16:21:08 | C16: CHQ DEP - TRANSFER OW 1 - MUMBAI CLEARIN: RDC CONCRETE (INDIA) :HDFC BANK LTD | D16: Rdc Concrete (India) Pvt Ltd | E16: 73551.304 | F16: Aggregate Panagarh Crusher | G16: Aggregate Panagarh Crusher
B17: 03/10/2026 16:21:08 | C17: CHQ DEP - TRANSFER OW 1 - MUMBAI CLEARIN: RDC CONCRETE (INDIA) :HDFC BANK LTD | D17: Rdc Concrete (India) Pvt Ltd | E17: 272991.31 | F17: Flyash Business | G17: Flyash Business
B18: 03/10/2026 16:21:08 | C18: CHQ DEP - TRANSFER OW 1 - MUMBAI CLEARIN: RDC CONCRETE (INDIA) :HDFC BANK LTD | D18: Rdc Concrete (India) Pvt Ltd | E18: 1077330.1 | F18: Main Operation | G18: Main Operation
B19: 03/10/2026 16:21:08 | C19: CHQ DEP - TRANSFER OW 1 - MUMBAI CLEARIN: RDC CONCRETE (INDIA) :HDFC BANK LTD | D19: Rdc Concrete (India) Pvt Ltd | E19: 327288.88 | F19: Trading Business | G19: Trading Business
B20: 03/10/2026 16:44:42 | C20: FT- 2026-10-03- P2100P2100 - 0073041655 | D20: Ultratech Cement Limited - Drs | E20: 167840 | F20: Gujarat | G20: Main Operation
B21: 03/10/2026 16:44:42 | C21: FT- 2026-10-03- P2100P2100 - 0073041656 | D21: Ultratech Cement Limited - Drs | E21: 151222 | F21: Gujarat | G21: Main Operation
B22: 03/10/2026 16:44:42 | C22: FT- 2026-10-03- P2100P2100 - 0073041657 | D22: Ultratech Cement Limited - Drs | E22: 151724 | F22: Gujarat | G22: Main Operation
B23: 03/10/2026 17:24:40 | C23: RTGS Cr-INDB0000098-MAHESH TRADING CO-ULTRAFINE MINRAL AND ADMIXURES PVT -INDBR22026100300507422 | D23: Mahesh Trading Company - Drs | E23: 624456 | F23: Galsi | G23: Main Operation
B24: 05/10/2026 11:02:10 | C24: NEFT Cr-SBIN0004266-D E C INFRASTRUCTURE AND PROJECTS I-ULTRAFINE MINERAL amp ADMIXTURES-SBIF400020188382 | D24: D.E.C. Infrastructure and Projects (India) PVT LTD-DRS | E24: 1106026 | F24: Haryana | G24: Trading Business
B25: 05/10/2026 15:03:28 | C25: NEFT RETURN-INCORRECT ACCOUNT NUMBER-Shree Pad Corporation-IBKLN92026100526372626 | D25: Shree Pad Corporation-Crs | E25: 12800 | F25: Gujarat | G25: Main Operation
B26: 05/10/2026 16:38:46 | C26: CHQ DEP - TRANSFER OW 1 - MUMBAI CLEARIN: RDC CONCRETE (INDIA) :HDFC BANK LTD | D26: Rdc Concrete (India) Pvt Ltd | E26: 427028.68 | F26: Aggregate Pachami Trading | G26: Aggregate Pachami Trading
... B96: 12/10/2026 20:49:43 | C96: RTGS Cr-ICIC0099999-RAMTEJA CONSTRUCTIONS PRIVATE LIMIT-Ultrafine Mineral Admixtures Priv-ICICR22026101219329637 | D96: Ramteja Constructions Private Limited-Drs | E96: 588680 | F96: Vizag | G96: Main Operation
B99: - | C99: - | D99: - | E99: - | F99: - | G99: -
B101: Date | C101: Description | D101: Name | E101: Amount
B102: 22/09/2026 11:56:16 | C102: CHQ DEP - CTS CLG1 - GOA, PANJIM TBG OPS | E102: 335680
D193: SOUTHERNPOWERDISTRIBUTIONCOMPANYOFANDHRA-Cr | G193: Nellore | H193: Main Operation
D194: SOUTHERNPOWERDISTRIBUTIONCOMPANYOFANDHRA-Cr | G194: Nellore | H194: Main Operation
D195: Premier Roadlines Ltd - Crs
D196: SHREEKRISHNA SUPPLIERS-Crs
D198: RATHI ASSOCIATES - Crs
D199: AKBAR TRAVELS OF INDIA PVT. LTD-Crs

Sheet Working
A1: # | B1: PDC | D1: 46296 | E1: 46298 | F1: 46300 | G1: 46301 | H1: 46307
B2: PARTICULARS | C2: Ratio | D2: 2000000 | E2: 2111898 | F2: 2500000 | G2: 2500000 | H2: 2500000
B3: Aggregate Pachami Trading | C3: 0.17081147 | D3: =D$2*$C3 -> 341622.94 | E3: =E$2*$C3 -> 360736.41 | F3: =F$2*$C3 -> 427028.68 | G3: =G$2*$C3 -> 427028.68 | H3: =H$2*$C3 -> 427028.68
B4: Aggregate Panagarh Crusher | C4: 0.03482711 | D4: =D$2*$C4 -> 69654.22 | E4: =E$2*$C4 -> 73551.304 | F4: =F$2*$C4 -> 87067.775 | G4: =G$2*$C4 -> 87067.775 | H4: =H$2*$C4 -> 87067.775
B5: Flyash Business | C5: 0.12926349 | D5: =D$2*$C5 -> 258526.99 | E5: =E$2*$C5 -> 272991.31 | F5: =F$2*$C5 -> 323158.74 | G5: =G$2*$C5 -> 323158.74 | H5: =H$2*$C5 -> 323158.74
B6: Main Operation | C6: 0.51012411 | D6: =D$2*$C6 -> 1020248.2 | E6: =E$2*$C6 -> 1077330.1 | F6: =F$2*$C6 -> 1275310.3 | G6: =G$2*$C6 -> 1275310.3 | H6: =H$2*$C6 -> 1275310.3
B7: Trading Business | C7: 0.15497381 | D7: =D$2*$C7 -> 309947.62 | E7: =E$2*$C7 -> 327288.88 | F7: =F$2*$C7 -> 387434.53 | G7: =G$2*$C7 -> 387434.53 | H7: =H$2*$C7 -> 387434.53
B8: Grand Total | C8: =SUM(C3:C7) -> 1 | D8: =SUM(D3:D7) -> 2000000 | E8: =SUM(E3:E7) -> 2111898 | F8: =SUM(F3:F7) -> 2500000 | G8: =SUM(G3:G7) -> 2500000 | H8: =SUM(H3:H7) -> 2500000
A10: # | B10: IOCL | D10: 46298 | E10: 46301 | F10: 46303
B11: PARTICULARS | C11: Ratio | D11: 200000 | E11: 350000 | F11: 2426338
B12: Main | C12: 0.44977779 | D12: =D$11*$C12 -> 89955.558 | E12: =E$11*$C12 -> 157422.23 | F12: =F$11*$C12 -> 1091312.9
B13: Flyash | C13: 0.32964703 | D13: =D$11*$C13 -> 65929.405 | E13: =E$11*$C13 -> 115376.46 | F13: =F$11*$C13 -> 799835.11
B14: Aggregate | C14: 0.22057518 | D14: =D$11*$C14 -> 44115.037 | E14: =E$11*$C14 -> 77201.314 | F14: =F$11*$C14 -> 535189.95
B15: TOATL | C15: =SUM(C12:C14) -> 1 | D15: =SUM(D12:D14) -> 200000 | E15: =SUM(E12:E14) -> 350000 | F15: =SUM(F12:F14) -> 2426338
A17: # | B17: ETC Pool
B18: PARTICULARS | C18: Ratio
B19: Main | C19: 0.31
B20: Aggregate | C20: 0.69
B21: TOATL | C21: =SUM(C19:C20) -> 1
B24: IOCL Consumption September | D24: Ratio
B25: Flyash | C25: 1724212.1 | D25: =C25/$C$28 -> 0.32964703
B26: Aggregate Panagarh Crusher | C26: 1153714 | D26: =C26/$C$28 -> 0.22057518
B27: Main Operation | C27: 2352553.6 | D27: =C27/$C$28 -> 0.44977779
B28: TOTAL | C28: =SUM(C25:C27) -> 5230479.6 | D28: =SUM(D25:D27) -> 1
B31: ETC POOL
B32: Main Operation | D32: 102000
B33: Aggregate | D33: 227000
D34: =SUM(D32:D33) -> 329000
